2024-12-20 09:24:18.001 | ERROR    | utils.ClientLogManager:log:49 - Loop Failed! Error: Error in Opti::solve [OptiNode] at .../casadi/core/optistack.cpp:165:
.../casadi/core/optistack_internal.cpp:1030: Assertion "return_success(accept_limit)" failed:
Solver failed. You may use opti.debug.value to investigate the latest values of variables. return_status is 'NonIpopt_Exception_Thrown', occurred on line 48364 in file /home/turingzero/.local/lib/python3.10/site-packages/casadi/casadi.py
2024-12-20 09:24:18.176 | ERROR    | utils.ClientLogManager:log:49 - Loop Failed! Error: Error in Opti::solve [OptiNode] at .../casadi/core/optistack.cpp:165:
.../casadi/core/optistack_internal.cpp:1030: Assertion "return_success(accept_limit)" failed:
Solver failed. You may use opti.debug.value to investigate the latest values of variables. return_status is 'NonIpopt_Exception_Thrown', occurred on line 48364 in file /home/turingzero/.local/lib/python3.10/site-packages/casadi/casadi.py
2024-12-20 09:24:18.393 | ERROR    | utils.ClientLogManager:log:49 - Loop Failed! Error: Error in Opti::solve [OptiNode] at .../casadi/core/optistack.cpp:165:
.../casadi/core/optistack_internal.cpp:1030: Assertion "return_success(accept_limit)" failed:
Solver failed. You may use opti.debug.value to investigate the latest values of variables. return_status is 'NonIpopt_Exception_Thrown', occurred on line 48364 in file /home/turingzero/.local/lib/python3.10/site-packages/casadi/casadi.py
2024-12-20 09:24:18.565 | ERROR    | utils.ClientLogManager:log:49 - Loop Failed! Error: Error in Opti::solve [OptiNode] at .../casadi/core/optistack.cpp:165:
.../casadi/core/optistack_internal.cpp:1030: Assertion "return_success(accept_limit)" failed:
Solver failed. You may use opti.debug.value to investigate the latest values of variables. return_status is 'NonIpopt_Exception_Thrown', occurred on line 48364 in file /home/turingzero/.local/lib/python3.10/site-packages/casadi/casadi.py
2024-12-20 09:24:18.731 | ERROR    | utils.ClientLogManager:log:49 - Loop Failed! Error: Error in Opti::solve [OptiNode] at .../casadi/core/optistack.cpp:165:
.../casadi/core/optistack_internal.cpp:1030: Assertion "return_success(accept_limit)" failed:
Solver failed. You may use opti.debug.value to investigate the latest values of variables. return_status is 'NonIpopt_Exception_Thrown', occurred on line 48364 in file /home/turingzero/.local/lib/python3.10/site-packages/casadi/casadi.py
2024-12-20 09:24:19.232 | ERROR    | utils.ClientLogManager:log:49 - Loop Failed! Error: Error in Opti::solve [OptiNode] at .../casadi/core/optistack.cpp:165:
.../casadi/core/optistack_internal.cpp:1030: Assertion "return_success(accept_limit)" failed:
Solver failed. You may use opti.debug.value to investigate the latest values of variables. return_status is 'NonIpopt_Exception_Thrown', occurred on line 48364 in file /home/turingzero/.local/lib/python3.10/site-packages/casadi/casadi.py
2024-12-20 09:24:19.261 | ERROR    | utils.ClientLogManager:log:49 - Loop Failed! Error: Error in Opti::solve [OptiNode] at .../casadi/core/optistack.cpp:165:
.../casadi/core/optistack_internal.cpp:1030: Assertion "return_success(accept_limit)" failed:
Solver failed. You may use opti.debug.value to investigate the latest values of variables. return_status is 'NonIpopt_Exception_Thrown', occurred on line 48364 in file /home/turingzero/.local/lib/python3.10/site-packages/casadi/casadi.py
2024-12-20 09:30:13.664 | ERROR    | utils.ClientLogManager:log:49 - Loop Failed! Error: Error in Opti::solve [OptiNode] at .../casadi/core/optistack.cpp:165:
.../casadi/core/optistack_internal.cpp:1030: Assertion "return_success(accept_limit)" failed:
Solver failed. You may use opti.debug.value to investigate the latest values of variables. return_status is 'NonIpopt_Exception_Thrown', occurred on line 48364 in file /home/turingzero/.local/lib/python3.10/site-packages/casadi/casadi.py
2024-12-20 09:30:14.161 | ERROR    | utils.ClientLogManager:log:49 - Loop Failed! Error: Error in Opti::solve [OptiNode] at .../casadi/core/optistack.cpp:165:
.../casadi/core/optistack_internal.cpp:1030: Assertion "return_success(accept_limit)" failed:
Solver failed. You may use opti.debug.value to investigate the latest values of variables. return_status is 'NonIpopt_Exception_Thrown', occurred on line 48364 in file /home/turingzero/.local/lib/python3.10/site-packages/casadi/casadi.py
2024-12-20 09:30:14.191 | ERROR    | utils.ClientLogManager:log:49 - Loop Failed! Error: Error in Opti::solve [OptiNode] at .../casadi/core/optistack.cpp:165:
.../casadi/core/optistack_internal.cpp:1030: Assertion "return_success(accept_limit)" failed:
Solver failed. You may use opti.debug.value to investigate the latest values of variables. return_status is 'NonIpopt_Exception_Thrown', occurred on line 48364 in file /home/turingzero/.local/lib/python3.10/site-packages/casadi/casadi.py
2024-12-20 09:30:14.222 | ERROR    | utils.ClientLogManager:log:49 - Loop Failed! Error: Error in Opti::solve [OptiNode] at .../casadi/core/optistack.cpp:165:
.../casadi/core/optistack_internal.cpp:1030: Assertion "return_success(accept_limit)" failed:
Solver failed. You may use opti.debug.value to investigate the latest values of variables. return_status is 'NonIpopt_Exception_Thrown', occurred on line 48364 in file /home/turingzero/.local/lib/python3.10/site-packages/casadi/casadi.py
2024-12-20 09:30:14.252 | ERROR    | utils.ClientLogManager:log:49 - Loop Failed! Error: Error in Opti::solve [OptiNode] at .../casadi/core/optistack.cpp:165:
.../casadi/core/optistack_internal.cpp:1030: Assertion "return_success(accept_limit)" failed:
Solver failed. You may use opti.debug.value to investigate the latest values of variables. return_status is 'NonIpopt_Exception_Thrown', occurred on line 48364 in file /home/turingzero/.local/lib/python3.10/site-packages/casadi/casadi.py
2024-12-20 09:30:14.282 | ERROR    | utils.ClientLogManager:log:49 - Loop Failed! Error: Error in Opti::solve [OptiNode] at .../casadi/core/optistack.cpp:165:
.../casadi/core/optistack_internal.cpp:1030: Assertion "return_success(accept_limit)" failed:
Solver failed. You may use opti.debug.value to investigate the latest values of variables. return_status is 'NonIpopt_Exception_Thrown', occurred on line 48364 in file /home/turingzero/.local/lib/python3.10/site-packages/casadi/casadi.py
2024-12-20 09:30:14.312 | ERROR    | utils.ClientLogManager:log:49 - Loop Failed! Error: Error in Opti::solve [OptiNode] at .../casadi/core/optistack.cpp:165:
.../casadi/core/optistack_internal.cpp:1030: Assertion "return_success(accept_limit)" failed:
Solver failed. You may use opti.debug.value to investigate the latest values of variables. return_status is 'NonIpopt_Exception_Thrown', occurred on line 48364 in file /home/turingzero/.local/lib/python3.10/site-packages/casadi/casadi.py
2024-12-20 09:30:14.342 | ERROR    | utils.ClientLogManager:log:49 - Loop Failed! Error: Error in Opti::solve [OptiNode] at .../casadi/core/optistack.cpp:165:
.../casadi/core/optistack_internal.cpp:1030: Assertion "return_success(accept_limit)" failed:
Solver failed. You may use opti.debug.value to investigate the latest values of variables. return_status is 'NonIpopt_Exception_Thrown', occurred on line 48364 in file /home/turingzero/.local/lib/python3.10/site-packages/casadi/casadi.py
2024-12-20 09:30:14.372 | ERROR    | utils.ClientLogManager:log:49 - Loop Failed! Error: Error in Opti::solve [OptiNode] at .../casadi/core/optistack.cpp:165:
.../casadi/core/optistack_internal.cpp:1030: Assertion "return_success(accept_limit)" failed:
Solver failed. You may use opti.debug.value to investigate the latest values of variables. return_status is 'NonIpopt_Exception_Thrown', occurred on line 48364 in file /home/turingzero/.local/lib/python3.10/site-packages/casadi/casadi.py
2024-12-20 09:30:14.402 | ERROR    | utils.ClientLogManager:log:49 - Loop Failed! Error: Error in Opti::solve [OptiNode] at .../casadi/core/optistack.cpp:165:
.../casadi/core/optistack_internal.cpp:1030: Assertion "return_success(accept_limit)" failed:
Solver failed. You may use opti.debug.value to investigate the latest values of variables. return_status is 'NonIpopt_Exception_Thrown', occurred on line 48364 in file /home/turingzero/.local/lib/python3.10/site-packages/casadi/casadi.py
2024-12-20 09:30:14.432 | ERROR    | utils.ClientLogManager:log:49 - Loop Failed! Error: Error in Opti::solve [OptiNode] at .../casadi/core/optistack.cpp:165:
.../casadi/core/optistack_internal.cpp:1030: Assertion "return_success(accept_limit)" failed:
Solver failed. You may use opti.debug.value to investigate the latest values of variables. return_status is 'NonIpopt_Exception_Thrown', occurred on line 48364 in file /home/turingzero/.local/lib/python3.10/site-packages/casadi/casadi.py
2024-12-20 09:30:14.462 | ERROR    | utils.ClientLogManager:log:49 - Loop Failed! Error: Error in Opti::solve [OptiNode] at .../casadi/core/optistack.cpp:165:
.../casadi/core/optistack_internal.cpp:1030: Assertion "return_success(accept_limit)" failed:
Solver failed. You may use opti.debug.value to investigate the latest values of variables. return_status is 'NonIpopt_Exception_Thrown', occurred on line 48364 in file /home/turingzero/.local/lib/python3.10/site-packages/casadi/casadi.py
2024-12-20 09:30:14.492 | ERROR    | utils.ClientLogManager:log:49 - Loop Failed! Error: Error in Opti::solve [OptiNode] at .../casadi/core/optistack.cpp:165:
.../casadi/core/optistack_internal.cpp:1030: Assertion "return_success(accept_limit)" failed:
Solver failed. You may use opti.debug.value to investigate the latest values of variables. return_status is 'NonIpopt_Exception_Thrown', occurred on line 48364 in file /home/turingzero/.local/lib/python3.10/site-packages/casadi/casadi.py
2024-12-20 09:30:14.522 | ERROR    | utils.ClientLogManager:log:49 - Loop Failed! Error: Error in Opti::solve [OptiNode] at .../casadi/core/optistack.cpp:165:
.../casadi/core/optistack_internal.cpp:1030: Assertion "return_success(accept_limit)" failed:
Solver failed. You may use opti.debug.value to investigate the latest values of variables. return_status is 'NonIpopt_Exception_Thrown', occurred on line 48364 in file /home/turingzero/.local/lib/python3.10/site-packages/casadi/casadi.py
2024-12-20 09:30:14.552 | ERROR    | utils.ClientLogManager:log:49 - Loop Failed! Error: Error in Opti::solve [OptiNode] at .../casadi/core/optistack.cpp:165:
.../casadi/core/optistack_internal.cpp:1030: Assertion "return_success(accept_limit)" failed:
Solver failed. You may use opti.debug.value to investigate the latest values of variables. return_status is 'NonIpopt_Exception_Thrown', occurred on line 48364 in file /home/turingzero/.local/lib/python3.10/site-packages/casadi/casadi.py
2024-12-20 09:30:14.582 | ERROR    | utils.ClientLogManager:log:49 - Loop Failed! Error: Error in Opti::solve [OptiNode] at .../casadi/core/optistack.cpp:165:
.../casadi/core/optistack_internal.cpp:1030: Assertion "return_success(accept_limit)" failed:
Solver failed. You may use opti.debug.value to investigate the latest values of variables. return_status is 'NonIpopt_Exception_Thrown', occurred on line 48364 in file /home/turingzero/.local/lib/python3.10/site-packages/casadi/casadi.py
2024-12-20 09:30:14.612 | ERROR    | utils.ClientLogManager:log:49 - Loop Failed! Error: Error in Opti::solve [OptiNode] at .../casadi/core/optistack.cpp:165:
.../casadi/core/optistack_internal.cpp:1030: Assertion "return_success(accept_limit)" failed:
Solver failed. You may use opti.debug.value to investigate the latest values of variables. return_status is 'NonIpopt_Exception_Thrown', occurred on line 48364 in file /home/turingzero/.local/lib/python3.10/site-packages/casadi/casadi.py
2024-12-20 09:30:14.643 | ERROR    | utils.ClientLogManager:log:49 - Loop Failed! Error: Error in Opti::solve [OptiNode] at .../casadi/core/optistack.cpp:165:
.../casadi/core/optistack_internal.cpp:1030: Assertion "return_success(accept_limit)" failed:
Solver failed. You may use opti.debug.value to investigate the latest values of variables. return_status is 'NonIpopt_Exception_Thrown', occurred on line 48364 in file /home/turingzero/.local/lib/python3.10/site-packages/casadi/casadi.py
2024-12-20 09:30:14.673 | ERROR    | utils.ClientLogManager:log:49 - Loop Failed! Error: Error in Opti::solve [OptiNode] at .../casadi/core/optistack.cpp:165:
.../casadi/core/optistack_internal.cpp:1030: Assertion "return_success(accept_limit)" failed:
Solver failed. You may use opti.debug.value to investigate the latest values of variables. return_status is 'NonIpopt_Exception_Thrown', occurred on line 48364 in file /home/turingzero/.local/lib/python3.10/site-packages/casadi/casadi.py
2024-12-20 09:30:14.703 | ERROR    | utils.ClientLogManager:log:49 - Loop Failed! Error: Error in Opti::solve [OptiNode] at .../casadi/core/optistack.cpp:165:
.../casadi/core/optistack_internal.cpp:1030: Assertion "return_success(accept_limit)" failed:
Solver failed. You may use opti.debug.value to investigate the latest values of variables. return_status is 'NonIpopt_Exception_Thrown', occurred on line 48364 in file /home/turingzero/.local/lib/python3.10/site-packages/casadi/casadi.py
2024-12-20 09:30:14.734 | ERROR    | utils.ClientLogManager:log:49 - Loop Failed! Error: Error in Opti::solve [OptiNode] at .../casadi/core/optistack.cpp:165:
.../casadi/core/optistack_internal.cpp:1030: Assertion "return_success(accept_limit)" failed:
Solver failed. You may use opti.debug.value to investigate the latest values of variables. return_status is 'NonIpopt_Exception_Thrown', occurred on line 48364 in file /home/turingzero/.local/lib/python3.10/site-packages/casadi/casadi.py
2024-12-20 09:30:14.764 | ERROR    | utils.ClientLogManager:log:49 - Loop Failed! Error: Error in Opti::solve [OptiNode] at .../casadi/core/optistack.cpp:165:
.../casadi/core/optistack_internal.cpp:1030: Assertion "return_success(accept_limit)" failed:
Solver failed. You may use opti.debug.value to investigate the latest values of variables. return_status is 'NonIpopt_Exception_Thrown', occurred on line 48364 in file /home/turingzero/.local/lib/python3.10/site-packages/casadi/casadi.py
2024-12-20 09:30:14.795 | ERROR    | utils.ClientLogManager:log:49 - Loop Failed! Error: Error in Opti::solve [OptiNode] at .../casadi/core/optistack.cpp:165:
.../casadi/core/optistack_internal.cpp:1030: Assertion "return_success(accept_limit)" failed:
Solver failed. You may use opti.debug.value to investigate the latest values of variables. return_status is 'NonIpopt_Exception_Thrown', occurred on line 48364 in file /home/turingzero/.local/lib/python3.10/site-packages/casadi/casadi.py
2024-12-20 09:30:14.824 | ERROR    | utils.ClientLogManager:log:49 - Loop Failed! Error: Error in Opti::solve [OptiNode] at .../casadi/core/optistack.cpp:165:
.../casadi/core/optistack_internal.cpp:1030: Assertion "return_success(accept_limit)" failed:
Solver failed. You may use opti.debug.value to investigate the latest values of variables. return_status is 'NonIpopt_Exception_Thrown', occurred on line 48364 in file /home/turingzero/.local/lib/python3.10/site-packages/casadi/casadi.py
2024-12-20 09:30:14.854 | ERROR    | utils.ClientLogManager:log:49 - Loop Failed! Error: Error in Opti::solve [OptiNode] at .../casadi/core/optistack.cpp:165:
.../casadi/core/optistack_internal.cpp:1030: Assertion "return_success(accept_limit)" failed:
Solver failed. You may use opti.debug.value to investigate the latest values of variables. return_status is 'NonIpopt_Exception_Thrown', occurred on line 48364 in file /home/turingzero/.local/lib/python3.10/site-packages/casadi/casadi.py
2024-12-20 09:30:14.885 | ERROR    | utils.ClientLogManager:log:49 - Loop Failed! Error: Error in Opti::solve [OptiNode] at .../casadi/core/optistack.cpp:165:
.../casadi/core/optistack_internal.cpp:1030: Assertion "return_success(accept_limit)" failed:
Solver failed. You may use opti.debug.value to investigate the latest values of variables. return_status is 'NonIpopt_Exception_Thrown', occurred on line 48364 in file /home/turingzero/.local/lib/python3.10/site-packages/casadi/casadi.py
2024-12-20 09:30:14.914 | ERROR    | utils.ClientLogManager:log:49 - Loop Failed! Error: Error in Opti::solve [OptiNode] at .../casadi/core/optistack.cpp:165:
.../casadi/core/optistack_internal.cpp:1030: Assertion "return_success(accept_limit)" failed:
Solver failed. You may use opti.debug.value to investigate the latest values of variables. return_status is 'NonIpopt_Exception_Thrown', occurred on line 48364 in file /home/turingzero/.local/lib/python3.10/site-packages/casadi/casadi.py
2024-12-20 09:30:14.944 | ERROR    | utils.ClientLogManager:log:49 - Loop Failed! Error: Error in Opti::solve [OptiNode] at .../casadi/core/optistack.cpp:165:
.../casadi/core/optistack_internal.cpp:1030: Assertion "return_success(accept_limit)" failed:
Solver failed. You may use opti.debug.value to investigate the latest values of variables. return_status is 'NonIpopt_Exception_Thrown', occurred on line 48364 in file /home/turingzero/.local/lib/python3.10/site-packages/casadi/casadi.py
2024-12-20 09:30:14.975 | ERROR    | utils.ClientLogManager:log:49 - Loop Failed! Error: Error in Opti::solve [OptiNode] at .../casadi/core/optistack.cpp:165:
.../casadi/core/optistack_internal.cpp:1030: Assertion "return_success(accept_limit)" failed:
Solver failed. You may use opti.debug.value to investigate the latest values of variables. return_status is 'NonIpopt_Exception_Thrown', occurred on line 48364 in file /home/turingzero/.local/lib/python3.10/site-packages/casadi/casadi.py
2024-12-20 09:30:15.004 | ERROR    | utils.ClientLogManager:log:49 - Loop Failed! Error: Error in Opti::solve [OptiNode] at .../casadi/core/optistack.cpp:165:
.../casadi/core/optistack_internal.cpp:1030: Assertion "return_success(accept_limit)" failed:
Solver failed. You may use opti.debug.value to investigate the latest values of variables. return_status is 'NonIpopt_Exception_Thrown', occurred on line 48364 in file /home/turingzero/.local/lib/python3.10/site-packages/casadi/casadi.py
2024-12-20 09:30:15.035 | ERROR    | utils.ClientLogManager:log:49 - Loop Failed! Error: Error in Opti::solve [OptiNode] at .../casadi/core/optistack.cpp:165:
.../casadi/core/optistack_internal.cpp:1030: Assertion "return_success(accept_limit)" failed:
Solver failed. You may use opti.debug.value to investigate the latest values of variables. return_status is 'NonIpopt_Exception_Thrown', occurred on line 48364 in file /home/turingzero/.local/lib/python3.10/site-packages/casadi/casadi.py
2024-12-20 09:30:15.065 | ERROR    | utils.ClientLogManager:log:49 - Loop Failed! Error: Error in Opti::solve [OptiNode] at .../casadi/core/optistack.cpp:165:
.../casadi/core/optistack_internal.cpp:1030: Assertion "return_success(accept_limit)" failed:
Solver failed. You may use opti.debug.value to investigate the latest values of variables. return_status is 'NonIpopt_Exception_Thrown', occurred on line 48364 in file /home/turingzero/.local/lib/python3.10/site-packages/casadi/casadi.py
2024-12-20 09:31:55.709 | ERROR    | utils.ClientLogManager:log:49 - Loop Failed! Error: Error in Opti::solve [OptiNode] at .../casadi/core/optistack.cpp:165:
.../casadi/core/optistack_internal.cpp:1030: Assertion "return_success(accept_limit)" failed:
Solver failed. You may use opti.debug.value to investigate the latest values of variables. return_status is 'NonIpopt_Exception_Thrown', occurred on line 48364 in file /home/turingzero/.local/lib/python3.10/site-packages/casadi/casadi.py
2024-12-20 09:31:55.902 | ERROR    | utils.ClientLogManager:log:49 - Loop Failed! Error: Error in Opti::solve [OptiNode] at .../casadi/core/optistack.cpp:165:
.../casadi/core/optistack_internal.cpp:1030: Assertion "return_success(accept_limit)" failed:
Solver failed. You may use opti.debug.value to investigate the latest values of variables. return_status is 'NonIpopt_Exception_Thrown', occurred on line 48364 in file /home/turingzero/.local/lib/python3.10/site-packages/casadi/casadi.py
2024-12-20 09:31:56.058 | ERROR    | utils.ClientLogManager:log:49 - Loop Failed! Error: Error in Opti::solve [OptiNode] at .../casadi/core/optistack.cpp:165:
.../casadi/core/optistack_internal.cpp:1030: Assertion "return_success(accept_limit)" failed:
Solver failed. You may use opti.debug.value to investigate the latest values of variables. return_status is 'NonIpopt_Exception_Thrown', occurred on line 48364 in file /home/turingzero/.local/lib/python3.10/site-packages/casadi/casadi.py
2024-12-20 09:31:56.216 | ERROR    | utils.ClientLogManager:log:49 - Loop Failed! Error: Error in Opti::solve [OptiNode] at .../casadi/core/optistack.cpp:165:
.../casadi/core/optistack_internal.cpp:1030: Assertion "return_success(accept_limit)" failed:
Solver failed. You may use opti.debug.value to investigate the latest values of variables. return_status is 'NonIpopt_Exception_Thrown', occurred on line 48364 in file /home/turingzero/.local/lib/python3.10/site-packages/casadi/casadi.py
2024-12-20 09:31:56.351 | ERROR    | utils.ClientLogManager:log:49 - Loop Failed! Error: Error in Opti::solve [OptiNode] at .../casadi/core/optistack.cpp:165:
.../casadi/core/optistack_internal.cpp:1030: Assertion "return_success(accept_limit)" failed:
Solver failed. You may use opti.debug.value to investigate the latest values of variables. return_status is 'NonIpopt_Exception_Thrown', occurred on line 48364 in file /home/turingzero/.local/lib/python3.10/site-packages/casadi/casadi.py
2024-12-20 09:31:56.524 | ERROR    | utils.ClientLogManager:log:49 - Loop Failed! Error: Error in Opti::solve [OptiNode] at .../casadi/core/optistack.cpp:165:
.../casadi/core/optistack_internal.cpp:1030: Assertion "return_success(accept_limit)" failed:
Solver failed. You may use opti.debug.value to investigate the latest values of variables. return_status is 'NonIpopt_Exception_Thrown', occurred on line 48364 in file /home/turingzero/.local/lib/python3.10/site-packages/casadi/casadi.py
2024-12-20 09:31:57.024 | ERROR    | utils.ClientLogManager:log:49 - Loop Failed! Error: Error in Opti::solve [OptiNode] at .../casadi/core/optistack.cpp:165:
.../casadi/core/optistack_internal.cpp:1030: Assertion "return_success(accept_limit)" failed:
Solver failed. You may use opti.debug.value to investigate the latest values of variables. return_status is 'NonIpopt_Exception_Thrown', occurred on line 48364 in file /home/turingzero/.local/lib/python3.10/site-packages/casadi/casadi.py
2024-12-20 09:31:57.054 | ERROR    | utils.ClientLogManager:log:49 - Loop Failed! Error: Error in Opti::solve [OptiNode] at .../casadi/core/optistack.cpp:165:
.../casadi/core/optistack_internal.cpp:1030: Assertion "return_success(accept_limit)" failed:
Solver failed. You may use opti.debug.value to investigate the latest values of variables. return_status is 'NonIpopt_Exception_Thrown', occurred on line 48364 in file /home/turingzero/.local/lib/python3.10/site-packages/casadi/casadi.py
2024-12-20 09:31:57.084 | ERROR    | utils.ClientLogManager:log:49 - Loop Failed! Error: Error in Opti::solve [OptiNode] at .../casadi/core/optistack.cpp:165:
.../casadi/core/optistack_internal.cpp:1030: Assertion "return_success(accept_limit)" failed:
Solver failed. You may use opti.debug.value to investigate the latest values of variables. return_status is 'NonIpopt_Exception_Thrown', occurred on line 48364 in file /home/turingzero/.local/lib/python3.10/site-packages/casadi/casadi.py
2024-12-20 09:31:57.115 | ERROR    | utils.ClientLogManager:log:49 - Loop Failed! Error: Error in Opti::solve [OptiNode] at .../casadi/core/optistack.cpp:165:
.../casadi/core/optistack_internal.cpp:1030: Assertion "return_success(accept_limit)" failed:
Solver failed. You may use opti.debug.value to investigate the latest values of variables. return_status is 'NonIpopt_Exception_Thrown', occurred on line 48364 in file /home/turingzero/.local/lib/python3.10/site-packages/casadi/casadi.py
2024-12-20 09:31:57.144 | ERROR    | utils.ClientLogManager:log:49 - Loop Failed! Error: Error in Opti::solve [OptiNode] at .../casadi/core/optistack.cpp:165:
.../casadi/core/optistack_internal.cpp:1030: Assertion "return_success(accept_limit)" failed:
Solver failed. You may use opti.debug.value to investigate the latest values of variables. return_status is 'NonIpopt_Exception_Thrown', occurred on line 48364 in file /home/turingzero/.local/lib/python3.10/site-packages/casadi/casadi.py
2024-12-20 09:31:57.175 | ERROR    | utils.ClientLogManager:log:49 - Loop Failed! Error: Error in Opti::solve [OptiNode] at .../casadi/core/optistack.cpp:165:
.../casadi/core/optistack_internal.cpp:1030: Assertion "return_success(accept_limit)" failed:
Solver failed. You may use opti.debug.value to investigate the latest values of variables. return_status is 'NonIpopt_Exception_Thrown', occurred on line 48364 in file /home/turingzero/.local/lib/python3.10/site-packages/casadi/casadi.py
2024-12-20 09:31:57.204 | ERROR    | utils.ClientLogManager:log:49 - Loop Failed! Error: Error in Opti::solve [OptiNode] at .../casadi/core/optistack.cpp:165:
.../casadi/core/optistack_internal.cpp:1030: Assertion "return_success(accept_limit)" failed:
Solver failed. You may use opti.debug.value to investigate the latest values of variables. return_status is 'NonIpopt_Exception_Thrown', occurred on line 48364 in file /home/turingzero/.local/lib/python3.10/site-packages/casadi/casadi.py
2024-12-20 09:31:57.233 | ERROR    | utils.ClientLogManager:log:49 - Loop Failed! Error: Error in Opti::solve [OptiNode] at .../casadi/core/optistack.cpp:165:
.../casadi/core/optistack_internal.cpp:1030: Assertion "return_success(accept_limit)" failed:
Solver failed. You may use opti.debug.value to investigate the latest values of variables. return_status is 'NonIpopt_Exception_Thrown', occurred on line 48364 in file /home/turingzero/.local/lib/python3.10/site-packages/casadi/casadi.py
2024-12-20 09:31:57.264 | ERROR    | utils.ClientLogManager:log:49 - Loop Failed! Error: Error in Opti::solve [OptiNode] at .../casadi/core/optistack.cpp:165:
.../casadi/core/optistack_internal.cpp:1030: Assertion "return_success(accept_limit)" failed:
Solver failed. You may use opti.debug.value to investigate the latest values of variables. return_status is 'NonIpopt_Exception_Thrown', occurred on line 48364 in file /home/turingzero/.local/lib/python3.10/site-packages/casadi/casadi.py
2024-12-20 09:31:57.295 | ERROR    | utils.ClientLogManager:log:49 - Loop Failed! Error: Error in Opti::solve [OptiNode] at .../casadi/core/optistack.cpp:165:
.../casadi/core/optistack_internal.cpp:1030: Assertion "return_success(accept_limit)" failed:
Solver failed. You may use opti.debug.value to investigate the latest values of variables. return_status is 'NonIpopt_Exception_Thrown', occurred on line 48364 in file /home/turingzero/.local/lib/python3.10/site-packages/casadi/casadi.py
2024-12-20 09:31:57.325 | ERROR    | utils.ClientLogManager:log:49 - Loop Failed! Error: Error in Opti::solve [OptiNode] at .../casadi/core/optistack.cpp:165:
.../casadi/core/optistack_internal.cpp:1030: Assertion "return_success(accept_limit)" failed:
Solver failed. You may use opti.debug.value to investigate the latest values of variables. return_status is 'NonIpopt_Exception_Thrown', occurred on line 48364 in file /home/turingzero/.local/lib/python3.10/site-packages/casadi/casadi.py
2024-12-20 09:31:57.355 | ERROR    | utils.ClientLogManager:log:49 - Loop Failed! Error: Error in Opti::solve [OptiNode] at .../casadi/core/optistack.cpp:165:
.../casadi/core/optistack_internal.cpp:1030: Assertion "return_success(accept_limit)" failed:
Solver failed. You may use opti.debug.value to investigate the latest values of variables. return_status is 'NonIpopt_Exception_Thrown', occurred on line 48364 in file /home/turingzero/.local/lib/python3.10/site-packages/casadi/casadi.py
2024-12-20 09:31:57.385 | ERROR    | utils.ClientLogManager:log:49 - Loop Failed! Error: Error in Opti::solve [OptiNode] at .../casadi/core/optistack.cpp:165:
.../casadi/core/optistack_internal.cpp:1030: Assertion "return_success(accept_limit)" failed:
Solver failed. You may use opti.debug.value to investigate the latest values of variables. return_status is 'NonIpopt_Exception_Thrown', occurred on line 48364 in file /home/turingzero/.local/lib/python3.10/site-packages/casadi/casadi.py
2024-12-20 09:31:57.415 | ERROR    | utils.ClientLogManager:log:49 - Loop Failed! Error: Error in Opti::solve [OptiNode] at .../casadi/core/optistack.cpp:165:
.../casadi/core/optistack_internal.cpp:1030: Assertion "return_success(accept_limit)" failed:
Solver failed. You may use opti.debug.value to investigate the latest values of variables. return_status is 'NonIpopt_Exception_Thrown', occurred on line 48364 in file /home/turingzero/.local/lib/python3.10/site-packages/casadi/casadi.py
2024-12-20 09:31:57.446 | ERROR    | utils.ClientLogManager:log:49 - Loop Failed! Error: Error in Opti::solve [OptiNode] at .../casadi/core/optistack.cpp:165:
.../casadi/core/optistack_internal.cpp:1030: Assertion "return_success(accept_limit)" failed:
Solver failed. You may use opti.debug.value to investigate the latest values of variables. return_status is 'NonIpopt_Exception_Thrown', occurred on line 48364 in file /home/turingzero/.local/lib/python3.10/site-packages/casadi/casadi.py
2024-12-20 09:31:57.475 | ERROR    | utils.ClientLogManager:log:49 - Loop Failed! Error: Error in Opti::solve [OptiNode] at .../casadi/core/optistack.cpp:165:
.../casadi/core/optistack_internal.cpp:1030: Assertion "return_success(accept_limit)" failed:
Solver failed. You may use opti.debug.value to investigate the latest values of variables. return_status is 'NonIpopt_Exception_Thrown', occurred on line 48364 in file /home/turingzero/.local/lib/python3.10/site-packages/casadi/casadi.py
2024-12-20 09:31:57.505 | ERROR    | utils.ClientLogManager:log:49 - Loop Failed! Error: Error in Opti::solve [OptiNode] at .../casadi/core/optistack.cpp:165:
.../casadi/core/optistack_internal.cpp:1030: Assertion "return_success(accept_limit)" failed:
Solver failed. You may use opti.debug.value to investigate the latest values of variables. return_status is 'NonIpopt_Exception_Thrown', occurred on line 48364 in file /home/turingzero/.local/lib/python3.10/site-packages/casadi/casadi.py
2024-12-20 09:31:57.536 | ERROR    | utils.ClientLogManager:log:49 - Loop Failed! Error: Error in Opti::solve [OptiNode] at .../casadi/core/optistack.cpp:165:
.../casadi/core/optistack_internal.cpp:1030: Assertion "return_success(accept_limit)" failed:
Solver failed. You may use opti.debug.value to investigate the latest values of variables. return_status is 'NonIpopt_Exception_Thrown', occurred on line 48364 in file /home/turingzero/.local/lib/python3.10/site-packages/casadi/casadi.py
2024-12-20 09:31:57.565 | ERROR    | utils.ClientLogManager:log:49 - Loop Failed! Error: Error in Opti::solve [OptiNode] at .../casadi/core/optistack.cpp:165:
.../casadi/core/optistack_internal.cpp:1030: Assertion "return_success(accept_limit)" failed:
Solver failed. You may use opti.debug.value to investigate the latest values of variables. return_status is 'NonIpopt_Exception_Thrown', occurred on line 48364 in file /home/turingzero/.local/lib/python3.10/site-packages/casadi/casadi.py
2024-12-20 09:31:57.595 | ERROR    | utils.ClientLogManager:log:49 - Loop Failed! Error: Error in Opti::solve [OptiNode] at .../casadi/core/optistack.cpp:165:
.../casadi/core/optistack_internal.cpp:1030: Assertion "return_success(accept_limit)" failed:
Solver failed. You may use opti.debug.value to investigate the latest values of variables. return_status is 'NonIpopt_Exception_Thrown', occurred on line 48364 in file /home/turingzero/.local/lib/python3.10/site-packages/casadi/casadi.py
2024-12-20 09:31:57.625 | ERROR    | utils.ClientLogManager:log:49 - Loop Failed! Error: Error in Opti::solve [OptiNode] at .../casadi/core/optistack.cpp:165:
.../casadi/core/optistack_internal.cpp:1030: Assertion "return_success(accept_limit)" failed:
Solver failed. You may use opti.debug.value to investigate the latest values of variables. return_status is 'NonIpopt_Exception_Thrown', occurred on line 48364 in file /home/turingzero/.local/lib/python3.10/site-packages/casadi/casadi.py
2024-12-20 09:31:57.655 | ERROR    | utils.ClientLogManager:log:49 - Loop Failed! Error: Error in Opti::solve [OptiNode] at .../casadi/core/optistack.cpp:165:
.../casadi/core/optistack_internal.cpp:1030: Assertion "return_success(accept_limit)" failed:
Solver failed. You may use opti.debug.value to investigate the latest values of variables. return_status is 'NonIpopt_Exception_Thrown', occurred on line 48364 in file /home/turingzero/.local/lib/python3.10/site-packages/casadi/casadi.py
2024-12-20 09:31:57.685 | ERROR    | utils.ClientLogManager:log:49 - Loop Failed! Error: Error in Opti::solve [OptiNode] at .../casadi/core/optistack.cpp:165:
.../casadi/core/optistack_internal.cpp:1030: Assertion "return_success(accept_limit)" failed:
Solver failed. You may use opti.debug.value to investigate the latest values of variables. return_status is 'NonIpopt_Exception_Thrown', occurred on line 48364 in file /home/turingzero/.local/lib/python3.10/site-packages/casadi/casadi.py
2024-12-20 09:31:57.715 | ERROR    | utils.ClientLogManager:log:49 - Loop Failed! Error: Error in Opti::solve [OptiNode] at .../casadi/core/optistack.cpp:165:
.../casadi/core/optistack_internal.cpp:1030: Assertion "return_success(accept_limit)" failed:
Solver failed. You may use opti.debug.value to investigate the latest values of variables. return_status is 'NonIpopt_Exception_Thrown', occurred on line 48364 in file /home/turingzero/.local/lib/python3.10/site-packages/casadi/casadi.py
2024-12-20 09:31:57.746 | ERROR    | utils.ClientLogManager:log:49 - Loop Failed! Error: Error in Opti::solve [OptiNode] at .../casadi/core/optistack.cpp:165:
.../casadi/core/optistack_internal.cpp:1030: Assertion "return_success(accept_limit)" failed:
Solver failed. You may use opti.debug.value to investigate the latest values of variables. return_status is 'NonIpopt_Exception_Thrown', occurred on line 48364 in file /home/turingzero/.local/lib/python3.10/site-packages/casadi/casadi.py
2024-12-20 09:31:57.776 | ERROR    | utils.ClientLogManager:log:49 - Loop Failed! Error: Error in Opti::solve [OptiNode] at .../casadi/core/optistack.cpp:165:
.../casadi/core/optistack_internal.cpp:1030: Assertion "return_success(accept_limit)" failed:
Solver failed. You may use opti.debug.value to investigate the latest values of variables. return_status is 'NonIpopt_Exception_Thrown', occurred on line 48364 in file /home/turingzero/.local/lib/python3.10/site-packages/casadi/casadi.py
2024-12-20 09:31:57.806 | ERROR    | utils.ClientLogManager:log:49 - Loop Failed! Error: Error in Opti::solve [OptiNode] at .../casadi/core/optistack.cpp:165:
.../casadi/core/optistack_internal.cpp:1030: Assertion "return_success(accept_limit)" failed:
Solver failed. You may use opti.debug.value to investigate the latest values of variables. return_status is 'NonIpopt_Exception_Thrown', occurred on line 48364 in file /home/turingzero/.local/lib/python3.10/site-packages/casadi/casadi.py
2024-12-20 09:31:57.836 | ERROR    | utils.ClientLogManager:log:49 - Loop Failed! Error: Error in Opti::solve [OptiNode] at .../casadi/core/optistack.cpp:165:
.../casadi/core/optistack_internal.cpp:1030: Assertion "return_success(accept_limit)" failed:
Solver failed. You may use opti.debug.value to investigate the latest values of variables. return_status is 'NonIpopt_Exception_Thrown', occurred on line 48364 in file /home/turingzero/.local/lib/python3.10/site-packages/casadi/casadi.py
2024-12-20 09:31:57.866 | ERROR    | utils.ClientLogManager:log:49 - Loop Failed! Error: Error in Opti::solve [OptiNode] at .../casadi/core/optistack.cpp:165:
.../casadi/core/optistack_internal.cpp:1030: Assertion "return_success(accept_limit)" failed:
Solver failed. You may use opti.debug.value to investigate the latest values of variables. return_status is 'NonIpopt_Exception_Thrown', occurred on line 48364 in file /home/turingzero/.local/lib/python3.10/site-packages/casadi/casadi.py
2024-12-20 09:31:57.896 | ERROR    | utils.ClientLogManager:log:49 - Loop Failed! Error: Error in Opti::solve [OptiNode] at .../casadi/core/optistack.cpp:165:
.../casadi/core/optistack_internal.cpp:1030: Assertion "return_success(accept_limit)" failed:
Solver failed. You may use opti.debug.value to investigate the latest values of variables. return_status is 'NonIpopt_Exception_Thrown', occurred on line 48364 in file /home/turingzero/.local/lib/python3.10/site-packages/casadi/casadi.py
2024-12-20 09:31:57.926 | ERROR    | utils.ClientLogManager:log:49 - Loop Failed! Error: Error in Opti::solve [OptiNode] at .../casadi/core/optistack.cpp:165:
.../casadi/core/optistack_internal.cpp:1030: Assertion "return_success(accept_limit)" failed:
Solver failed. You may use opti.debug.value to investigate the latest values of variables. return_status is 'NonIpopt_Exception_Thrown', occurred on line 48364 in file /home/turingzero/.local/lib/python3.10/site-packages/casadi/casadi.py
2024-12-20 09:31:57.956 | ERROR    | utils.ClientLogManager:log:49 - Loop Failed! Error: Error in Opti::solve [OptiNode] at .../casadi/core/optistack.cpp:165:
.../casadi/core/optistack_internal.cpp:1030: Assertion "return_success(accept_limit)" failed:
Solver failed. You may use opti.debug.value to investigate the latest values of variables. return_status is 'NonIpopt_Exception_Thrown', occurred on line 48364 in file /home/turingzero/.local/lib/python3.10/site-packages/casadi/casadi.py
2024-12-20 09:32:23.235 | ERROR    | utils.ClientLogManager:log:49 - Loop Failed! Error: Error in Opti::solve [OptiNode] at .../casadi/core/optistack.cpp:165:
.../casadi/core/optistack_internal.cpp:1030: Assertion "return_success(accept_limit)" failed:
Solver failed. You may use opti.debug.value to investigate the latest values of variables. return_status is 'NonIpopt_Exception_Thrown', occurred on line 48364 in file /home/turingzero/.local/lib/python3.10/site-packages/casadi/casadi.py
2024-12-20 09:32:23.421 | ERROR    | utils.ClientLogManager:log:49 - Loop Failed! Error: Error in Opti::solve [OptiNode] at .../casadi/core/optistack.cpp:165:
.../casadi/core/optistack_internal.cpp:1030: Assertion "return_success(accept_limit)" failed:
Solver failed. You may use opti.debug.value to investigate the latest values of variables. return_status is 'NonIpopt_Exception_Thrown', occurred on line 48364 in file /home/turingzero/.local/lib/python3.10/site-packages/casadi/casadi.py
2024-12-20 09:32:23.608 | ERROR    | utils.ClientLogManager:log:49 - Loop Failed! Error: Error in Opti::solve [OptiNode] at .../casadi/core/optistack.cpp:165:
.../casadi/core/optistack_internal.cpp:1030: Assertion "return_success(accept_limit)" failed:
Solver failed. You may use opti.debug.value to investigate the latest values of variables. return_status is 'NonIpopt_Exception_Thrown', occurred on line 48364 in file /home/turingzero/.local/lib/python3.10/site-packages/casadi/casadi.py
2024-12-20 09:32:23.809 | ERROR    | utils.ClientLogManager:log:49 - Loop Failed! Error: Error in Opti::solve [OptiNode] at .../casadi/core/optistack.cpp:165:
.../casadi/core/optistack_internal.cpp:1030: Assertion "return_success(accept_limit)" failed:
Solver failed. You may use opti.debug.value to investigate the latest values of variables. return_status is 'NonIpopt_Exception_Thrown', occurred on line 48364 in file /home/turingzero/.local/lib/python3.10/site-packages/casadi/casadi.py
2024-12-20 09:32:24.309 | ERROR    | utils.ClientLogManager:log:49 - Loop Failed! Error: Error in Opti::solve [OptiNode] at .../casadi/core/optistack.cpp:165:
.../casadi/core/optistack_internal.cpp:1030: Assertion "return_success(accept_limit)" failed:
Solver failed. You may use opti.debug.value to investigate the latest values of variables. return_status is 'NonIpopt_Exception_Thrown', occurred on line 48364 in file /home/turingzero/.local/lib/python3.10/site-packages/casadi/casadi.py
2024-12-20 09:32:24.339 | ERROR    | utils.ClientLogManager:log:49 - Loop Failed! Error: Error in Opti::solve [OptiNode] at .../casadi/core/optistack.cpp:165:
.../casadi/core/optistack_internal.cpp:1030: Assertion "return_success(accept_limit)" failed:
Solver failed. You may use opti.debug.value to investigate the latest values of variables. return_status is 'NonIpopt_Exception_Thrown', occurred on line 48364 in file /home/turingzero/.local/lib/python3.10/site-packages/casadi/casadi.py
2024-12-20 09:32:24.369 | ERROR    | utils.ClientLogManager:log:49 - Loop Failed! Error: Error in Opti::solve [OptiNode] at .../casadi/core/optistack.cpp:165:
.../casadi/core/optistack_internal.cpp:1030: Assertion "return_success(accept_limit)" failed:
Solver failed. You may use opti.debug.value to investigate the latest values of variables. return_status is 'NonIpopt_Exception_Thrown', occurred on line 48364 in file /home/turingzero/.local/lib/python3.10/site-packages/casadi/casadi.py
2024-12-20 09:32:24.399 | ERROR    | utils.ClientLogManager:log:49 - Loop Failed! Error: Error in Opti::solve [OptiNode] at .../casadi/core/optistack.cpp:165:
.../casadi/core/optistack_internal.cpp:1030: Assertion "return_success(accept_limit)" failed:
Solver failed. You may use opti.debug.value to investigate the latest values of variables. return_status is 'NonIpopt_Exception_Thrown', occurred on line 48364 in file /home/turingzero/.local/lib/python3.10/site-packages/casadi/casadi.py
2024-12-20 09:32:24.430 | ERROR    | utils.ClientLogManager:log:49 - Loop Failed! Error: Error in Opti::solve [OptiNode] at .../casadi/core/optistack.cpp:165:
.../casadi/core/optistack_internal.cpp:1030: Assertion "return_success(accept_limit)" failed:
Solver failed. You may use opti.debug.value to investigate the latest values of variables. return_status is 'NonIpopt_Exception_Thrown', occurred on line 48364 in file /home/turingzero/.local/lib/python3.10/site-packages/casadi/casadi.py
2024-12-20 09:32:24.461 | ERROR    | utils.ClientLogManager:log:49 - Loop Failed! Error: Error in Opti::solve [OptiNode] at .../casadi/core/optistack.cpp:165:
.../casadi/core/optistack_internal.cpp:1030: Assertion "return_success(accept_limit)" failed:
Solver failed. You may use opti.debug.value to investigate the latest values of variables. return_status is 'NonIpopt_Exception_Thrown', occurred on line 48364 in file /home/turingzero/.local/lib/python3.10/site-packages/casadi/casadi.py
2024-12-20 09:32:24.490 | ERROR    | utils.ClientLogManager:log:49 - Loop Failed! Error: Error in Opti::solve [OptiNode] at .../casadi/core/optistack.cpp:165:
.../casadi/core/optistack_internal.cpp:1030: Assertion "return_success(accept_limit)" failed:
Solver failed. You may use opti.debug.value to investigate the latest values of variables. return_status is 'NonIpopt_Exception_Thrown', occurred on line 48364 in file /home/turingzero/.local/lib/python3.10/site-packages/casadi/casadi.py
2024-12-20 09:32:24.519 | ERROR    | utils.ClientLogManager:log:49 - Loop Failed! Error: _PyEval_EvalFrameDefault returned a result with an exception set, occurred on line 112 in file /home/turingzero/Downloads/TBK-Client/utils/MPCPlanner.py
2024-12-20 09:32:24.550 | ERROR    | utils.ClientLogManager:log:49 - Loop Failed! Error: Error in Opti::solve [OptiNode] at .../casadi/core/optistack.cpp:165:
.../casadi/core/optistack_internal.cpp:1030: Assertion "return_success(accept_limit)" failed:
Solver failed. You may use opti.debug.value to investigate the latest values of variables. return_status is 'NonIpopt_Exception_Thrown', occurred on line 48364 in file /home/turingzero/.local/lib/python3.10/site-packages/casadi/casadi.py
2024-12-20 09:32:24.581 | ERROR    | utils.ClientLogManager:log:49 - Loop Failed! Error: Error in Opti::solve [OptiNode] at .../casadi/core/optistack.cpp:165:
.../casadi/core/optistack_internal.cpp:1030: Assertion "return_success(accept_limit)" failed:
Solver failed. You may use opti.debug.value to investigate the latest values of variables. return_status is 'NonIpopt_Exception_Thrown', occurred on line 48364 in file /home/turingzero/.local/lib/python3.10/site-packages/casadi/casadi.py
2024-12-20 09:32:24.611 | ERROR    | utils.ClientLogManager:log:49 - Loop Failed! Error: Error in Opti::solve [OptiNode] at .../casadi/core/optistack.cpp:165:
.../casadi/core/optistack_internal.cpp:1030: Assertion "return_success(accept_limit)" failed:
Solver failed. You may use opti.debug.value to investigate the latest values of variables. return_status is 'NonIpopt_Exception_Thrown', occurred on line 48364 in file /home/turingzero/.local/lib/python3.10/site-packages/casadi/casadi.py
2024-12-20 09:32:24.641 | ERROR    | utils.ClientLogManager:log:49 - Loop Failed! Error: Error in Opti::solve [OptiNode] at .../casadi/core/optistack.cpp:165:
.../casadi/core/optistack_internal.cpp:1030: Assertion "return_success(accept_limit)" failed:
Solver failed. You may use opti.debug.value to investigate the latest values of variables. return_status is 'NonIpopt_Exception_Thrown', occurred on line 48364 in file /home/turingzero/.local/lib/python3.10/site-packages/casadi/casadi.py
2024-12-20 09:32:24.672 | ERROR    | utils.ClientLogManager:log:49 - Loop Failed! Error: Error in Opti::solve [OptiNode] at .../casadi/core/optistack.cpp:165:
.../casadi/core/optistack_internal.cpp:1030: Assertion "return_success(accept_limit)" failed:
Solver failed. You may use opti.debug.value to investigate the latest values of variables. return_status is 'NonIpopt_Exception_Thrown', occurred on line 48364 in file /home/turingzero/.local/lib/python3.10/site-packages/casadi/casadi.py
2024-12-20 09:32:24.702 | ERROR    | utils.ClientLogManager:log:49 - Loop Failed! Error: Error in Opti::solve [OptiNode] at .../casadi/core/optistack.cpp:165:
.../casadi/core/optistack_internal.cpp:1030: Assertion "return_success(accept_limit)" failed:
Solver failed. You may use opti.debug.value to investigate the latest values of variables. return_status is 'NonIpopt_Exception_Thrown', occurred on line 48364 in file /home/turingzero/.local/lib/python3.10/site-packages/casadi/casadi.py
2024-12-20 09:32:24.732 | ERROR    | utils.ClientLogManager:log:49 - Loop Failed! Error: Error in Opti::solve [OptiNode] at .../casadi/core/optistack.cpp:165:
.../casadi/core/optistack_internal.cpp:1030: Assertion "return_success(accept_limit)" failed:
Solver failed. You may use opti.debug.value to investigate the latest values of variables. return_status is 'NonIpopt_Exception_Thrown', occurred on line 48364 in file /home/turingzero/.local/lib/python3.10/site-packages/casadi/casadi.py
2024-12-20 09:32:24.762 | ERROR    | utils.ClientLogManager:log:49 - Loop Failed! Error: Error in Opti::solve [OptiNode] at .../casadi/core/optistack.cpp:165:
.../casadi/core/optistack_internal.cpp:1030: Assertion "return_success(accept_limit)" failed:
Solver failed. You may use opti.debug.value to investigate the latest values of variables. return_status is 'NonIpopt_Exception_Thrown', occurred on line 48364 in file /home/turingzero/.local/lib/python3.10/site-packages/casadi/casadi.py
2024-12-20 09:32:24.792 | ERROR    | utils.ClientLogManager:log:49 - Loop Failed! Error: Error in Opti::solve [OptiNode] at .../casadi/core/optistack.cpp:165:
.../casadi/core/optistack_internal.cpp:1030: Assertion "return_success(accept_limit)" failed:
Solver failed. You may use opti.debug.value to investigate the latest values of variables. return_status is 'NonIpopt_Exception_Thrown', occurred on line 48364 in file /home/turingzero/.local/lib/python3.10/site-packages/casadi/casadi.py
2024-12-20 09:32:24.822 | ERROR    | utils.ClientLogManager:log:49 - Loop Failed! Error: Error in Opti::solve [OptiNode] at .../casadi/core/optistack.cpp:165:
.../casadi/core/optistack_internal.cpp:1030: Assertion "return_success(accept_limit)" failed:
Solver failed. You may use opti.debug.value to investigate the latest values of variables. return_status is 'NonIpopt_Exception_Thrown', occurred on line 48364 in file /home/turingzero/.local/lib/python3.10/site-packages/casadi/casadi.py
2024-12-20 09:32:24.852 | ERROR    | utils.ClientLogManager:log:49 - Loop Failed! Error: Error in Opti::solve [OptiNode] at .../casadi/core/optistack.cpp:165:
.../casadi/core/optistack_internal.cpp:1030: Assertion "return_success(accept_limit)" failed:
Solver failed. You may use opti.debug.value to investigate the latest values of variables. return_status is 'NonIpopt_Exception_Thrown', occurred on line 48364 in file /home/turingzero/.local/lib/python3.10/site-packages/casadi/casadi.py
2024-12-20 09:32:24.882 | ERROR    | utils.ClientLogManager:log:49 - Loop Failed! Error: Error in Opti::solve [OptiNode] at .../casadi/core/optistack.cpp:165:
.../casadi/core/optistack_internal.cpp:1030: Assertion "return_success(accept_limit)" failed:
Solver failed. You may use opti.debug.value to investigate the latest values of variables. return_status is 'NonIpopt_Exception_Thrown', occurred on line 48364 in file /home/turingzero/.local/lib/python3.10/site-packages/casadi/casadi.py
2024-12-20 09:32:24.912 | ERROR    | utils.ClientLogManager:log:49 - Loop Failed! Error: Error in Opti::solve [OptiNode] at .../casadi/core/optistack.cpp:165:
.../casadi/core/optistack_internal.cpp:1030: Assertion "return_success(accept_limit)" failed:
Solver failed. You may use opti.debug.value to investigate the latest values of variables. return_status is 'NonIpopt_Exception_Thrown', occurred on line 48364 in file /home/turingzero/.local/lib/python3.10/site-packages/casadi/casadi.py
2024-12-20 09:32:24.943 | ERROR    | utils.ClientLogManager:log:49 - Loop Failed! Error: Error in Opti::solve [OptiNode] at .../casadi/core/optistack.cpp:165:
.../casadi/core/optistack_internal.cpp:1030: Assertion "return_success(accept_limit)" failed:
Solver failed. You may use opti.debug.value to investigate the latest values of variables. return_status is 'NonIpopt_Exception_Thrown', occurred on line 48364 in file /home/turingzero/.local/lib/python3.10/site-packages/casadi/casadi.py
2024-12-20 09:32:24.972 | ERROR    | utils.ClientLogManager:log:49 - Loop Failed! Error: Error in Opti::solve [OptiNode] at .../casadi/core/optistack.cpp:165:
.../casadi/core/optistack_internal.cpp:1030: Assertion "return_success(accept_limit)" failed:
Solver failed. You may use opti.debug.value to investigate the latest values of variables. return_status is 'NonIpopt_Exception_Thrown', occurred on line 48364 in file /home/turingzero/.local/lib/python3.10/site-packages/casadi/casadi.py
2024-12-20 09:32:25.002 | ERROR    | utils.ClientLogManager:log:49 - Loop Failed! Error: Error in Opti::solve [OptiNode] at .../casadi/core/optistack.cpp:165:
.../casadi/core/optistack_internal.cpp:1030: Assertion "return_success(accept_limit)" failed:
Solver failed. You may use opti.debug.value to investigate the latest values of variables. return_status is 'NonIpopt_Exception_Thrown', occurred on line 48364 in file /home/turingzero/.local/lib/python3.10/site-packages/casadi/casadi.py
2024-12-20 09:32:25.033 | ERROR    | utils.ClientLogManager:log:49 - Loop Failed! Error: Error in Opti::solve [OptiNode] at .../casadi/core/optistack.cpp:165:
.../casadi/core/optistack_internal.cpp:1030: Assertion "return_success(accept_limit)" failed:
Solver failed. You may use opti.debug.value to investigate the latest values of variables. return_status is 'NonIpopt_Exception_Thrown', occurred on line 48364 in file /home/turingzero/.local/lib/python3.10/site-packages/casadi/casadi.py
2024-12-20 09:32:25.064 | ERROR    | utils.ClientLogManager:log:49 - Loop Failed! Error: Error in Opti::solve [OptiNode] at .../casadi/core/optistack.cpp:165:
.../casadi/core/optistack_internal.cpp:1030: Assertion "return_success(accept_limit)" failed:
Solver failed. You may use opti.debug.value to investigate the latest values of variables. return_status is 'NonIpopt_Exception_Thrown', occurred on line 48364 in file /home/turingzero/.local/lib/python3.10/site-packages/casadi/casadi.py
2024-12-20 09:32:25.093 | ERROR    | utils.ClientLogManager:log:49 - Loop Failed! Error: Error in Opti::solve [OptiNode] at .../casadi/core/optistack.cpp:165:
.../casadi/core/optistack_internal.cpp:1030: Assertion "return_success(accept_limit)" failed:
Solver failed. You may use opti.debug.value to investigate the latest values of variables. return_status is 'NonIpopt_Exception_Thrown', occurred on line 48364 in file /home/turingzero/.local/lib/python3.10/site-packages/casadi/casadi.py
2024-12-20 09:32:25.123 | ERROR    | utils.ClientLogManager:log:49 - Loop Failed! Error: Error in Opti::solve [OptiNode] at .../casadi/core/optistack.cpp:165:
.../casadi/core/optistack_internal.cpp:1030: Assertion "return_success(accept_limit)" failed:
Solver failed. You may use opti.debug.value to investigate the latest values of variables. return_status is 'NonIpopt_Exception_Thrown', occurred on line 48364 in file /home/turingzero/.local/lib/python3.10/site-packages/casadi/casadi.py
2024-12-20 09:32:25.152 | ERROR    | utils.ClientLogManager:log:49 - Loop Failed! Error: Error in Opti::solve [OptiNode] at .../casadi/core/optistack.cpp:165:
.../casadi/core/optistack_internal.cpp:1030: Assertion "return_success(accept_limit)" failed:
Solver failed. You may use opti.debug.value to investigate the latest values of variables. return_status is 'NonIpopt_Exception_Thrown', occurred on line 48364 in file /home/turingzero/.local/lib/python3.10/site-packages/casadi/casadi.py
2024-12-20 09:32:25.182 | ERROR    | utils.ClientLogManager:log:49 - Loop Failed! Error: Error in Opti::solve [OptiNode] at .../casadi/core/optistack.cpp:165:
.../casadi/core/optistack_internal.cpp:1030: Assertion "return_success(accept_limit)" failed:
Solver failed. You may use opti.debug.value to investigate the latest values of variables. return_status is 'NonIpopt_Exception_Thrown', occurred on line 48364 in file /home/turingzero/.local/lib/python3.10/site-packages/casadi/casadi.py
2024-12-20 09:32:25.214 | ERROR    | utils.ClientLogManager:log:49 - Loop Failed! Error: Error in Opti::solve [OptiNode] at .../casadi/core/optistack.cpp:165:
.../casadi/core/optistack_internal.cpp:1030: Assertion "return_success(accept_limit)" failed:
Solver failed. You may use opti.debug.value to investigate the latest values of variables. return_status is 'NonIpopt_Exception_Thrown', occurred on line 48364 in file /home/turingzero/.local/lib/python3.10/site-packages/casadi/casadi.py
2024-12-20 09:32:25.244 | ERROR    | utils.ClientLogManager:log:49 - Loop Failed! Error: Error in Opti::solve [OptiNode] at .../casadi/core/optistack.cpp:165:
.../casadi/core/optistack_internal.cpp:1030: Assertion "return_success(accept_limit)" failed:
Solver failed. You may use opti.debug.value to investigate the latest values of variables. return_status is 'NonIpopt_Exception_Thrown', occurred on line 48364 in file /home/turingzero/.local/lib/python3.10/site-packages/casadi/casadi.py
2024-12-20 09:32:25.273 | ERROR    | utils.ClientLogManager:log:49 - Loop Failed! Error: Error in Opti::solve [OptiNode] at .../casadi/core/optistack.cpp:165:
.../casadi/core/optistack_internal.cpp:1030: Assertion "return_success(accept_limit)" failed:
Solver failed. You may use opti.debug.value to investigate the latest values of variables. return_status is 'NonIpopt_Exception_Thrown', occurred on line 48364 in file /home/turingzero/.local/lib/python3.10/site-packages/casadi/casadi.py
2024-12-20 09:32:25.335 | ERROR    | utils.ClientLogManager:log:49 - Loop Failed! Error: Error in Opti::solve [OptiNode] at .../casadi/core/optistack.cpp:165:
.../casadi/core/optistack_internal.cpp:1030: Assertion "return_success(accept_limit)" failed:
Solver failed. You may use opti.debug.value to investigate the latest values of variables. return_status is 'NonIpopt_Exception_Thrown', occurred on line 48364 in file /home/turingzero/.local/lib/python3.10/site-packages/casadi/casadi.py
2024-12-20 09:32:25.363 | ERROR    | utils.ClientLogManager:log:49 - Loop Failed! Error: Error in Opti::solve [OptiNode] at .../casadi/core/optistack.cpp:165:
.../casadi/core/optistack_internal.cpp:1030: Assertion "return_success(accept_limit)" failed:
Solver failed. You may use opti.debug.value to investigate the latest values of variables. return_status is 'NonIpopt_Exception_Thrown', occurred on line 48364 in file /home/turingzero/.local/lib/python3.10/site-packages/casadi/casadi.py
2024-12-20 09:32:25.397 | ERROR    | utils.ClientLogManager:log:49 - Loop Failed! Error: Error in Opti::solve [OptiNode] at .../casadi/core/optistack.cpp:165:
.../casadi/core/optistack_internal.cpp:1030: Assertion "return_success(accept_limit)" failed:
Solver failed. You may use opti.debug.value to investigate the latest values of variables. return_status is 'NonIpopt_Exception_Thrown', occurred on line 48364 in file /home/turingzero/.local/lib/python3.10/site-packages/casadi/casadi.py
2024-12-20 09:32:25.424 | ERROR    | utils.ClientLogManager:log:49 - Loop Failed! Error: Error in Opti::solve [OptiNode] at .../casadi/core/optistack.cpp:165:
.../casadi/core/optistack_internal.cpp:1030: Assertion "return_success(accept_limit)" failed:
Solver failed. You may use opti.debug.value to investigate the latest values of variables. return_status is 'NonIpopt_Exception_Thrown', occurred on line 48364 in file /home/turingzero/.local/lib/python3.10/site-packages/casadi/casadi.py
2024-12-20 09:32:25.453 | ERROR    | utils.ClientLogManager:log:49 - Loop Failed! Error: Error in Opti::solve [OptiNode] at .../casadi/core/optistack.cpp:165:
.../casadi/core/optistack_internal.cpp:1030: Assertion "return_success(accept_limit)" failed:
Solver failed. You may use opti.debug.value to investigate the latest values of variables. return_status is 'NonIpopt_Exception_Thrown', occurred on line 48364 in file /home/turingzero/.local/lib/python3.10/site-packages/casadi/casadi.py
2024-12-20 09:32:25.483 | ERROR    | utils.ClientLogManager:log:49 - Loop Failed! Error: Error in Opti::solve [OptiNode] at .../casadi/core/optistack.cpp:165:
.../casadi/core/optistack_internal.cpp:1030: Assertion "return_success(accept_limit)" failed:
Solver failed. You may use opti.debug.value to investigate the latest values of variables. return_status is 'NonIpopt_Exception_Thrown', occurred on line 48364 in file /home/turingzero/.local/lib/python3.10/site-packages/casadi/casadi.py
2024-12-20 09:32:25.514 | ERROR    | utils.ClientLogManager:log:49 - Loop Failed! Error: Error in Opti::solve [OptiNode] at .../casadi/core/optistack.cpp:165:
.../casadi/core/optistack_internal.cpp:1030: Assertion "return_success(accept_limit)" failed:
Solver failed. You may use opti.debug.value to investigate the latest values of variables. return_status is 'NonIpopt_Exception_Thrown', occurred on line 48364 in file /home/turingzero/.local/lib/python3.10/site-packages/casadi/casadi.py
2024-12-20 09:32:25.543 | ERROR    | utils.ClientLogManager:log:49 - Loop Failed! Error: Error in Opti::solve [OptiNode] at .../casadi/core/optistack.cpp:165:
.../casadi/core/optistack_internal.cpp:1030: Assertion "return_success(accept_limit)" failed:
Solver failed. You may use opti.debug.value to investigate the latest values of variables. return_status is 'NonIpopt_Exception_Thrown', occurred on line 48364 in file /home/turingzero/.local/lib/python3.10/site-packages/casadi/casadi.py
2024-12-20 09:32:25.573 | ERROR    | utils.ClientLogManager:log:49 - Loop Failed! Error: Error in Opti::solve [OptiNode] at .../casadi/core/optistack.cpp:165:
.../casadi/core/optistack_internal.cpp:1030: Assertion "return_success(accept_limit)" failed:
Solver failed. You may use opti.debug.value to investigate the latest values of variables. return_status is 'NonIpopt_Exception_Thrown', occurred on line 48364 in file /home/turingzero/.local/lib/python3.10/site-packages/casadi/casadi.py
2024-12-20 09:32:25.603 | ERROR    | utils.ClientLogManager:log:49 - Loop Failed! Error: Error in Opti::solve [OptiNode] at .../casadi/core/optistack.cpp:165:
.../casadi/core/optistack_internal.cpp:1030: Assertion "return_success(accept_limit)" failed:
Solver failed. You may use opti.debug.value to investigate the latest values of variables. return_status is 'NonIpopt_Exception_Thrown', occurred on line 48364 in file /home/turingzero/.local/lib/python3.10/site-packages/casadi/casadi.py
2024-12-20 09:32:25.633 | ERROR    | utils.ClientLogManager:log:49 - Loop Failed! Error: Error in Opti::solve [OptiNode] at .../casadi/core/optistack.cpp:165:
.../casadi/core/optistack_internal.cpp:1030: Assertion "return_success(accept_limit)" failed:
Solver failed. You may use opti.debug.value to investigate the latest values of variables. return_status is 'NonIpopt_Exception_Thrown', occurred on line 48364 in file /home/turingzero/.local/lib/python3.10/site-packages/casadi/casadi.py
2024-12-20 09:32:25.664 | ERROR    | utils.ClientLogManager:log:49 - Loop Failed! Error: Error in Opti::solve [OptiNode] at .../casadi/core/optistack.cpp:165:
.../casadi/core/optistack_internal.cpp:1030: Assertion "return_success(accept_limit)" failed:
Solver failed. You may use opti.debug.value to investigate the latest values of variables. return_status is 'NonIpopt_Exception_Thrown', occurred on line 48364 in file /home/turingzero/.local/lib/python3.10/site-packages/casadi/casadi.py
2024-12-20 09:32:25.693 | ERROR    | utils.ClientLogManager:log:49 - Loop Failed! Error: Error in Opti::solve [OptiNode] at .../casadi/core/optistack.cpp:165:
.../casadi/core/optistack_internal.cpp:1030: Assertion "return_success(accept_limit)" failed:
Solver failed. You may use opti.debug.value to investigate the latest values of variables. return_status is 'NonIpopt_Exception_Thrown', occurred on line 48364 in file /home/turingzero/.local/lib/python3.10/site-packages/casadi/casadi.py
2024-12-20 09:32:25.723 | ERROR    | utils.ClientLogManager:log:49 - Loop Failed! Error: Error in Opti::solve [OptiNode] at .../casadi/core/optistack.cpp:165:
.../casadi/core/optistack_internal.cpp:1030: Assertion "return_success(accept_limit)" failed:
Solver failed. You may use opti.debug.value to investigate the latest values of variables. return_status is 'NonIpopt_Exception_Thrown', occurred on line 48364 in file /home/turingzero/.local/lib/python3.10/site-packages/casadi/casadi.py
2024-12-20 09:32:25.753 | ERROR    | utils.ClientLogManager:log:49 - Loop Failed! Error: Error in Opti::solve [OptiNode] at .../casadi/core/optistack.cpp:165:
.../casadi/core/optistack_internal.cpp:1030: Assertion "return_success(accept_limit)" failed:
Solver failed. You may use opti.debug.value to investigate the latest values of variables. return_status is 'NonIpopt_Exception_Thrown', occurred on line 48364 in file /home/turingzero/.local/lib/python3.10/site-packages/casadi/casadi.py
2024-12-20 09:32:25.783 | ERROR    | utils.ClientLogManager:log:49 - Loop Failed! Error: Error in Opti::solve [OptiNode] at .../casadi/core/optistack.cpp:165:
.../casadi/core/optistack_internal.cpp:1030: Assertion "return_success(accept_limit)" failed:
Solver failed. You may use opti.debug.value to investigate the latest values of variables. return_status is 'NonIpopt_Exception_Thrown', occurred on line 48364 in file /home/turingzero/.local/lib/python3.10/site-packages/casadi/casadi.py
2024-12-20 09:32:26.030 | ERROR    | utils.ClientLogManager:log:49 - Loop Failed! Error: Wrong number or type of arguments for function 'Opti_set_value'.
  Prototype:
set_value(self,MX,DM)
  You have: '(Opti,MX,np.array(float))'
, occurred on line 48297 in file /home/turingzero/.local/lib/python3.10/site-packages/casadi/casadi.py
2024-12-20 09:32:26.031 | ERROR    | utils.ClientLogManager:log:49 - Loop Failed! Error: Wrong number or type of arguments for overloaded function 'Opti_set_value'.
  Possible prototypes are:
    set_value(self,[MX])
    set_value(self,MX,DM)
  You have: '(Opti,tuple_iterator,np.array(float))'
, occurred on line 48297 in file /home/turingzero/.local/lib/python3.10/site-packages/casadi/casadi.py
2024-12-20 09:40:02.529 | ERROR    | utils.ClientLogManager:log:49 - Loop Failed! Error: Error in Opti::solve [OptiNode] at .../casadi/core/optistack.cpp:165:
.../casadi/core/optistack_internal.cpp:1030: Assertion "return_success(accept_limit)" failed:
Solver failed. You may use opti.debug.value to investigate the latest values of variables. return_status is 'NonIpopt_Exception_Thrown', occurred on line 48364 in file /home/turingzero/.local/lib/python3.10/site-packages/casadi/casadi.py
2024-12-20 09:40:02.721 | ERROR    | utils.ClientLogManager:log:49 - Loop Failed! Error: Error in Opti::solve [OptiNode] at .../casadi/core/optistack.cpp:165:
.../casadi/core/optistack_internal.cpp:1030: Assertion "return_success(accept_limit)" failed:
Solver failed. You may use opti.debug.value to investigate the latest values of variables. return_status is 'NonIpopt_Exception_Thrown', occurred on line 48364 in file /home/turingzero/.local/lib/python3.10/site-packages/casadi/casadi.py
2024-12-20 09:40:02.901 | ERROR    | utils.ClientLogManager:log:49 - Loop Failed! Error: Error in Opti::solve [OptiNode] at .../casadi/core/optistack.cpp:165:
.../casadi/core/optistack_internal.cpp:1030: Assertion "return_success(accept_limit)" failed:
Solver failed. You may use opti.debug.value to investigate the latest values of variables. return_status is 'NonIpopt_Exception_Thrown', occurred on line 48364 in file /home/turingzero/.local/lib/python3.10/site-packages/casadi/casadi.py
2024-12-20 09:40:03.092 | ERROR    | utils.ClientLogManager:log:49 - Loop Failed! Error: Error in Opti::solve [OptiNode] at .../casadi/core/optistack.cpp:165:
.../casadi/core/optistack_internal.cpp:1030: Assertion "return_success(accept_limit)" failed:
Solver failed. You may use opti.debug.value to investigate the latest values of variables. return_status is 'NonIpopt_Exception_Thrown', occurred on line 48364 in file /home/turingzero/.local/lib/python3.10/site-packages/casadi/casadi.py
2024-12-20 09:40:03.269 | ERROR    | utils.ClientLogManager:log:49 - Loop Failed! Error: <built-in function OptiSol_value> returned a result with an exception set, occurred on line 50861 in file /home/turingzero/.local/lib/python3.10/site-packages/casadi/casadi.py
2024-12-20 09:40:04.784 | ERROR    | utils.ClientLogManager:log:49 - Loop Failed! Error: Error in Opti::solve [OptiNode] at .../casadi/core/optistack.cpp:165:
.../casadi/core/optistack_internal.cpp:1030: Assertion "return_success(accept_limit)" failed:
Solver failed. You may use opti.debug.value to investigate the latest values of variables. return_status is 'NonIpopt_Exception_Thrown', occurred on line 48364 in file /home/turingzero/.local/lib/python3.10/site-packages/casadi/casadi.py
2024-12-20 09:40:04.949 | ERROR    | utils.ClientLogManager:log:49 - Loop Failed! Error: Error in Opti::solve [OptiNode] at .../casadi/core/optistack.cpp:165:
.../casadi/core/optistack_internal.cpp:1030: Assertion "return_success(accept_limit)" failed:
Solver failed. You may use opti.debug.value to investigate the latest values of variables. return_status is 'NonIpopt_Exception_Thrown', occurred on line 48364 in file /home/turingzero/.local/lib/python3.10/site-packages/casadi/casadi.py
2024-12-20 09:40:05.448 | ERROR    | utils.ClientLogManager:log:49 - Loop Failed! Error: Error in Opti::solve [OptiNode] at .../casadi/core/optistack.cpp:165:
.../casadi/core/optistack_internal.cpp:1030: Assertion "return_success(accept_limit)" failed:
Solver failed. You may use opti.debug.value to investigate the latest values of variables. return_status is 'NonIpopt_Exception_Thrown', occurred on line 48364 in file /home/turingzero/.local/lib/python3.10/site-packages/casadi/casadi.py
2024-12-20 09:40:05.479 | ERROR    | utils.ClientLogManager:log:49 - Loop Failed! Error: Error in Opti::solve [OptiNode] at .../casadi/core/optistack.cpp:165:
.../casadi/core/optistack_internal.cpp:1030: Assertion "return_success(accept_limit)" failed:
Solver failed. You may use opti.debug.value to investigate the latest values of variables. return_status is 'NonIpopt_Exception_Thrown', occurred on line 48364 in file /home/turingzero/.local/lib/python3.10/site-packages/casadi/casadi.py
2024-12-20 09:40:05.508 | ERROR    | utils.ClientLogManager:log:49 - Loop Failed! Error: Error in Opti::solve [OptiNode] at .../casadi/core/optistack.cpp:165:
.../casadi/core/optistack_internal.cpp:1030: Assertion "return_success(accept_limit)" failed:
Solver failed. You may use opti.debug.value to investigate the latest values of variables. return_status is 'NonIpopt_Exception_Thrown', occurred on line 48364 in file /home/turingzero/.local/lib/python3.10/site-packages/casadi/casadi.py
2024-12-20 09:40:05.538 | ERROR    | utils.ClientLogManager:log:49 - Loop Failed! Error: Error in Opti::solve [OptiNode] at .../casadi/core/optistack.cpp:165:
.../casadi/core/optistack_internal.cpp:1030: Assertion "return_success(accept_limit)" failed:
Solver failed. You may use opti.debug.value to investigate the latest values of variables. return_status is 'NonIpopt_Exception_Thrown', occurred on line 48364 in file /home/turingzero/.local/lib/python3.10/site-packages/casadi/casadi.py
2024-12-20 09:40:05.568 | ERROR    | utils.ClientLogManager:log:49 - Loop Failed! Error: Error in Opti::solve [OptiNode] at .../casadi/core/optistack.cpp:165:
.../casadi/core/optistack_internal.cpp:1030: Assertion "return_success(accept_limit)" failed:
Solver failed. You may use opti.debug.value to investigate the latest values of variables. return_status is 'NonIpopt_Exception_Thrown', occurred on line 48364 in file /home/turingzero/.local/lib/python3.10/site-packages/casadi/casadi.py
2024-12-20 09:40:05.598 | ERROR    | utils.ClientLogManager:log:49 - Loop Failed! Error: Error in Opti::solve [OptiNode] at .../casadi/core/optistack.cpp:165:
.../casadi/core/optistack_internal.cpp:1030: Assertion "return_success(accept_limit)" failed:
Solver failed. You may use opti.debug.value to investigate the latest values of variables. return_status is 'NonIpopt_Exception_Thrown', occurred on line 48364 in file /home/turingzero/.local/lib/python3.10/site-packages/casadi/casadi.py
2024-12-20 09:40:05.628 | ERROR    | utils.ClientLogManager:log:49 - Loop Failed! Error: Error in Opti::solve [OptiNode] at .../casadi/core/optistack.cpp:165:
.../casadi/core/optistack_internal.cpp:1030: Assertion "return_success(accept_limit)" failed:
Solver failed. You may use opti.debug.value to investigate the latest values of variables. return_status is 'NonIpopt_Exception_Thrown', occurred on line 48364 in file /home/turingzero/.local/lib/python3.10/site-packages/casadi/casadi.py
