2024-12-26 10:16:37.299 | ERROR    | utils.ClientLogManager:log:49 - Loop Failed! Error: 'RRTBox' object has no attribute 'next_trajectories', occurred on line 167 in file /home/turingzero/Downloads/TBK-Client/ui/boxes/RRTBox.py
2024-12-26 10:17:59.343 | ERROR    | utils.ClientLogManager:log:49 - Loop Failed! Error: 'RRTBox' object has no attribute 'next_trajectories', occurred on line 167 in file /home/turingzero/Downloads/TBK-Client/ui/boxes/RRTBox.py
2024-12-26 10:18:08.230 | ERROR    | utils.ClientLogManager:log:49 - Loop Failed! Error: Error in Opti::solve [OptiNode] at .../casadi/core/optistack.cpp:165:
.../casadi/core/optistack_internal.cpp:1030: Assertion "return_success(accept_limit)" failed:
Solver failed. You may use opti.debug.value to investigate the latest values of variables. return_status is 'NonIpopt_Exception_Thrown', occurred on line 48364 in file /home/turingzero/.local/lib/python3.10/site-packages/casadi/casadi.py
2024-12-26 10:18:15.103 | ERROR    | utils.ClientLogManager:log:49 - Loop Failed! Error: 'RRTBox' object has no attribute 'next_trajectories', occurred on line 167 in file /home/turingzero/Downloads/TBK-Client/ui/boxes/RRTBox.py
2024-12-26 10:18:17.536 | ERROR    | utils.ClientLogManager:log:49 - Loop Failed! Error: Error in Opti::solve [OptiNode] at .../casadi/core/optistack.cpp:165:
.../casadi/core/optistack_internal.cpp:1030: Assertion "return_success(accept_limit)" failed:
Solver failed. You may use opti.debug.value to investigate the latest values of variables. return_status is 'NonIpopt_Exception_Thrown', occurred on line 48364 in file /home/turingzero/.local/lib/python3.10/site-packages/casadi/casadi.py
2024-12-26 10:18:18.034 | ERROR    | utils.ClientLogManager:log:49 - Loop Failed! Error: Error in Opti::solve [OptiNode] at .../casadi/core/optistack.cpp:165:
.../casadi/core/optistack_internal.cpp:1030: Assertion "return_success(accept_limit)" failed:
Solver failed. You may use opti.debug.value to investigate the latest values of variables. return_status is 'NonIpopt_Exception_Thrown', occurred on line 48364 in file /home/turingzero/.local/lib/python3.10/site-packages/casadi/casadi.py
2024-12-26 10:18:32.137 | ERROR    | utils.ClientLogManager:log:49 - Loop Failed! Error: 'RRTBox' object has no attribute 'next_trajectories', occurred on line 167 in file /home/turingzero/Downloads/TBK-Client/ui/boxes/RRTBox.py
2024-12-26 10:18:46.844 | ERROR    | utils.ClientLogManager:log:49 - Loop Failed! Error: <built-in function delete_item> returned a result with an exception set, occurred on line 8032 in file /home/turingzero/.local/lib/python3.10/site-packages/dearpygui/dearpygui.py
2024-12-26 10:19:11.328 | ERROR    | utils.ClientLogManager:log:49 - Loop Failed! Error: 'RRTBox' object has no attribute 'next_trajectories', occurred on line 167 in file /home/turingzero/Downloads/TBK-Client/ui/boxes/RRTBox.py
2024-12-26 10:19:19.509 | ERROR    | utils.ClientLogManager:log:49 - Loop Failed! Error: Error in Opti::solve [OptiNode] at .../casadi/core/optistack.cpp:165:
.../casadi/core/optistack_internal.cpp:1030: Assertion "return_success(accept_limit)" failed:
Solver failed. You may use opti.debug.value to investigate the latest values of variables. return_status is 'NonIpopt_Exception_Thrown', occurred on line 48364 in file /home/turingzero/.local/lib/python3.10/site-packages/casadi/casadi.py
2024-12-26 10:19:34.720 | ERROR    | utils.ClientLogManager:log:49 - Loop Failed! Error: 'RRTBox' object has no attribute 'next_trajectories', occurred on line 167 in file /home/turingzero/Downloads/TBK-Client/ui/boxes/RRTBox.py
2024-12-26 10:21:10.611 | ERROR    | utils.ClientLogManager:log:49 - Loop Failed! Error: 'RRTBox' object has no attribute 'next_trajectories', occurred on line 167 in file /home/turingzero/Downloads/TBK-Client/ui/boxes/RRTBox.py
2024-12-26 10:21:24.068 | ERROR    | utils.ClientLogManager:log:49 - Loop Failed! Error: <built-in function delete_item> returned a result with an exception set, occurred on line 8032 in file /home/turingzero/.local/lib/python3.10/site-packages/dearpygui/dearpygui.py
2024-12-26 10:21:51.602 | ERROR    | utils.ClientLogManager:log:49 - Loop Failed! Error: 'RRTBox' object has no attribute 'next_trajectories', occurred on line 167 in file /home/turingzero/Downloads/TBK-Client/ui/boxes/RRTBox.py
2024-12-26 10:26:26.727 | ERROR    | utils.ClientLogManager:log:49 - Loop Failed! Error: 'RRTBox' object has no attribute 'next_trajectories', occurred on line 167 in file /home/turingzero/Downloads/TBK-Client/ui/boxes/RRTBox.py
2024-12-26 11:04:03.815 | ERROR    | utils.ClientLogManager:log:49 - Loop Failed! Error: 'RRTBox' object has no attribute 'next_trajectories', occurred on line 167 in file /home/turingzero/Downloads/TBK-Client/ui/boxes/RRTBox.py
2024-12-26 11:04:09.176 | ERROR    | utils.ClientLogManager:log:49 - Loop Failed! Error: <built-in function OptiSol_value> returned a result with an exception set, occurred on line 50861 in file /home/turingzero/.local/lib/python3.10/site-packages/casadi/casadi.py
