2024-12-20 09:24:18.001 | ERROR    | utils.ClientLogManager:log:49 - Loop Failed! Error: Error in Opti::solve [OptiNode] at .../casadi/core/optistack.cpp:165:
.../casadi/core/optistack_internal.cpp:1030: Assertion "return_success(accept_limit)" failed:
Solver failed. You may use opti.debug.value to investigate the latest values of variables. return_status is 'NonIpopt_Exception_Thrown', occurred on line 48364 in file /home/turingzero/.local/lib/python3.10/site-packages/casadi/casadi.py
2024-12-20 09:24:18.176 | ERROR    | utils.ClientLogManager:log:49 - Loop Failed! Error: Error in Opti::solve [OptiNode] at .../casadi/core/optistack.cpp:165:
.../casadi/core/optistack_internal.cpp:1030: Assertion "return_success(accept_limit)" failed:
Solver failed. You may use opti.debug.value to investigate the latest values of variables. return_status is 'NonIpopt_Exception_Thrown', occurred on line 48364 in file /home/turingzero/.local/lib/python3.10/site-packages/casadi/casadi.py
2024-12-20 09:24:18.393 | ERROR    | utils.ClientLogManager:log:49 - Loop Failed! Error: Error in Opti::solve [OptiNode] at .../casadi/core/optistack.cpp:165:
.../casadi/core/optistack_internal.cpp:1030: Assertion "return_success(accept_limit)" failed:
Solver failed. You may use opti.debug.value to investigate the latest values of variables. return_status is 'NonIpopt_Exception_Thrown', occurred on line 48364 in file /home/turingzero/.local/lib/python3.10/site-packages/casadi/casadi.py
2024-12-20 09:24:18.565 | ERROR    | utils.ClientLogManager:log:49 - Loop Failed! Error: Error in Opti::solve [OptiNode] at .../casadi/core/optistack.cpp:165:
.../casadi/core/optistack_internal.cpp:1030: Assertion "return_success(accept_limit)" failed:
Solver failed. You may use opti.debug.value to investigate the latest values of variables. return_status is 'NonIpopt_Exception_Thrown', occurred on line 48364 in file /home/turingzero/.local/lib/python3.10/site-packages/casadi/casadi.py
2024-12-20 09:24:18.731 | ERROR    | utils.ClientLogManager:log:49 - Loop Failed! Error: Error in Opti::solve [OptiNode] at .../casadi/core/optistack.cpp:165:
.../casadi/core/optistack_internal.cpp:1030: Assertion "return_success(accept_limit)" failed:
Solver failed. You may use opti.debug.value to investigate the latest values of variables. return_status is 'NonIpopt_Exception_Thrown', occurred on line 48364 in file /home/turingzero/.local/lib/python3.10/site-packages/casadi/casadi.py
2024-12-20 09:24:19.232 | ERROR    | utils.ClientLogManager:log:49 - Loop Failed! Error: Error in Opti::solve [OptiNode] at .../casadi/core/optistack.cpp:165:
.../casadi/core/optistack_internal.cpp:1030: Assertion "return_success(accept_limit)" failed:
Solver failed. You may use opti.debug.value to investigate the latest values of variables. return_status is 'NonIpopt_Exception_Thrown', occurred on line 48364 in file /home/turingzero/.local/lib/python3.10/site-packages/casadi/casadi.py
2024-12-20 09:24:19.261 | ERROR    | utils.ClientLogManager:log:49 - Loop Failed! Error: Error in Opti::solve [OptiNode] at .../casadi/core/optistack.cpp:165:
.../casadi/core/optistack_internal.cpp:1030: Assertion "return_success(accept_limit)" failed:
Solver failed. You may use opti.debug.value to investigate the latest values of variables. return_status is 'NonIpopt_Exception_Thrown', occurred on line 48364 in file /home/turingzero/.local/lib/python3.10/site-packages/casadi/casadi.py
2024-12-20 09:30:13.664 | ERROR    | utils.ClientLogManager:log:49 - Loop Failed! Error: Error in Opti::solve [OptiNode] at .../casadi/core/optistack.cpp:165:
.../casadi/core/optistack_internal.cpp:1030: Assertion "return_success(accept_limit)" failed:
Solver failed. You may use opti.debug.value to investigate the latest values of variables. return_status is 'NonIpopt_Exception_Thrown', occurred on line 48364 in file /home/turingzero/.local/lib/python3.10/site-packages/casadi/casadi.py
2024-12-20 09:30:14.161 | ERROR    | utils.ClientLogManager:log:49 - Loop Failed! Error: Error in Opti::solve [OptiNode] at .../casadi/core/optistack.cpp:165:
.../casadi/core/optistack_internal.cpp:1030: Assertion "return_success(accept_limit)" failed:
Solver failed. You may use opti.debug.value to investigate the latest values of variables. return_status is 'NonIpopt_Exception_Thrown', occurred on line 48364 in file /home/turingzero/.local/lib/python3.10/site-packages/casadi/casadi.py
2024-12-20 09:30:14.191 | ERROR    | utils.ClientLogManager:log:49 - Loop Failed! Error: Error in Opti::solve [OptiNode] at .../casadi/core/optistack.cpp:165:
.../casadi/core/optistack_internal.cpp:1030: Assertion "return_success(accept_limit)" failed:
Solver failed. You may use opti.debug.value to investigate the latest values of variables. return_status is 'NonIpopt_Exception_Thrown', occurred on line 48364 in file /home/turingzero/.local/lib/python3.10/site-packages/casadi/casadi.py
2024-12-20 09:30:14.222 | ERROR    | utils.ClientLogManager:log:49 - Loop Failed! Error: Error in Opti::solve [OptiNode] at .../casadi/core/optistack.cpp:165:
.../casadi/core/optistack_internal.cpp:1030: Assertion "return_success(accept_limit)" failed:
Solver failed. You may use opti.debug.value to investigate the latest values of variables. return_status is 'NonIpopt_Exception_Thrown', occurred on line 48364 in file /home/turingzero/.local/lib/python3.10/site-packages/casadi/casadi.py
2024-12-20 09:30:14.252 | ERROR    | utils.ClientLogManager:log:49 - Loop Failed! Error: Error in Opti::solve [OptiNode] at .../casadi/core/optistack.cpp:165:
.../casadi/core/optistack_internal.cpp:1030: Assertion "return_success(accept_limit)" failed:
Solver failed. You may use opti.debug.value to investigate the latest values of variables. return_status is 'NonIpopt_Exception_Thrown', occurred on line 48364 in file /home/turingzero/.local/lib/python3.10/site-packages/casadi/casadi.py
2024-12-20 09:30:14.282 | ERROR    | utils.ClientLogManager:log:49 - Loop Failed! Error: Error in Opti::solve [OptiNode] at .../casadi/core/optistack.cpp:165:
.../casadi/core/optistack_internal.cpp:1030: Assertion "return_success(accept_limit)" failed:
Solver failed. You may use opti.debug.value to investigate the latest values of variables. return_status is 'NonIpopt_Exception_Thrown', occurred on line 48364 in file /home/turingzero/.local/lib/python3.10/site-packages/casadi/casadi.py
2024-12-20 09:30:14.312 | ERROR    | utils.ClientLogManager:log:49 - Loop Failed! Error: Error in Opti::solve [OptiNode] at .../casadi/core/optistack.cpp:165:
.../casadi/core/optistack_internal.cpp:1030: Assertion "return_success(accept_limit)" failed:
Solver failed. You may use opti.debug.value to investigate the latest values of variables. return_status is 'NonIpopt_Exception_Thrown', occurred on line 48364 in file /home/turingzero/.local/lib/python3.10/site-packages/casadi/casadi.py
2024-12-20 09:30:14.342 | ERROR    | utils.ClientLogManager:log:49 - Loop Failed! Error: Error in Opti::solve [OptiNode] at .../casadi/core/optistack.cpp:165:
.../casadi/core/optistack_internal.cpp:1030: Assertion "return_success(accept_limit)" failed:
Solver failed. You may use opti.debug.value to investigate the latest values of variables. return_status is 'NonIpopt_Exception_Thrown', occurred on line 48364 in file /home/turingzero/.local/lib/python3.10/site-packages/casadi/casadi.py
2024-12-20 09:30:14.372 | ERROR    | utils.ClientLogManager:log:49 - Loop Failed! Error: Error in Opti::solve [OptiNode] at .../casadi/core/optistack.cpp:165:
.../casadi/core/optistack_internal.cpp:1030: Assertion "return_success(accept_limit)" failed:
Solver failed. You may use opti.debug.value to investigate the latest values of variables. return_status is 'NonIpopt_Exception_Thrown', occurred on line 48364 in file /home/turingzero/.local/lib/python3.10/site-packages/casadi/casadi.py
2024-12-20 09:30:14.402 | ERROR    | utils.ClientLogManager:log:49 - Loop Failed! Error: Error in Opti::solve [OptiNode] at .../casadi/core/optistack.cpp:165:
.../casadi/core/optistack_internal.cpp:1030: Assertion "return_success(accept_limit)" failed:
Solver failed. You may use opti.debug.value to investigate the latest values of variables. return_status is 'NonIpopt_Exception_Thrown', occurred on line 48364 in file /home/turingzero/.local/lib/python3.10/site-packages/casadi/casadi.py
2024-12-20 09:30:14.432 | ERROR    | utils.ClientLogManager:log:49 - Loop Failed! Error: Error in Opti::solve [OptiNode] at .../casadi/core/optistack.cpp:165:
.../casadi/core/optistack_internal.cpp:1030: Assertion "return_success(accept_limit)" failed:
Solver failed. You may use opti.debug.value to investigate the latest values of variables. return_status is 'NonIpopt_Exception_Thrown', occurred on line 48364 in file /home/turingzero/.local/lib/python3.10/site-packages/casadi/casadi.py
2024-12-20 09:30:14.462 | ERROR    | utils.ClientLogManager:log:49 - Loop Failed! Error: Error in Opti::solve [OptiNode] at .../casadi/core/optistack.cpp:165:
.../casadi/core/optistack_internal.cpp:1030: Assertion "return_success(accept_limit)" failed:
Solver failed. You may use opti.debug.value to investigate the latest values of variables. return_status is 'NonIpopt_Exception_Thrown', occurred on line 48364 in file /home/turingzero/.local/lib/python3.10/site-packages/casadi/casadi.py
2024-12-20 09:30:14.492 | ERROR    | utils.ClientLogManager:log:49 - Loop Failed! Error: Error in Opti::solve [OptiNode] at .../casadi/core/optistack.cpp:165:
.../casadi/core/optistack_internal.cpp:1030: Assertion "return_success(accept_limit)" failed:
Solver failed. You may use opti.debug.value to investigate the latest values of variables. return_status is 'NonIpopt_Exception_Thrown', occurred on line 48364 in file /home/turingzero/.local/lib/python3.10/site-packages/casadi/casadi.py
2024-12-20 09:30:14.522 | ERROR    | utils.ClientLogManager:log:49 - Loop Failed! Error: Error in Opti::solve [OptiNode] at .../casadi/core/optistack.cpp:165:
.../casadi/core/optistack_internal.cpp:1030: Assertion "return_success(accept_limit)" failed:
Solver failed. You may use opti.debug.value to investigate the latest values of variables. return_status is 'NonIpopt_Exception_Thrown', occurred on line 48364 in file /home/turingzero/.local/lib/python3.10/site-packages/casadi/casadi.py
2024-12-20 09:30:14.552 | ERROR    | utils.ClientLogManager:log:49 - Loop Failed! Error: Error in Opti::solve [OptiNode] at .../casadi/core/optistack.cpp:165:
.../casadi/core/optistack_internal.cpp:1030: Assertion "return_success(accept_limit)" failed:
Solver failed. You may use opti.debug.value to investigate the latest values of variables. return_status is 'NonIpopt_Exception_Thrown', occurred on line 48364 in file /home/turingzero/.local/lib/python3.10/site-packages/casadi/casadi.py
2024-12-20 09:30:14.582 | ERROR    | utils.ClientLogManager:log:49 - Loop Failed! Error: Error in Opti::solve [OptiNode] at .../casadi/core/optistack.cpp:165:
.../casadi/core/optistack_internal.cpp:1030: Assertion "return_success(accept_limit)" failed:
Solver failed. You may use opti.debug.value to investigate the latest values of variables. return_status is 'NonIpopt_Exception_Thrown', occurred on line 48364 in file /home/turingzero/.local/lib/python3.10/site-packages/casadi/casadi.py
2024-12-20 09:30:14.612 | ERROR    | utils.ClientLogManager:log:49 - Loop Failed! Error: Error in Opti::solve [OptiNode] at .../casadi/core/optistack.cpp:165:
.../casadi/core/optistack_internal.cpp:1030: Assertion "return_success(accept_limit)" failed:
Solver failed. You may use opti.debug.value to investigate the latest values of variables. return_status is 'NonIpopt_Exception_Thrown', occurred on line 48364 in file /home/turingzero/.local/lib/python3.10/site-packages/casadi/casadi.py
2024-12-20 09:30:14.643 | ERROR    | utils.ClientLogManager:log:49 - Loop Failed! Error: Error in Opti::solve [OptiNode] at .../casadi/core/optistack.cpp:165:
.../casadi/core/optistack_internal.cpp:1030: Assertion "return_success(accept_limit)" failed:
Solver failed. You may use opti.debug.value to investigate the latest values of variables. return_status is 'NonIpopt_Exception_Thrown', occurred on line 48364 in file /home/turingzero/.local/lib/python3.10/site-packages/casadi/casadi.py
2024-12-20 09:30:14.673 | ERROR    | utils.ClientLogManager:log:49 - Loop Failed! Error: Error in Opti::solve [OptiNode] at .../casadi/core/optistack.cpp:165:
.../casadi/core/optistack_internal.cpp:1030: Assertion "return_success(accept_limit)" failed:
Solver failed. You may use opti.debug.value to investigate the latest values of variables. return_status is 'NonIpopt_Exception_Thrown', occurred on line 48364 in file /home/turingzero/.local/lib/python3.10/site-packages/casadi/casadi.py
2024-12-20 09:30:14.703 | ERROR    | utils.ClientLogManager:log:49 - Loop Failed! Error: Error in Opti::solve [OptiNode] at .../casadi/core/optistack.cpp:165:
.../casadi/core/optistack_internal.cpp:1030: Assertion "return_success(accept_limit)" failed:
Solver failed. You may use opti.debug.value to investigate the latest values of variables. return_status is 'NonIpopt_Exception_Thrown', occurred on line 48364 in file /home/turingzero/.local/lib/python3.10/site-packages/casadi/casadi.py
2024-12-20 09:30:14.734 | ERROR    | utils.ClientLogManager:log:49 - Loop Failed! Error: Error in Opti::solve [OptiNode] at .../casadi/core/optistack.cpp:165:
.../casadi/core/optistack_internal.cpp:1030: Assertion "return_success(accept_limit)" failed:
Solver failed. You may use opti.debug.value to investigate the latest values of variables. return_status is 'NonIpopt_Exception_Thrown', occurred on line 48364 in file /home/turingzero/.local/lib/python3.10/site-packages/casadi/casadi.py
2024-12-20 09:30:14.764 | ERROR    | utils.ClientLogManager:log:49 - Loop Failed! Error: Error in Opti::solve [OptiNode] at .../casadi/core/optistack.cpp:165:
.../casadi/core/optistack_internal.cpp:1030: Assertion "return_success(accept_limit)" failed:
Solver failed. You may use opti.debug.value to investigate the latest values of variables. return_status is 'NonIpopt_Exception_Thrown', occurred on line 48364 in file /home/turingzero/.local/lib/python3.10/site-packages/casadi/casadi.py
2024-12-20 09:30:14.795 | ERROR    | utils.ClientLogManager:log:49 - Loop Failed! Error: Error in Opti::solve [OptiNode] at .../casadi/core/optistack.cpp:165:
.../casadi/core/optistack_internal.cpp:1030: Assertion "return_success(accept_limit)" failed:
Solver failed. You may use opti.debug.value to investigate the latest values of variables. return_status is 'NonIpopt_Exception_Thrown', occurred on line 48364 in file /home/turingzero/.local/lib/python3.10/site-packages/casadi/casadi.py
2024-12-20 09:30:14.824 | ERROR    | utils.ClientLogManager:log:49 - Loop Failed! Error: Error in Opti::solve [OptiNode] at .../casadi/core/optistack.cpp:165:
.../casadi/core/optistack_internal.cpp:1030: Assertion "return_success(accept_limit)" failed:
Solver failed. You may use opti.debug.value to investigate the latest values of variables. return_status is 'NonIpopt_Exception_Thrown', occurred on line 48364 in file /home/turingzero/.local/lib/python3.10/site-packages/casadi/casadi.py
2024-12-20 09:30:14.854 | ERROR    | utils.ClientLogManager:log:49 - Loop Failed! Error: Error in Opti::solve [OptiNode] at .../casadi/core/optistack.cpp:165:
.../casadi/core/optistack_internal.cpp:1030: Assertion "return_success(accept_limit)" failed:
Solver failed. You may use opti.debug.value to investigate the latest values of variables. return_status is 'NonIpopt_Exception_Thrown', occurred on line 48364 in file /home/turingzero/.local/lib/python3.10/site-packages/casadi/casadi.py
2024-12-20 09:30:14.885 | ERROR    | utils.ClientLogManager:log:49 - Loop Failed! Error: Error in Opti::solve [OptiNode] at .../casadi/core/optistack.cpp:165:
.../casadi/core/optistack_internal.cpp:1030: Assertion "return_success(accept_limit)" failed:
Solver failed. You may use opti.debug.value to investigate the latest values of variables. return_status is 'NonIpopt_Exception_Thrown', occurred on line 48364 in file /home/turingzero/.local/lib/python3.10/site-packages/casadi/casadi.py
2024-12-20 09:30:14.914 | ERROR    | utils.ClientLogManager:log:49 - Loop Failed! Error: Error in Opti::solve [OptiNode] at .../casadi/core/optistack.cpp:165:
.../casadi/core/optistack_internal.cpp:1030: Assertion "return_success(accept_limit)" failed:
Solver failed. You may use opti.debug.value to investigate the latest values of variables. return_status is 'NonIpopt_Exception_Thrown', occurred on line 48364 in file /home/turingzero/.local/lib/python3.10/site-packages/casadi/casadi.py
2024-12-20 09:30:14.944 | ERROR    | utils.ClientLogManager:log:49 - Loop Failed! Error: Error in Opti::solve [OptiNode] at .../casadi/core/optistack.cpp:165:
.../casadi/core/optistack_internal.cpp:1030: Assertion "return_success(accept_limit)" failed:
Solver failed. You may use opti.debug.value to investigate the latest values of variables. return_status is 'NonIpopt_Exception_Thrown', occurred on line 48364 in file /home/turingzero/.local/lib/python3.10/site-packages/casadi/casadi.py
2024-12-20 09:30:14.975 | ERROR    | utils.ClientLogManager:log:49 - Loop Failed! Error: Error in Opti::solve [OptiNode] at .../casadi/core/optistack.cpp:165:
.../casadi/core/optistack_internal.cpp:1030: Assertion "return_success(accept_limit)" failed:
Solver failed. You may use opti.debug.value to investigate the latest values of variables. return_status is 'NonIpopt_Exception_Thrown', occurred on line 48364 in file /home/turingzero/.local/lib/python3.10/site-packages/casadi/casadi.py
2024-12-20 09:30:15.004 | ERROR    | utils.ClientLogManager:log:49 - Loop Failed! Error: Error in Opti::solve [OptiNode] at .../casadi/core/optistack.cpp:165:
.../casadi/core/optistack_internal.cpp:1030: Assertion "return_success(accept_limit)" failed:
Solver failed. You may use opti.debug.value to investigate the latest values of variables. return_status is 'NonIpopt_Exception_Thrown', occurred on line 48364 in file /home/turingzero/.local/lib/python3.10/site-packages/casadi/casadi.py
2024-12-20 09:30:15.035 | ERROR    | utils.ClientLogManager:log:49 - Loop Failed! Error: Error in Opti::solve [OptiNode] at .../casadi/core/optistack.cpp:165:
.../casadi/core/optistack_internal.cpp:1030: Assertion "return_success(accept_limit)" failed:
Solver failed. You may use opti.debug.value to investigate the latest values of variables. return_status is 'NonIpopt_Exception_Thrown', occurred on line 48364 in file /home/turingzero/.local/lib/python3.10/site-packages/casadi/casadi.py
2024-12-20 09:30:15.065 | ERROR    | utils.ClientLogManager:log:49 - Loop Failed! Error: Error in Opti::solve [OptiNode] at .../casadi/core/optistack.cpp:165:
.../casadi/core/optistack_internal.cpp:1030: Assertion "return_success(accept_limit)" failed:
Solver failed. You may use opti.debug.value to investigate the latest values of variables. return_status is 'NonIpopt_Exception_Thrown', occurred on line 48364 in file /home/turingzero/.local/lib/python3.10/site-packages/casadi/casadi.py
2024-12-20 09:31:55.709 | ERROR    | utils.ClientLogManager:log:49 - Loop Failed! Error: Error in Opti::solve [OptiNode] at .../casadi/core/optistack.cpp:165:
.../casadi/core/optistack_internal.cpp:1030: Assertion "return_success(accept_limit)" failed:
Solver failed. You may use opti.debug.value to investigate the latest values of variables. return_status is 'NonIpopt_Exception_Thrown', occurred on line 48364 in file /home/turingzero/.local/lib/python3.10/site-packages/casadi/casadi.py
2024-12-20 09:31:55.902 | ERROR    | utils.ClientLogManager:log:49 - Loop Failed! Error: Error in Opti::solve [OptiNode] at .../casadi/core/optistack.cpp:165:
.../casadi/core/optistack_internal.cpp:1030: Assertion "return_success(accept_limit)" failed:
Solver failed. You may use opti.debug.value to investigate the latest values of variables. return_status is 'NonIpopt_Exception_Thrown', occurred on line 48364 in file /home/turingzero/.local/lib/python3.10/site-packages/casadi/casadi.py
2024-12-20 09:31:56.058 | ERROR    | utils.ClientLogManager:log:49 - Loop Failed! Error: Error in Opti::solve [OptiNode] at .../casadi/core/optistack.cpp:165:
.../casadi/core/optistack_internal.cpp:1030: Assertion "return_success(accept_limit)" failed:
Solver failed. You may use opti.debug.value to investigate the latest values of variables. return_status is 'NonIpopt_Exception_Thrown', occurred on line 48364 in file /home/turingzero/.local/lib/python3.10/site-packages/casadi/casadi.py
2024-12-20 09:31:56.216 | ERROR    | utils.ClientLogManager:log:49 - Loop Failed! Error: Error in Opti::solve [OptiNode] at .../casadi/core/optistack.cpp:165:
.../casadi/core/optistack_internal.cpp:1030: Assertion "return_success(accept_limit)" failed:
Solver failed. You may use opti.debug.value to investigate the latest values of variables. return_status is 'NonIpopt_Exception_Thrown', occurred on line 48364 in file /home/turingzero/.local/lib/python3.10/site-packages/casadi/casadi.py
2024-12-20 09:31:56.351 | ERROR    | utils.ClientLogManager:log:49 - Loop Failed! Error: Error in Opti::solve [OptiNode] at .../casadi/core/optistack.cpp:165:
.../casadi/core/optistack_internal.cpp:1030: Assertion "return_success(accept_limit)" failed:
Solver failed. You may use opti.debug.value to investigate the latest values of variables. return_status is 'NonIpopt_Exception_Thrown', occurred on line 48364 in file /home/turingzero/.local/lib/python3.10/site-packages/casadi/casadi.py
2024-12-20 09:31:56.524 | ERROR    | utils.ClientLogManager:log:49 - Loop Failed! Error: Error in Opti::solve [OptiNode] at .../casadi/core/optistack.cpp:165:
.../casadi/core/optistack_internal.cpp:1030: Assertion "return_success(accept_limit)" failed:
Solver failed. You may use opti.debug.value to investigate the latest values of variables. return_status is 'NonIpopt_Exception_Thrown', occurred on line 48364 in file /home/turingzero/.local/lib/python3.10/site-packages/casadi/casadi.py
2024-12-20 09:31:57.024 | ERROR    | utils.ClientLogManager:log:49 - Loop Failed! Error: Error in Opti::solve [OptiNode] at .../casadi/core/optistack.cpp:165:
.../casadi/core/optistack_internal.cpp:1030: Assertion "return_success(accept_limit)" failed:
Solver failed. You may use opti.debug.value to investigate the latest values of variables. return_status is 'NonIpopt_Exception_Thrown', occurred on line 48364 in file /home/turingzero/.local/lib/python3.10/site-packages/casadi/casadi.py
2024-12-20 09:31:57.054 | ERROR    | utils.ClientLogManager:log:49 - Loop Failed! Error: Error in Opti::solve [OptiNode] at .../casadi/core/optistack.cpp:165:
.../casadi/core/optistack_internal.cpp:1030: Assertion "return_success(accept_limit)" failed:
Solver failed. You may use opti.debug.value to investigate the latest values of variables. return_status is 'NonIpopt_Exception_Thrown', occurred on line 48364 in file /home/turingzero/.local/lib/python3.10/site-packages/casadi/casadi.py
2024-12-20 09:31:57.084 | ERROR    | utils.ClientLogManager:log:49 - Loop Failed! Error: Error in Opti::solve [OptiNode] at .../casadi/core/optistack.cpp:165:
.../casadi/core/optistack_internal.cpp:1030: Assertion "return_success(accept_limit)" failed:
Solver failed. You may use opti.debug.value to investigate the latest values of variables. return_status is 'NonIpopt_Exception_Thrown', occurred on line 48364 in file /home/turingzero/.local/lib/python3.10/site-packages/casadi/casadi.py
2024-12-20 09:31:57.115 | ERROR    | utils.ClientLogManager:log:49 - Loop Failed! Error: Error in Opti::solve [OptiNode] at .../casadi/core/optistack.cpp:165:
.../casadi/core/optistack_internal.cpp:1030: Assertion "return_success(accept_limit)" failed:
Solver failed. You may use opti.debug.value to investigate the latest values of variables. return_status is 'NonIpopt_Exception_Thrown', occurred on line 48364 in file /home/turingzero/.local/lib/python3.10/site-packages/casadi/casadi.py
2024-12-20 09:31:57.144 | ERROR    | utils.ClientLogManager:log:49 - Loop Failed! Error: Error in Opti::solve [OptiNode] at .../casadi/core/optistack.cpp:165:
.../casadi/core/optistack_internal.cpp:1030: Assertion "return_success(accept_limit)" failed:
Solver failed. You may use opti.debug.value to investigate the latest values of variables. return_status is 'NonIpopt_Exception_Thrown', occurred on line 48364 in file /home/turingzero/.local/lib/python3.10/site-packages/casadi/casadi.py
2024-12-20 09:31:57.175 | ERROR    | utils.ClientLogManager:log:49 - Loop Failed! Error: Error in Opti::solve [OptiNode] at .../casadi/core/optistack.cpp:165:
.../casadi/core/optistack_internal.cpp:1030: Assertion "return_success(accept_limit)" failed:
Solver failed. You may use opti.debug.value to investigate the latest values of variables. return_status is 'NonIpopt_Exception_Thrown', occurred on line 48364 in file /home/turingzero/.local/lib/python3.10/site-packages/casadi/casadi.py
2024-12-20 09:31:57.204 | ERROR    | utils.ClientLogManager:log:49 - Loop Failed! Error: Error in Opti::solve [OptiNode] at .../casadi/core/optistack.cpp:165:
.../casadi/core/optistack_internal.cpp:1030: Assertion "return_success(accept_limit)" failed:
Solver failed. You may use opti.debug.value to investigate the latest values of variables. return_status is 'NonIpopt_Exception_Thrown', occurred on line 48364 in file /home/turingzero/.local/lib/python3.10/site-packages/casadi/casadi.py
2024-12-20 09:31:57.233 | ERROR    | utils.ClientLogManager:log:49 - Loop Failed! Error: Error in Opti::solve [OptiNode] at .../casadi/core/optistack.cpp:165:
.../casadi/core/optistack_internal.cpp:1030: Assertion "return_success(accept_limit)" failed:
Solver failed. You may use opti.debug.value to investigate the latest values of variables. return_status is 'NonIpopt_Exception_Thrown', occurred on line 48364 in file /home/turingzero/.local/lib/python3.10/site-packages/casadi/casadi.py
2024-12-20 09:31:57.264 | ERROR    | utils.ClientLogManager:log:49 - Loop Failed! Error: Error in Opti::solve [OptiNode] at .../casadi/core/optistack.cpp:165:
.../casadi/core/optistack_internal.cpp:1030: Assertion "return_success(accept_limit)" failed:
Solver failed. You may use opti.debug.value to investigate the latest values of variables. return_status is 'NonIpopt_Exception_Thrown', occurred on line 48364 in file /home/turingzero/.local/lib/python3.10/site-packages/casadi/casadi.py
2024-12-20 09:31:57.295 | ERROR    | utils.ClientLogManager:log:49 - Loop Failed! Error: Error in Opti::solve [OptiNode] at .../casadi/core/optistack.cpp:165:
.../casadi/core/optistack_internal.cpp:1030: Assertion "return_success(accept_limit)" failed:
Solver failed. You may use opti.debug.value to investigate the latest values of variables. return_status is 'NonIpopt_Exception_Thrown', occurred on line 48364 in file /home/turingzero/.local/lib/python3.10/site-packages/casadi/casadi.py
2024-12-20 09:31:57.325 | ERROR    | utils.ClientLogManager:log:49 - Loop Failed! Error: Error in Opti::solve [OptiNode] at .../casadi/core/optistack.cpp:165:
.../casadi/core/optistack_internal.cpp:1030: Assertion "return_success(accept_limit)" failed:
Solver failed. You may use opti.debug.value to investigate the latest values of variables. return_status is 'NonIpopt_Exception_Thrown', occurred on line 48364 in file /home/turingzero/.local/lib/python3.10/site-packages/casadi/casadi.py
2024-12-20 09:31:57.355 | ERROR    | utils.ClientLogManager:log:49 - Loop Failed! Error: Error in Opti::solve [OptiNode] at .../casadi/core/optistack.cpp:165:
.../casadi/core/optistack_internal.cpp:1030: Assertion "return_success(accept_limit)" failed:
Solver failed. You may use opti.debug.value to investigate the latest values of variables. return_status is 'NonIpopt_Exception_Thrown', occurred on line 48364 in file /home/turingzero/.local/lib/python3.10/site-packages/casadi/casadi.py
2024-12-20 09:31:57.385 | ERROR    | utils.ClientLogManager:log:49 - Loop Failed! Error: Error in Opti::solve [OptiNode] at .../casadi/core/optistack.cpp:165:
.../casadi/core/optistack_internal.cpp:1030: Assertion "return_success(accept_limit)" failed:
Solver failed. You may use opti.debug.value to investigate the latest values of variables. return_status is 'NonIpopt_Exception_Thrown', occurred on line 48364 in file /home/turingzero/.local/lib/python3.10/site-packages/casadi/casadi.py
2024-12-20 09:31:57.415 | ERROR    | utils.ClientLogManager:log:49 - Loop Failed! Error: Error in Opti::solve [OptiNode] at .../casadi/core/optistack.cpp:165:
.../casadi/core/optistack_internal.cpp:1030: Assertion "return_success(accept_limit)" failed:
Solver failed. You may use opti.debug.value to investigate the latest values of variables. return_status is 'NonIpopt_Exception_Thrown', occurred on line 48364 in file /home/turingzero/.local/lib/python3.10/site-packages/casadi/casadi.py
2024-12-20 09:31:57.446 | ERROR    | utils.ClientLogManager:log:49 - Loop Failed! Error: Error in Opti::solve [OptiNode] at .../casadi/core/optistack.cpp:165:
.../casadi/core/optistack_internal.cpp:1030: Assertion "return_success(accept_limit)" failed:
Solver failed. You may use opti.debug.value to investigate the latest values of variables. return_status is 'NonIpopt_Exception_Thrown', occurred on line 48364 in file /home/turingzero/.local/lib/python3.10/site-packages/casadi/casadi.py
2024-12-20 09:31:57.475 | ERROR    | utils.ClientLogManager:log:49 - Loop Failed! Error: Error in Opti::solve [OptiNode] at .../casadi/core/optistack.cpp:165:
.../casadi/core/optistack_internal.cpp:1030: Assertion "return_success(accept_limit)" failed:
Solver failed. You may use opti.debug.value to investigate the latest values of variables. return_status is 'NonIpopt_Exception_Thrown', occurred on line 48364 in file /home/turingzero/.local/lib/python3.10/site-packages/casadi/casadi.py
2024-12-20 09:31:57.505 | ERROR    | utils.ClientLogManager:log:49 - Loop Failed! Error: Error in Opti::solve [OptiNode] at .../casadi/core/optistack.cpp:165:
.../casadi/core/optistack_internal.cpp:1030: Assertion "return_success(accept_limit)" failed:
Solver failed. You may use opti.debug.value to investigate the latest values of variables. return_status is 'NonIpopt_Exception_Thrown', occurred on line 48364 in file /home/turingzero/.local/lib/python3.10/site-packages/casadi/casadi.py
2024-12-20 09:31:57.536 | ERROR    | utils.ClientLogManager:log:49 - Loop Failed! Error: Error in Opti::solve [OptiNode] at .../casadi/core/optistack.cpp:165:
.../casadi/core/optistack_internal.cpp:1030: Assertion "return_success(accept_limit)" failed:
Solver failed. You may use opti.debug.value to investigate the latest values of variables. return_status is 'NonIpopt_Exception_Thrown', occurred on line 48364 in file /home/turingzero/.local/lib/python3.10/site-packages/casadi/casadi.py
2024-12-20 09:31:57.565 | ERROR    | utils.ClientLogManager:log:49 - Loop Failed! Error: Error in Opti::solve [OptiNode] at .../casadi/core/optistack.cpp:165:
.../casadi/core/optistack_internal.cpp:1030: Assertion "return_success(accept_limit)" failed:
Solver failed. You may use opti.debug.value to investigate the latest values of variables. return_status is 'NonIpopt_Exception_Thrown', occurred on line 48364 in file /home/turingzero/.local/lib/python3.10/site-packages/casadi/casadi.py
2024-12-20 09:31:57.595 | ERROR    | utils.ClientLogManager:log:49 - Loop Failed! Error: Error in Opti::solve [OptiNode] at .../casadi/core/optistack.cpp:165:
.../casadi/core/optistack_internal.cpp:1030: Assertion "return_success(accept_limit)" failed:
Solver failed. You may use opti.debug.value to investigate the latest values of variables. return_status is 'NonIpopt_Exception_Thrown', occurred on line 48364 in file /home/turingzero/.local/lib/python3.10/site-packages/casadi/casadi.py
2024-12-20 09:31:57.625 | ERROR    | utils.ClientLogManager:log:49 - Loop Failed! Error: Error in Opti::solve [OptiNode] at .../casadi/core/optistack.cpp:165:
.../casadi/core/optistack_internal.cpp:1030: Assertion "return_success(accept_limit)" failed:
Solver failed. You may use opti.debug.value to investigate the latest values of variables. return_status is 'NonIpopt_Exception_Thrown', occurred on line 48364 in file /home/turingzero/.local/lib/python3.10/site-packages/casadi/casadi.py
2024-12-20 09:31:57.655 | ERROR    | utils.ClientLogManager:log:49 - Loop Failed! Error: Error in Opti::solve [OptiNode] at .../casadi/core/optistack.cpp:165:
.../casadi/core/optistack_internal.cpp:1030: Assertion "return_success(accept_limit)" failed:
Solver failed. You may use opti.debug.value to investigate the latest values of variables. return_status is 'NonIpopt_Exception_Thrown', occurred on line 48364 in file /home/turingzero/.local/lib/python3.10/site-packages/casadi/casadi.py
2024-12-20 09:31:57.685 | ERROR    | utils.ClientLogManager:log:49 - Loop Failed! Error: Error in Opti::solve [OptiNode] at .../casadi/core/optistack.cpp:165:
.../casadi/core/optistack_internal.cpp:1030: Assertion "return_success(accept_limit)" failed:
Solver failed. You may use opti.debug.value to investigate the latest values of variables. return_status is 'NonIpopt_Exception_Thrown', occurred on line 48364 in file /home/turingzero/.local/lib/python3.10/site-packages/casadi/casadi.py
2024-12-20 09:31:57.715 | ERROR    | utils.ClientLogManager:log:49 - Loop Failed! Error: Error in Opti::solve [OptiNode] at .../casadi/core/optistack.cpp:165:
.../casadi/core/optistack_internal.cpp:1030: Assertion "return_success(accept_limit)" failed:
Solver failed. You may use opti.debug.value to investigate the latest values of variables. return_status is 'NonIpopt_Exception_Thrown', occurred on line 48364 in file /home/turingzero/.local/lib/python3.10/site-packages/casadi/casadi.py
2024-12-20 09:31:57.746 | ERROR    | utils.ClientLogManager:log:49 - Loop Failed! Error: Error in Opti::solve [OptiNode] at .../casadi/core/optistack.cpp:165:
.../casadi/core/optistack_internal.cpp:1030: Assertion "return_success(accept_limit)" failed:
Solver failed. You may use opti.debug.value to investigate the latest values of variables. return_status is 'NonIpopt_Exception_Thrown', occurred on line 48364 in file /home/turingzero/.local/lib/python3.10/site-packages/casadi/casadi.py
2024-12-20 09:31:57.776 | ERROR    | utils.ClientLogManager:log:49 - Loop Failed! Error: Error in Opti::solve [OptiNode] at .../casadi/core/optistack.cpp:165:
.../casadi/core/optistack_internal.cpp:1030: Assertion "return_success(accept_limit)" failed:
Solver failed. You may use opti.debug.value to investigate the latest values of variables. return_status is 'NonIpopt_Exception_Thrown', occurred on line 48364 in file /home/turingzero/.local/lib/python3.10/site-packages/casadi/casadi.py
2024-12-20 09:31:57.806 | ERROR    | utils.ClientLogManager:log:49 - Loop Failed! Error: Error in Opti::solve [OptiNode] at .../casadi/core/optistack.cpp:165:
.../casadi/core/optistack_internal.cpp:1030: Assertion "return_success(accept_limit)" failed:
Solver failed. You may use opti.debug.value to investigate the latest values of variables. return_status is 'NonIpopt_Exception_Thrown', occurred on line 48364 in file /home/turingzero/.local/lib/python3.10/site-packages/casadi/casadi.py
2024-12-20 09:31:57.836 | ERROR    | utils.ClientLogManager:log:49 - Loop Failed! Error: Error in Opti::solve [OptiNode] at .../casadi/core/optistack.cpp:165:
.../casadi/core/optistack_internal.cpp:1030: Assertion "return_success(accept_limit)" failed:
Solver failed. You may use opti.debug.value to investigate the latest values of variables. return_status is 'NonIpopt_Exception_Thrown', occurred on line 48364 in file /home/turingzero/.local/lib/python3.10/site-packages/casadi/casadi.py
2024-12-20 09:31:57.866 | ERROR    | utils.ClientLogManager:log:49 - Loop Failed! Error: Error in Opti::solve [OptiNode] at .../casadi/core/optistack.cpp:165:
.../casadi/core/optistack_internal.cpp:1030: Assertion "return_success(accept_limit)" failed:
Solver failed. You may use opti.debug.value to investigate the latest values of variables. return_status is 'NonIpopt_Exception_Thrown', occurred on line 48364 in file /home/turingzero/.local/lib/python3.10/site-packages/casadi/casadi.py
2024-12-20 09:31:57.896 | ERROR    | utils.ClientLogManager:log:49 - Loop Failed! Error: Error in Opti::solve [OptiNode] at .../casadi/core/optistack.cpp:165:
.../casadi/core/optistack_internal.cpp:1030: Assertion "return_success(accept_limit)" failed:
Solver failed. You may use opti.debug.value to investigate the latest values of variables. return_status is 'NonIpopt_Exception_Thrown', occurred on line 48364 in file /home/turingzero/.local/lib/python3.10/site-packages/casadi/casadi.py
2024-12-20 09:31:57.926 | ERROR    | utils.ClientLogManager:log:49 - Loop Failed! Error: Error in Opti::solve [OptiNode] at .../casadi/core/optistack.cpp:165:
.../casadi/core/optistack_internal.cpp:1030: Assertion "return_success(accept_limit)" failed:
Solver failed. You may use opti.debug.value to investigate the latest values of variables. return_status is 'NonIpopt_Exception_Thrown', occurred on line 48364 in file /home/turingzero/.local/lib/python3.10/site-packages/casadi/casadi.py
2024-12-20 09:31:57.956 | ERROR    | utils.ClientLogManager:log:49 - Loop Failed! Error: Error in Opti::solve [OptiNode] at .../casadi/core/optistack.cpp:165:
.../casadi/core/optistack_internal.cpp:1030: Assertion "return_success(accept_limit)" failed:
Solver failed. You may use opti.debug.value to investigate the latest values of variables. return_status is 'NonIpopt_Exception_Thrown', occurred on line 48364 in file /home/turingzero/.local/lib/python3.10/site-packages/casadi/casadi.py
2024-12-20 09:32:23.235 | ERROR    | utils.ClientLogManager:log:49 - Loop Failed! Error: Error in Opti::solve [OptiNode] at .../casadi/core/optistack.cpp:165:
.../casadi/core/optistack_internal.cpp:1030: Assertion "return_success(accept_limit)" failed:
Solver failed. You may use opti.debug.value to investigate the latest values of variables. return_status is 'NonIpopt_Exception_Thrown', occurred on line 48364 in file /home/turingzero/.local/lib/python3.10/site-packages/casadi/casadi.py
2024-12-20 09:32:23.421 | ERROR    | utils.ClientLogManager:log:49 - Loop Failed! Error: Error in Opti::solve [OptiNode] at .../casadi/core/optistack.cpp:165:
.../casadi/core/optistack_internal.cpp:1030: Assertion "return_success(accept_limit)" failed:
Solver failed. You may use opti.debug.value to investigate the latest values of variables. return_status is 'NonIpopt_Exception_Thrown', occurred on line 48364 in file /home/turingzero/.local/lib/python3.10/site-packages/casadi/casadi.py
2024-12-20 09:32:23.608 | ERROR    | utils.ClientLogManager:log:49 - Loop Failed! Error: Error in Opti::solve [OptiNode] at .../casadi/core/optistack.cpp:165:
.../casadi/core/optistack_internal.cpp:1030: Assertion "return_success(accept_limit)" failed:
Solver failed. You may use opti.debug.value to investigate the latest values of variables. return_status is 'NonIpopt_Exception_Thrown', occurred on line 48364 in file /home/turingzero/.local/lib/python3.10/site-packages/casadi/casadi.py
2024-12-20 09:32:23.809 | ERROR    | utils.ClientLogManager:log:49 - Loop Failed! Error: Error in Opti::solve [OptiNode] at .../casadi/core/optistack.cpp:165:
.../casadi/core/optistack_internal.cpp:1030: Assertion "return_success(accept_limit)" failed:
Solver failed. You may use opti.debug.value to investigate the latest values of variables. return_status is 'NonIpopt_Exception_Thrown', occurred on line 48364 in file /home/turingzero/.local/lib/python3.10/site-packages/casadi/casadi.py
2024-12-20 09:32:24.309 | ERROR    | utils.ClientLogManager:log:49 - Loop Failed! Error: Error in Opti::solve [OptiNode] at .../casadi/core/optistack.cpp:165:
.../casadi/core/optistack_internal.cpp:1030: Assertion "return_success(accept_limit)" failed:
Solver failed. You may use opti.debug.value to investigate the latest values of variables. return_status is 'NonIpopt_Exception_Thrown', occurred on line 48364 in file /home/turingzero/.local/lib/python3.10/site-packages/casadi/casadi.py
2024-12-20 09:32:24.339 | ERROR    | utils.ClientLogManager:log:49 - Loop Failed! Error: Error in Opti::solve [OptiNode] at .../casadi/core/optistack.cpp:165:
.../casadi/core/optistack_internal.cpp:1030: Assertion "return_success(accept_limit)" failed:
Solver failed. You may use opti.debug.value to investigate the latest values of variables. return_status is 'NonIpopt_Exception_Thrown', occurred on line 48364 in file /home/turingzero/.local/lib/python3.10/site-packages/casadi/casadi.py
2024-12-20 09:32:24.369 | ERROR    | utils.ClientLogManager:log:49 - Loop Failed! Error: Error in Opti::solve [OptiNode] at .../casadi/core/optistack.cpp:165:
.../casadi/core/optistack_internal.cpp:1030: Assertion "return_success(accept_limit)" failed:
Solver failed. You may use opti.debug.value to investigate the latest values of variables. return_status is 'NonIpopt_Exception_Thrown', occurred on line 48364 in file /home/turingzero/.local/lib/python3.10/site-packages/casadi/casadi.py
2024-12-20 09:32:24.399 | ERROR    | utils.ClientLogManager:log:49 - Loop Failed! Error: Error in Opti::solve [OptiNode] at .../casadi/core/optistack.cpp:165:
.../casadi/core/optistack_internal.cpp:1030: Assertion "return_success(accept_limit)" failed:
Solver failed. You may use opti.debug.value to investigate the latest values of variables. return_status is 'NonIpopt_Exception_Thrown', occurred on line 48364 in file /home/turingzero/.local/lib/python3.10/site-packages/casadi/casadi.py
2024-12-20 09:32:24.430 | ERROR    | utils.ClientLogManager:log:49 - Loop Failed! Error: Error in Opti::solve [OptiNode] at .../casadi/core/optistack.cpp:165:
.../casadi/core/optistack_internal.cpp:1030: Assertion "return_success(accept_limit)" failed:
Solver failed. You may use opti.debug.value to investigate the latest values of variables. return_status is 'NonIpopt_Exception_Thrown', occurred on line 48364 in file /home/turingzero/.local/lib/python3.10/site-packages/casadi/casadi.py
2024-12-20 09:32:24.461 | ERROR    | utils.ClientLogManager:log:49 - Loop Failed! Error: Error in Opti::solve [OptiNode] at .../casadi/core/optistack.cpp:165:
.../casadi/core/optistack_internal.cpp:1030: Assertion "return_success(accept_limit)" failed:
Solver failed. You may use opti.debug.value to investigate the latest values of variables. return_status is 'NonIpopt_Exception_Thrown', occurred on line 48364 in file /home/turingzero/.local/lib/python3.10/site-packages/casadi/casadi.py
2024-12-20 09:32:24.490 | ERROR    | utils.ClientLogManager:log:49 - Loop Failed! Error: Error in Opti::solve [OptiNode] at .../casadi/core/optistack.cpp:165:
.../casadi/core/optistack_internal.cpp:1030: Assertion "return_success(accept_limit)" failed:
Solver failed. You may use opti.debug.value to investigate the latest values of variables. return_status is 'NonIpopt_Exception_Thrown', occurred on line 48364 in file /home/turingzero/.local/lib/python3.10/site-packages/casadi/casadi.py
2024-12-20 09:32:24.519 | ERROR    | utils.ClientLogManager:log:49 - Loop Failed! Error: _PyEval_EvalFrameDefault returned a result with an exception set, occurred on line 112 in file /home/turingzero/Downloads/TBK-Client/utils/MPCPlanner.py
2024-12-20 09:32:24.550 | ERROR    | utils.ClientLogManager:log:49 - Loop Failed! Error: Error in Opti::solve [OptiNode] at .../casadi/core/optistack.cpp:165:
.../casadi/core/optistack_internal.cpp:1030: Assertion "return_success(accept_limit)" failed:
Solver failed. You may use opti.debug.value to investigate the latest values of variables. return_status is 'NonIpopt_Exception_Thrown', occurred on line 48364 in file /home/turingzero/.local/lib/python3.10/site-packages/casadi/casadi.py
2024-12-20 09:32:24.581 | ERROR    | utils.ClientLogManager:log:49 - Loop Failed! Error: Error in Opti::solve [OptiNode] at .../casadi/core/optistack.cpp:165:
.../casadi/core/optistack_internal.cpp:1030: Assertion "return_success(accept_limit)" failed:
Solver failed. You may use opti.debug.value to investigate the latest values of variables. return_status is 'NonIpopt_Exception_Thrown', occurred on line 48364 in file /home/turingzero/.local/lib/python3.10/site-packages/casadi/casadi.py
2024-12-20 09:32:24.611 | ERROR    | utils.ClientLogManager:log:49 - Loop Failed! Error: Error in Opti::solve [OptiNode] at .../casadi/core/optistack.cpp:165:
.../casadi/core/optistack_internal.cpp:1030: Assertion "return_success(accept_limit)" failed:
Solver failed. You may use opti.debug.value to investigate the latest values of variables. return_status is 'NonIpopt_Exception_Thrown', occurred on line 48364 in file /home/turingzero/.local/lib/python3.10/site-packages/casadi/casadi.py
2024-12-20 09:32:24.641 | ERROR    | utils.ClientLogManager:log:49 - Loop Failed! Error: Error in Opti::solve [OptiNode] at .../casadi/core/optistack.cpp:165:
.../casadi/core/optistack_internal.cpp:1030: Assertion "return_success(accept_limit)" failed:
Solver failed. You may use opti.debug.value to investigate the latest values of variables. return_status is 'NonIpopt_Exception_Thrown', occurred on line 48364 in file /home/turingzero/.local/lib/python3.10/site-packages/casadi/casadi.py
2024-12-20 09:32:24.672 | ERROR    | utils.ClientLogManager:log:49 - Loop Failed! Error: Error in Opti::solve [OptiNode] at .../casadi/core/optistack.cpp:165:
.../casadi/core/optistack_internal.cpp:1030: Assertion "return_success(accept_limit)" failed:
Solver failed. You may use opti.debug.value to investigate the latest values of variables. return_status is 'NonIpopt_Exception_Thrown', occurred on line 48364 in file /home/turingzero/.local/lib/python3.10/site-packages/casadi/casadi.py
2024-12-20 09:32:24.702 | ERROR    | utils.ClientLogManager:log:49 - Loop Failed! Error: Error in Opti::solve [OptiNode] at .../casadi/core/optistack.cpp:165:
.../casadi/core/optistack_internal.cpp:1030: Assertion "return_success(accept_limit)" failed:
Solver failed. You may use opti.debug.value to investigate the latest values of variables. return_status is 'NonIpopt_Exception_Thrown', occurred on line 48364 in file /home/turingzero/.local/lib/python3.10/site-packages/casadi/casadi.py
2024-12-20 09:32:24.732 | ERROR    | utils.ClientLogManager:log:49 - Loop Failed! Error: Error in Opti::solve [OptiNode] at .../casadi/core/optistack.cpp:165:
.../casadi/core/optistack_internal.cpp:1030: Assertion "return_success(accept_limit)" failed:
Solver failed. You may use opti.debug.value to investigate the latest values of variables. return_status is 'NonIpopt_Exception_Thrown', occurred on line 48364 in file /home/turingzero/.local/lib/python3.10/site-packages/casadi/casadi.py
2024-12-20 09:32:24.762 | ERROR    | utils.ClientLogManager:log:49 - Loop Failed! Error: Error in Opti::solve [OptiNode] at .../casadi/core/optistack.cpp:165:
.../casadi/core/optistack_internal.cpp:1030: Assertion "return_success(accept_limit)" failed:
Solver failed. You may use opti.debug.value to investigate the latest values of variables. return_status is 'NonIpopt_Exception_Thrown', occurred on line 48364 in file /home/turingzero/.local/lib/python3.10/site-packages/casadi/casadi.py
2024-12-20 09:32:24.792 | ERROR    | utils.ClientLogManager:log:49 - Loop Failed! Error: Error in Opti::solve [OptiNode] at .../casadi/core/optistack.cpp:165:
.../casadi/core/optistack_internal.cpp:1030: Assertion "return_success(accept_limit)" failed:
Solver failed. You may use opti.debug.value to investigate the latest values of variables. return_status is 'NonIpopt_Exception_Thrown', occurred on line 48364 in file /home/turingzero/.local/lib/python3.10/site-packages/casadi/casadi.py
2024-12-20 09:32:24.822 | ERROR    | utils.ClientLogManager:log:49 - Loop Failed! Error: Error in Opti::solve [OptiNode] at .../casadi/core/optistack.cpp:165:
.../casadi/core/optistack_internal.cpp:1030: Assertion "return_success(accept_limit)" failed:
Solver failed. You may use opti.debug.value to investigate the latest values of variables. return_status is 'NonIpopt_Exception_Thrown', occurred on line 48364 in file /home/turingzero/.local/lib/python3.10/site-packages/casadi/casadi.py
2024-12-20 09:32:24.852 | ERROR    | utils.ClientLogManager:log:49 - Loop Failed! Error: Error in Opti::solve [OptiNode] at .../casadi/core/optistack.cpp:165:
.../casadi/core/optistack_internal.cpp:1030: Assertion "return_success(accept_limit)" failed:
Solver failed. You may use opti.debug.value to investigate the latest values of variables. return_status is 'NonIpopt_Exception_Thrown', occurred on line 48364 in file /home/turingzero/.local/lib/python3.10/site-packages/casadi/casadi.py
2024-12-20 09:32:24.882 | ERROR    | utils.ClientLogManager:log:49 - Loop Failed! Error: Error in Opti::solve [OptiNode] at .../casadi/core/optistack.cpp:165:
.../casadi/core/optistack_internal.cpp:1030: Assertion "return_success(accept_limit)" failed:
Solver failed. You may use opti.debug.value to investigate the latest values of variables. return_status is 'NonIpopt_Exception_Thrown', occurred on line 48364 in file /home/turingzero/.local/lib/python3.10/site-packages/casadi/casadi.py
2024-12-20 09:32:24.912 | ERROR    | utils.ClientLogManager:log:49 - Loop Failed! Error: Error in Opti::solve [OptiNode] at .../casadi/core/optistack.cpp:165:
.../casadi/core/optistack_internal.cpp:1030: Assertion "return_success(accept_limit)" failed:
Solver failed. You may use opti.debug.value to investigate the latest values of variables. return_status is 'NonIpopt_Exception_Thrown', occurred on line 48364 in file /home/turingzero/.local/lib/python3.10/site-packages/casadi/casadi.py
2024-12-20 09:32:24.943 | ERROR    | utils.ClientLogManager:log:49 - Loop Failed! Error: Error in Opti::solve [OptiNode] at .../casadi/core/optistack.cpp:165:
.../casadi/core/optistack_internal.cpp:1030: Assertion "return_success(accept_limit)" failed:
Solver failed. You may use opti.debug.value to investigate the latest values of variables. return_status is 'NonIpopt_Exception_Thrown', occurred on line 48364 in file /home/turingzero/.local/lib/python3.10/site-packages/casadi/casadi.py
2024-12-20 09:32:24.972 | ERROR    | utils.ClientLogManager:log:49 - Loop Failed! Error: Error in Opti::solve [OptiNode] at .../casadi/core/optistack.cpp:165:
.../casadi/core/optistack_internal.cpp:1030: Assertion "return_success(accept_limit)" failed:
Solver failed. You may use opti.debug.value to investigate the latest values of variables. return_status is 'NonIpopt_Exception_Thrown', occurred on line 48364 in file /home/turingzero/.local/lib/python3.10/site-packages/casadi/casadi.py
2024-12-20 09:32:25.002 | ERROR    | utils.ClientLogManager:log:49 - Loop Failed! Error: Error in Opti::solve [OptiNode] at .../casadi/core/optistack.cpp:165:
.../casadi/core/optistack_internal.cpp:1030: Assertion "return_success(accept_limit)" failed:
Solver failed. You may use opti.debug.value to investigate the latest values of variables. return_status is 'NonIpopt_Exception_Thrown', occurred on line 48364 in file /home/turingzero/.local/lib/python3.10/site-packages/casadi/casadi.py
2024-12-20 09:32:25.033 | ERROR    | utils.ClientLogManager:log:49 - Loop Failed! Error: Error in Opti::solve [OptiNode] at .../casadi/core/optistack.cpp:165:
.../casadi/core/optistack_internal.cpp:1030: Assertion "return_success(accept_limit)" failed:
Solver failed. You may use opti.debug.value to investigate the latest values of variables. return_status is 'NonIpopt_Exception_Thrown', occurred on line 48364 in file /home/turingzero/.local/lib/python3.10/site-packages/casadi/casadi.py
2024-12-20 09:32:25.064 | ERROR    | utils.ClientLogManager:log:49 - Loop Failed! Error: Error in Opti::solve [OptiNode] at .../casadi/core/optistack.cpp:165:
.../casadi/core/optistack_internal.cpp:1030: Assertion "return_success(accept_limit)" failed:
Solver failed. You may use opti.debug.value to investigate the latest values of variables. return_status is 'NonIpopt_Exception_Thrown', occurred on line 48364 in file /home/turingzero/.local/lib/python3.10/site-packages/casadi/casadi.py
2024-12-20 09:32:25.093 | ERROR    | utils.ClientLogManager:log:49 - Loop Failed! Error: Error in Opti::solve [OptiNode] at .../casadi/core/optistack.cpp:165:
.../casadi/core/optistack_internal.cpp:1030: Assertion "return_success(accept_limit)" failed:
Solver failed. You may use opti.debug.value to investigate the latest values of variables. return_status is 'NonIpopt_Exception_Thrown', occurred on line 48364 in file /home/turingzero/.local/lib/python3.10/site-packages/casadi/casadi.py
2024-12-20 09:32:25.123 | ERROR    | utils.ClientLogManager:log:49 - Loop Failed! Error: Error in Opti::solve [OptiNode] at .../casadi/core/optistack.cpp:165:
.../casadi/core/optistack_internal.cpp:1030: Assertion "return_success(accept_limit)" failed:
Solver failed. You may use opti.debug.value to investigate the latest values of variables. return_status is 'NonIpopt_Exception_Thrown', occurred on line 48364 in file /home/turingzero/.local/lib/python3.10/site-packages/casadi/casadi.py
2024-12-20 09:32:25.152 | ERROR    | utils.ClientLogManager:log:49 - Loop Failed! Error: Error in Opti::solve [OptiNode] at .../casadi/core/optistack.cpp:165:
.../casadi/core/optistack_internal.cpp:1030: Assertion "return_success(accept_limit)" failed:
Solver failed. You may use opti.debug.value to investigate the latest values of variables. return_status is 'NonIpopt_Exception_Thrown', occurred on line 48364 in file /home/turingzero/.local/lib/python3.10/site-packages/casadi/casadi.py
2024-12-20 09:32:25.182 | ERROR    | utils.ClientLogManager:log:49 - Loop Failed! Error: Error in Opti::solve [OptiNode] at .../casadi/core/optistack.cpp:165:
.../casadi/core/optistack_internal.cpp:1030: Assertion "return_success(accept_limit)" failed:
Solver failed. You may use opti.debug.value to investigate the latest values of variables. return_status is 'NonIpopt_Exception_Thrown', occurred on line 48364 in file /home/turingzero/.local/lib/python3.10/site-packages/casadi/casadi.py
2024-12-20 09:32:25.214 | ERROR    | utils.ClientLogManager:log:49 - Loop Failed! Error: Error in Opti::solve [OptiNode] at .../casadi/core/optistack.cpp:165:
.../casadi/core/optistack_internal.cpp:1030: Assertion "return_success(accept_limit)" failed:
Solver failed. You may use opti.debug.value to investigate the latest values of variables. return_status is 'NonIpopt_Exception_Thrown', occurred on line 48364 in file /home/turingzero/.local/lib/python3.10/site-packages/casadi/casadi.py
2024-12-20 09:32:25.244 | ERROR    | utils.ClientLogManager:log:49 - Loop Failed! Error: Error in Opti::solve [OptiNode] at .../casadi/core/optistack.cpp:165:
.../casadi/core/optistack_internal.cpp:1030: Assertion "return_success(accept_limit)" failed:
Solver failed. You may use opti.debug.value to investigate the latest values of variables. return_status is 'NonIpopt_Exception_Thrown', occurred on line 48364 in file /home/turingzero/.local/lib/python3.10/site-packages/casadi/casadi.py
2024-12-20 09:32:25.273 | ERROR    | utils.ClientLogManager:log:49 - Loop Failed! Error: Error in Opti::solve [OptiNode] at .../casadi/core/optistack.cpp:165:
.../casadi/core/optistack_internal.cpp:1030: Assertion "return_success(accept_limit)" failed:
Solver failed. You may use opti.debug.value to investigate the latest values of variables. return_status is 'NonIpopt_Exception_Thrown', occurred on line 48364 in file /home/turingzero/.local/lib/python3.10/site-packages/casadi/casadi.py
2024-12-20 09:32:25.335 | ERROR    | utils.ClientLogManager:log:49 - Loop Failed! Error: Error in Opti::solve [OptiNode] at .../casadi/core/optistack.cpp:165:
.../casadi/core/optistack_internal.cpp:1030: Assertion "return_success(accept_limit)" failed:
Solver failed. You may use opti.debug.value to investigate the latest values of variables. return_status is 'NonIpopt_Exception_Thrown', occurred on line 48364 in file /home/turingzero/.local/lib/python3.10/site-packages/casadi/casadi.py
2024-12-20 09:32:25.363 | ERROR    | utils.ClientLogManager:log:49 - Loop Failed! Error: Error in Opti::solve [OptiNode] at .../casadi/core/optistack.cpp:165:
.../casadi/core/optistack_internal.cpp:1030: Assertion "return_success(accept_limit)" failed:
Solver failed. You may use opti.debug.value to investigate the latest values of variables. return_status is 'NonIpopt_Exception_Thrown', occurred on line 48364 in file /home/turingzero/.local/lib/python3.10/site-packages/casadi/casadi.py
2024-12-20 09:32:25.397 | ERROR    | utils.ClientLogManager:log:49 - Loop Failed! Error: Error in Opti::solve [OptiNode] at .../casadi/core/optistack.cpp:165:
.../casadi/core/optistack_internal.cpp:1030: Assertion "return_success(accept_limit)" failed:
Solver failed. You may use opti.debug.value to investigate the latest values of variables. return_status is 'NonIpopt_Exception_Thrown', occurred on line 48364 in file /home/turingzero/.local/lib/python3.10/site-packages/casadi/casadi.py
2024-12-20 09:32:25.424 | ERROR    | utils.ClientLogManager:log:49 - Loop Failed! Error: Error in Opti::solve [OptiNode] at .../casadi/core/optistack.cpp:165:
.../casadi/core/optistack_internal.cpp:1030: Assertion "return_success(accept_limit)" failed:
Solver failed. You may use opti.debug.value to investigate the latest values of variables. return_status is 'NonIpopt_Exception_Thrown', occurred on line 48364 in file /home/turingzero/.local/lib/python3.10/site-packages/casadi/casadi.py
2024-12-20 09:32:25.453 | ERROR    | utils.ClientLogManager:log:49 - Loop Failed! Error: Error in Opti::solve [OptiNode] at .../casadi/core/optistack.cpp:165:
.../casadi/core/optistack_internal.cpp:1030: Assertion "return_success(accept_limit)" failed:
Solver failed. You may use opti.debug.value to investigate the latest values of variables. return_status is 'NonIpopt_Exception_Thrown', occurred on line 48364 in file /home/turingzero/.local/lib/python3.10/site-packages/casadi/casadi.py
2024-12-20 09:32:25.483 | ERROR    | utils.ClientLogManager:log:49 - Loop Failed! Error: Error in Opti::solve [OptiNode] at .../casadi/core/optistack.cpp:165:
.../casadi/core/optistack_internal.cpp:1030: Assertion "return_success(accept_limit)" failed:
Solver failed. You may use opti.debug.value to investigate the latest values of variables. return_status is 'NonIpopt_Exception_Thrown', occurred on line 48364 in file /home/turingzero/.local/lib/python3.10/site-packages/casadi/casadi.py
2024-12-20 09:32:25.514 | ERROR    | utils.ClientLogManager:log:49 - Loop Failed! Error: Error in Opti::solve [OptiNode] at .../casadi/core/optistack.cpp:165:
.../casadi/core/optistack_internal.cpp:1030: Assertion "return_success(accept_limit)" failed:
Solver failed. You may use opti.debug.value to investigate the latest values of variables. return_status is 'NonIpopt_Exception_Thrown', occurred on line 48364 in file /home/turingzero/.local/lib/python3.10/site-packages/casadi/casadi.py
2024-12-20 09:32:25.543 | ERROR    | utils.ClientLogManager:log:49 - Loop Failed! Error: Error in Opti::solve [OptiNode] at .../casadi/core/optistack.cpp:165:
.../casadi/core/optistack_internal.cpp:1030: Assertion "return_success(accept_limit)" failed:
Solver failed. You may use opti.debug.value to investigate the latest values of variables. return_status is 'NonIpopt_Exception_Thrown', occurred on line 48364 in file /home/turingzero/.local/lib/python3.10/site-packages/casadi/casadi.py
2024-12-20 09:32:25.573 | ERROR    | utils.ClientLogManager:log:49 - Loop Failed! Error: Error in Opti::solve [OptiNode] at .../casadi/core/optistack.cpp:165:
.../casadi/core/optistack_internal.cpp:1030: Assertion "return_success(accept_limit)" failed:
Solver failed. You may use opti.debug.value to investigate the latest values of variables. return_status is 'NonIpopt_Exception_Thrown', occurred on line 48364 in file /home/turingzero/.local/lib/python3.10/site-packages/casadi/casadi.py
2024-12-20 09:32:25.603 | ERROR    | utils.ClientLogManager:log:49 - Loop Failed! Error: Error in Opti::solve [OptiNode] at .../casadi/core/optistack.cpp:165:
.../casadi/core/optistack_internal.cpp:1030: Assertion "return_success(accept_limit)" failed:
Solver failed. You may use opti.debug.value to investigate the latest values of variables. return_status is 'NonIpopt_Exception_Thrown', occurred on line 48364 in file /home/turingzero/.local/lib/python3.10/site-packages/casadi/casadi.py
2024-12-20 09:32:25.633 | ERROR    | utils.ClientLogManager:log:49 - Loop Failed! Error: Error in Opti::solve [OptiNode] at .../casadi/core/optistack.cpp:165:
.../casadi/core/optistack_internal.cpp:1030: Assertion "return_success(accept_limit)" failed:
Solver failed. You may use opti.debug.value to investigate the latest values of variables. return_status is 'NonIpopt_Exception_Thrown', occurred on line 48364 in file /home/turingzero/.local/lib/python3.10/site-packages/casadi/casadi.py
2024-12-20 09:32:25.664 | ERROR    | utils.ClientLogManager:log:49 - Loop Failed! Error: Error in Opti::solve [OptiNode] at .../casadi/core/optistack.cpp:165:
.../casadi/core/optistack_internal.cpp:1030: Assertion "return_success(accept_limit)" failed:
Solver failed. You may use opti.debug.value to investigate the latest values of variables. return_status is 'NonIpopt_Exception_Thrown', occurred on line 48364 in file /home/turingzero/.local/lib/python3.10/site-packages/casadi/casadi.py
2024-12-20 09:32:25.693 | ERROR    | utils.ClientLogManager:log:49 - Loop Failed! Error: Error in Opti::solve [OptiNode] at .../casadi/core/optistack.cpp:165:
.../casadi/core/optistack_internal.cpp:1030: Assertion "return_success(accept_limit)" failed:
Solver failed. You may use opti.debug.value to investigate the latest values of variables. return_status is 'NonIpopt_Exception_Thrown', occurred on line 48364 in file /home/turingzero/.local/lib/python3.10/site-packages/casadi/casadi.py
2024-12-20 09:32:25.723 | ERROR    | utils.ClientLogManager:log:49 - Loop Failed! Error: Error in Opti::solve [OptiNode] at .../casadi/core/optistack.cpp:165:
.../casadi/core/optistack_internal.cpp:1030: Assertion "return_success(accept_limit)" failed:
Solver failed. You may use opti.debug.value to investigate the latest values of variables. return_status is 'NonIpopt_Exception_Thrown', occurred on line 48364 in file /home/turingzero/.local/lib/python3.10/site-packages/casadi/casadi.py
2024-12-20 09:32:25.753 | ERROR    | utils.ClientLogManager:log:49 - Loop Failed! Error: Error in Opti::solve [OptiNode] at .../casadi/core/optistack.cpp:165:
.../casadi/core/optistack_internal.cpp:1030: Assertion "return_success(accept_limit)" failed:
Solver failed. You may use opti.debug.value to investigate the latest values of variables. return_status is 'NonIpopt_Exception_Thrown', occurred on line 48364 in file /home/turingzero/.local/lib/python3.10/site-packages/casadi/casadi.py
2024-12-20 09:32:25.783 | ERROR    | utils.ClientLogManager:log:49 - Loop Failed! Error: Error in Opti::solve [OptiNode] at .../casadi/core/optistack.cpp:165:
.../casadi/core/optistack_internal.cpp:1030: Assertion "return_success(accept_limit)" failed:
Solver failed. You may use opti.debug.value to investigate the latest values of variables. return_status is 'NonIpopt_Exception_Thrown', occurred on line 48364 in file /home/turingzero/.local/lib/python3.10/site-packages/casadi/casadi.py
2024-12-20 09:32:26.030 | ERROR    | utils.ClientLogManager:log:49 - Loop Failed! Error: Wrong number or type of arguments for function 'Opti_set_value'.
  Prototype:
set_value(self,MX,DM)
  You have: '(Opti,MX,np.array(float))'
, occurred on line 48297 in file /home/turingzero/.local/lib/python3.10/site-packages/casadi/casadi.py
2024-12-20 09:32:26.031 | ERROR    | utils.ClientLogManager:log:49 - Loop Failed! Error: Wrong number or type of arguments for overloaded function 'Opti_set_value'.
  Possible prototypes are:
    set_value(self,[MX])
    set_value(self,MX,DM)
  You have: '(Opti,tuple_iterator,np.array(float))'
, occurred on line 48297 in file /home/turingzero/.local/lib/python3.10/site-packages/casadi/casadi.py
2024-12-20 09:40:02.529 | ERROR    | utils.ClientLogManager:log:49 - Loop Failed! Error: Error in Opti::solve [OptiNode] at .../casadi/core/optistack.cpp:165:
.../casadi/core/optistack_internal.cpp:1030: Assertion "return_success(accept_limit)" failed:
Solver failed. You may use opti.debug.value to investigate the latest values of variables. return_status is 'NonIpopt_Exception_Thrown', occurred on line 48364 in file /home/turingzero/.local/lib/python3.10/site-packages/casadi/casadi.py
2024-12-20 09:40:02.721 | ERROR    | utils.ClientLogManager:log:49 - Loop Failed! Error: Error in Opti::solve [OptiNode] at .../casadi/core/optistack.cpp:165:
.../casadi/core/optistack_internal.cpp:1030: Assertion "return_success(accept_limit)" failed:
Solver failed. You may use opti.debug.value to investigate the latest values of variables. return_status is 'NonIpopt_Exception_Thrown', occurred on line 48364 in file /home/turingzero/.local/lib/python3.10/site-packages/casadi/casadi.py
2024-12-20 09:40:02.901 | ERROR    | utils.ClientLogManager:log:49 - Loop Failed! Error: Error in Opti::solve [OptiNode] at .../casadi/core/optistack.cpp:165:
.../casadi/core/optistack_internal.cpp:1030: Assertion "return_success(accept_limit)" failed:
Solver failed. You may use opti.debug.value to investigate the latest values of variables. return_status is 'NonIpopt_Exception_Thrown', occurred on line 48364 in file /home/turingzero/.local/lib/python3.10/site-packages/casadi/casadi.py
2024-12-20 09:40:03.092 | ERROR    | utils.ClientLogManager:log:49 - Loop Failed! Error: Error in Opti::solve [OptiNode] at .../casadi/core/optistack.cpp:165:
.../casadi/core/optistack_internal.cpp:1030: Assertion "return_success(accept_limit)" failed:
Solver failed. You may use opti.debug.value to investigate the latest values of variables. return_status is 'NonIpopt_Exception_Thrown', occurred on line 48364 in file /home/turingzero/.local/lib/python3.10/site-packages/casadi/casadi.py
2024-12-20 09:40:03.269 | ERROR    | utils.ClientLogManager:log:49 - Loop Failed! Error: <built-in function OptiSol_value> returned a result with an exception set, occurred on line 50861 in file /home/turingzero/.local/lib/python3.10/site-packages/casadi/casadi.py
2024-12-20 09:40:04.784 | ERROR    | utils.ClientLogManager:log:49 - Loop Failed! Error: Error in Opti::solve [OptiNode] at .../casadi/core/optistack.cpp:165:
.../casadi/core/optistack_internal.cpp:1030: Assertion "return_success(accept_limit)" failed:
Solver failed. You may use opti.debug.value to investigate the latest values of variables. return_status is 'NonIpopt_Exception_Thrown', occurred on line 48364 in file /home/turingzero/.local/lib/python3.10/site-packages/casadi/casadi.py
2024-12-20 09:40:04.949 | ERROR    | utils.ClientLogManager:log:49 - Loop Failed! Error: Error in Opti::solve [OptiNode] at .../casadi/core/optistack.cpp:165:
.../casadi/core/optistack_internal.cpp:1030: Assertion "return_success(accept_limit)" failed:
Solver failed. You may use opti.debug.value to investigate the latest values of variables. return_status is 'NonIpopt_Exception_Thrown', occurred on line 48364 in file /home/turingzero/.local/lib/python3.10/site-packages/casadi/casadi.py
2024-12-20 09:40:05.448 | ERROR    | utils.ClientLogManager:log:49 - Loop Failed! Error: Error in Opti::solve [OptiNode] at .../casadi/core/optistack.cpp:165:
.../casadi/core/optistack_internal.cpp:1030: Assertion "return_success(accept_limit)" failed:
Solver failed. You may use opti.debug.value to investigate the latest values of variables. return_status is 'NonIpopt_Exception_Thrown', occurred on line 48364 in file /home/turingzero/.local/lib/python3.10/site-packages/casadi/casadi.py
2024-12-20 09:40:05.479 | ERROR    | utils.ClientLogManager:log:49 - Loop Failed! Error: Error in Opti::solve [OptiNode] at .../casadi/core/optistack.cpp:165:
.../casadi/core/optistack_internal.cpp:1030: Assertion "return_success(accept_limit)" failed:
Solver failed. You may use opti.debug.value to investigate the latest values of variables. return_status is 'NonIpopt_Exception_Thrown', occurred on line 48364 in file /home/turingzero/.local/lib/python3.10/site-packages/casadi/casadi.py
2024-12-20 09:40:05.508 | ERROR    | utils.ClientLogManager:log:49 - Loop Failed! Error: Error in Opti::solve [OptiNode] at .../casadi/core/optistack.cpp:165:
.../casadi/core/optistack_internal.cpp:1030: Assertion "return_success(accept_limit)" failed:
Solver failed. You may use opti.debug.value to investigate the latest values of variables. return_status is 'NonIpopt_Exception_Thrown', occurred on line 48364 in file /home/turingzero/.local/lib/python3.10/site-packages/casadi/casadi.py
2024-12-20 09:40:05.538 | ERROR    | utils.ClientLogManager:log:49 - Loop Failed! Error: Error in Opti::solve [OptiNode] at .../casadi/core/optistack.cpp:165:
.../casadi/core/optistack_internal.cpp:1030: Assertion "return_success(accept_limit)" failed:
Solver failed. You may use opti.debug.value to investigate the latest values of variables. return_status is 'NonIpopt_Exception_Thrown', occurred on line 48364 in file /home/turingzero/.local/lib/python3.10/site-packages/casadi/casadi.py
2024-12-20 09:40:05.568 | ERROR    | utils.ClientLogManager:log:49 - Loop Failed! Error: Error in Opti::solve [OptiNode] at .../casadi/core/optistack.cpp:165:
.../casadi/core/optistack_internal.cpp:1030: Assertion "return_success(accept_limit)" failed:
Solver failed. You may use opti.debug.value to investigate the latest values of variables. return_status is 'NonIpopt_Exception_Thrown', occurred on line 48364 in file /home/turingzero/.local/lib/python3.10/site-packages/casadi/casadi.py
2024-12-20 09:40:05.598 | ERROR    | utils.ClientLogManager:log:49 - Loop Failed! Error: Error in Opti::solve [OptiNode] at .../casadi/core/optistack.cpp:165:
.../casadi/core/optistack_internal.cpp:1030: Assertion "return_success(accept_limit)" failed:
Solver failed. You may use opti.debug.value to investigate the latest values of variables. return_status is 'NonIpopt_Exception_Thrown', occurred on line 48364 in file /home/turingzero/.local/lib/python3.10/site-packages/casadi/casadi.py
2024-12-20 09:40:05.628 | ERROR    | utils.ClientLogManager:log:49 - Loop Failed! Error: Error in Opti::solve [OptiNode] at .../casadi/core/optistack.cpp:165:
.../casadi/core/optistack_internal.cpp:1030: Assertion "return_success(accept_limit)" failed:
Solver failed. You may use opti.debug.value to investigate the latest values of variables. return_status is 'NonIpopt_Exception_Thrown', occurred on line 48364 in file /home/turingzero/.local/lib/python3.10/site-packages/casadi/casadi.py
2024-12-20 10:56:56.133 | ERROR    | utils.ClientLogManager:log:49 - Loop Failed! Error: Error in Opti::solve [OptiNode] at .../casadi/core/optistack.cpp:165:
.../casadi/core/optistack_internal.cpp:1030: Assertion "return_success(accept_limit)" failed:
Solver failed. You may use opti.debug.value to investigate the latest values of variables. return_status is 'NonIpopt_Exception_Thrown', occurred on line 48364 in file /usr/local/lib/python3.8/dist-packages/casadi/casadi.py
2024-12-20 14:51:27.308 | ERROR    | utils.ClientLogManager:log:49 - <utils.node_utils.TBKNode.Subscriber object at 0x7fded47b2430> calc failed! Error: 'TBKManager' object has no attribute 'Subscriber', occurred on line 63 in file /home/mark/TnTeQAQ/workspace/dpg demo/TBK-Client/utils/node_utils/TBKNode.py
2024-12-20 14:51:27.324 | ERROR    | utils.ClientLogManager:log:49 - <utils.node_utils.TBKNode.Subscriber object at 0x7fded47b2430> calc failed! Error: 'TBKManager' object has no attribute 'Subscriber', occurred on line 63 in file /home/mark/TnTeQAQ/workspace/dpg demo/TBK-Client/utils/node_utils/TBKNode.py
2024-12-20 14:51:27.341 | ERROR    | utils.ClientLogManager:log:49 - <utils.node_utils.TBKNode.Subscriber object at 0x7fded47b2430> calc failed! Error: 'TBKManager' object has no attribute 'Subscriber', occurred on line 63 in file /home/mark/TnTeQAQ/workspace/dpg demo/TBK-Client/utils/node_utils/TBKNode.py
2024-12-20 14:51:27.358 | ERROR    | utils.ClientLogManager:log:49 - <utils.node_utils.TBKNode.Subscriber object at 0x7fded47b2430> calc failed! Error: 'TBKManager' object has no attribute 'Subscriber', occurred on line 63 in file /home/mark/TnTeQAQ/workspace/dpg demo/TBK-Client/utils/node_utils/TBKNode.py
2024-12-20 14:51:27.374 | ERROR    | utils.ClientLogManager:log:49 - <utils.node_utils.TBKNode.Subscriber object at 0x7fded47b2430> calc failed! Error: 'TBKManager' object has no attribute 'Subscriber', occurred on line 63 in file /home/mark/TnTeQAQ/workspace/dpg demo/TBK-Client/utils/node_utils/TBKNode.py
2024-12-20 14:51:27.391 | ERROR    | utils.ClientLogManager:log:49 - <utils.node_utils.TBKNode.Subscriber object at 0x7fded47b2430> calc failed! Error: 'TBKManager' object has no attribute 'Subscriber', occurred on line 63 in file /home/mark/TnTeQAQ/workspace/dpg demo/TBK-Client/utils/node_utils/TBKNode.py
2024-12-20 14:51:27.408 | ERROR    | utils.ClientLogManager:log:49 - <utils.node_utils.TBKNode.Subscriber object at 0x7fded47b2430> calc failed! Error: 'TBKManager' object has no attribute 'Subscriber', occurred on line 63 in file /home/mark/TnTeQAQ/workspace/dpg demo/TBK-Client/utils/node_utils/TBKNode.py
2024-12-20 14:51:27.424 | ERROR    | utils.ClientLogManager:log:49 - <utils.node_utils.TBKNode.Subscriber object at 0x7fded47b2430> calc failed! Error: 'TBKManager' object has no attribute 'Subscriber', occurred on line 63 in file /home/mark/TnTeQAQ/workspace/dpg demo/TBK-Client/utils/node_utils/TBKNode.py
2024-12-20 14:51:27.441 | ERROR    | utils.ClientLogManager:log:49 - <utils.node_utils.TBKNode.Subscriber object at 0x7fded47b2430> calc failed! Error: 'TBKManager' object has no attribute 'Subscriber', occurred on line 63 in file /home/mark/TnTeQAQ/workspace/dpg demo/TBK-Client/utils/node_utils/TBKNode.py
2024-12-20 14:51:27.458 | ERROR    | utils.ClientLogManager:log:49 - <utils.node_utils.TBKNode.Subscriber object at 0x7fded47b2430> calc failed! Error: 'TBKManager' object has no attribute 'Subscriber', occurred on line 63 in file /home/mark/TnTeQAQ/workspace/dpg demo/TBK-Client/utils/node_utils/TBKNode.py
2024-12-20 14:51:27.474 | ERROR    | utils.ClientLogManager:log:49 - <utils.node_utils.TBKNode.Subscriber object at 0x7fded47b2430> calc failed! Error: 'TBKManager' object has no attribute 'Subscriber', occurred on line 63 in file /home/mark/TnTeQAQ/workspace/dpg demo/TBK-Client/utils/node_utils/TBKNode.py
2024-12-20 14:51:27.491 | ERROR    | utils.ClientLogManager:log:49 - <utils.node_utils.TBKNode.Subscriber object at 0x7fded47b2430> calc failed! Error: 'TBKManager' object has no attribute 'Subscriber', occurred on line 63 in file /home/mark/TnTeQAQ/workspace/dpg demo/TBK-Client/utils/node_utils/TBKNode.py
2024-12-20 14:51:27.508 | ERROR    | utils.ClientLogManager:log:49 - <utils.node_utils.TBKNode.Subscriber object at 0x7fded47b2430> calc failed! Error: 'TBKManager' object has no attribute 'Subscriber', occurred on line 63 in file /home/mark/TnTeQAQ/workspace/dpg demo/TBK-Client/utils/node_utils/TBKNode.py
2024-12-20 14:51:27.525 | ERROR    | utils.ClientLogManager:log:49 - <utils.node_utils.TBKNode.Subscriber object at 0x7fded47b2430> calc failed! Error: 'TBKManager' object has no attribute 'Subscriber', occurred on line 63 in file /home/mark/TnTeQAQ/workspace/dpg demo/TBK-Client/utils/node_utils/TBKNode.py
2024-12-20 14:51:27.578 | ERROR    | utils.ClientLogManager:log:49 - <utils.node_utils.TBKNode.Subscriber object at 0x7fded47b2430> calc failed! Error: 'TBKManager' object has no attribute 'Subscriber', occurred on line 63 in file /home/mark/TnTeQAQ/workspace/dpg demo/TBK-Client/utils/node_utils/TBKNode.py
2024-12-20 14:51:27.643 | ERROR    | utils.ClientLogManager:log:49 - <utils.node_utils.TBKNode.Subscriber object at 0x7fded47b2430> calc failed! Error: 'TBKManager' object has no attribute 'Subscriber', occurred on line 63 in file /home/mark/TnTeQAQ/workspace/dpg demo/TBK-Client/utils/node_utils/TBKNode.py
2024-12-20 14:51:27.699 | ERROR    | utils.ClientLogManager:log:49 - <utils.node_utils.TBKNode.Subscriber object at 0x7fded47b2430> calc failed! Error: 'TBKManager' object has no attribute 'Subscriber', occurred on line 63 in file /home/mark/TnTeQAQ/workspace/dpg demo/TBK-Client/utils/node_utils/TBKNode.py
2024-12-20 14:51:27.753 | ERROR    | utils.ClientLogManager:log:49 - <utils.node_utils.TBKNode.Subscriber object at 0x7fded47b2430> calc failed! Error: 'TBKManager' object has no attribute 'Subscriber', occurred on line 63 in file /home/mark/TnTeQAQ/workspace/dpg demo/TBK-Client/utils/node_utils/TBKNode.py
2024-12-20 14:51:27.801 | ERROR    | utils.ClientLogManager:log:49 - <utils.node_utils.TBKNode.Subscriber object at 0x7fded47b2430> calc failed! Error: 'TBKManager' object has no attribute 'Subscriber', occurred on line 63 in file /home/mark/TnTeQAQ/workspace/dpg demo/TBK-Client/utils/node_utils/TBKNode.py
2024-12-20 14:51:27.810 | ERROR    | utils.ClientLogManager:log:49 - <utils.node_utils.TBKNode.Subscriber object at 0x7fded47b2430> calc failed! Error: 'TBKManager' object has no attribute 'Subscriber', occurred on line 63 in file /home/mark/TnTeQAQ/workspace/dpg demo/TBK-Client/utils/node_utils/TBKNode.py
2024-12-20 14:51:27.824 | ERROR    | utils.ClientLogManager:log:49 - <utils.node_utils.TBKNode.Subscriber object at 0x7fded47b2430> calc failed! Error: 'TBKManager' object has no attribute 'Subscriber', occurred on line 63 in file /home/mark/TnTeQAQ/workspace/dpg demo/TBK-Client/utils/node_utils/TBKNode.py
2024-12-20 14:51:27.841 | ERROR    | utils.ClientLogManager:log:49 - <utils.node_utils.TBKNode.Subscriber object at 0x7fded47b2430> calc failed! Error: 'TBKManager' object has no attribute 'Subscriber', occurred on line 63 in file /home/mark/TnTeQAQ/workspace/dpg demo/TBK-Client/utils/node_utils/TBKNode.py
2024-12-20 14:51:27.855 | ERROR    | utils.ClientLogManager:log:49 - <utils.node_utils.TBKNode.Subscriber object at 0x7fded47b2430> calc failed! Error: 'TBKManager' object has no attribute 'Subscriber', occurred on line 63 in file /home/mark/TnTeQAQ/workspace/dpg demo/TBK-Client/utils/node_utils/TBKNode.py
2024-12-20 14:51:27.872 | ERROR    | utils.ClientLogManager:log:49 - <utils.node_utils.TBKNode.Subscriber object at 0x7fded47b2430> calc failed! Error: 'TBKManager' object has no attribute 'Subscriber', occurred on line 63 in file /home/mark/TnTeQAQ/workspace/dpg demo/TBK-Client/utils/node_utils/TBKNode.py
2024-12-20 14:51:27.888 | ERROR    | utils.ClientLogManager:log:49 - <utils.node_utils.TBKNode.Subscriber object at 0x7fded47b2430> calc failed! Error: 'TBKManager' object has no attribute 'Subscriber', occurred on line 63 in file /home/mark/TnTeQAQ/workspace/dpg demo/TBK-Client/utils/node_utils/TBKNode.py
2024-12-20 14:51:27.905 | ERROR    | utils.ClientLogManager:log:49 - <utils.node_utils.TBKNode.Subscriber object at 0x7fded47b2430> calc failed! Error: 'TBKManager' object has no attribute 'Subscriber', occurred on line 63 in file /home/mark/TnTeQAQ/workspace/dpg demo/TBK-Client/utils/node_utils/TBKNode.py
2024-12-20 14:51:27.922 | ERROR    | utils.ClientLogManager:log:49 - <utils.node_utils.TBKNode.Subscriber object at 0x7fded47b2430> calc failed! Error: 'TBKManager' object has no attribute 'Subscriber', occurred on line 63 in file /home/mark/TnTeQAQ/workspace/dpg demo/TBK-Client/utils/node_utils/TBKNode.py
2024-12-20 14:51:27.938 | ERROR    | utils.ClientLogManager:log:49 - <utils.node_utils.TBKNode.Subscriber object at 0x7fded47b2430> calc failed! Error: 'TBKManager' object has no attribute 'Subscriber', occurred on line 63 in file /home/mark/TnTeQAQ/workspace/dpg demo/TBK-Client/utils/node_utils/TBKNode.py
2024-12-20 14:51:27.955 | ERROR    | utils.ClientLogManager:log:49 - <utils.node_utils.TBKNode.Subscriber object at 0x7fded47b2430> calc failed! Error: 'TBKManager' object has no attribute 'Subscriber', occurred on line 63 in file /home/mark/TnTeQAQ/workspace/dpg demo/TBK-Client/utils/node_utils/TBKNode.py
2024-12-20 14:51:27.972 | ERROR    | utils.ClientLogManager:log:49 - <utils.node_utils.TBKNode.Subscriber object at 0x7fded47b2430> calc failed! Error: 'TBKManager' object has no attribute 'Subscriber', occurred on line 63 in file /home/mark/TnTeQAQ/workspace/dpg demo/TBK-Client/utils/node_utils/TBKNode.py
2024-12-20 14:51:28.025 | ERROR    | utils.ClientLogManager:log:49 - <utils.node_utils.TBKNode.Subscriber object at 0x7fded47b2430> calc failed! Error: 'TBKManager' object has no attribute 'Subscriber', occurred on line 63 in file /home/mark/TnTeQAQ/workspace/dpg demo/TBK-Client/utils/node_utils/TBKNode.py
2024-12-20 14:51:28.077 | ERROR    | utils.ClientLogManager:log:49 - <utils.node_utils.TBKNode.Subscriber object at 0x7fded47b2430> calc failed! Error: 'TBKManager' object has no attribute 'Subscriber', occurred on line 63 in file /home/mark/TnTeQAQ/workspace/dpg demo/TBK-Client/utils/node_utils/TBKNode.py
2024-12-20 14:51:28.088 | ERROR    | utils.ClientLogManager:log:49 - <utils.node_utils.TBKNode.Subscriber object at 0x7fded47b2430> calc failed! Error: 'TBKManager' object has no attribute 'Subscriber', occurred on line 63 in file /home/mark/TnTeQAQ/workspace/dpg demo/TBK-Client/utils/node_utils/TBKNode.py
2024-12-20 14:51:28.105 | ERROR    | utils.ClientLogManager:log:49 - <utils.node_utils.TBKNode.Subscriber object at 0x7fded47b2430> calc failed! Error: 'TBKManager' object has no attribute 'Subscriber', occurred on line 63 in file /home/mark/TnTeQAQ/workspace/dpg demo/TBK-Client/utils/node_utils/TBKNode.py
2024-12-20 14:51:28.122 | ERROR    | utils.ClientLogManager:log:49 - <utils.node_utils.TBKNode.Subscriber object at 0x7fded47b2430> calc failed! Error: 'TBKManager' object has no attribute 'Subscriber', occurred on line 63 in file /home/mark/TnTeQAQ/workspace/dpg demo/TBK-Client/utils/node_utils/TBKNode.py
2024-12-20 14:51:28.138 | ERROR    | utils.ClientLogManager:log:49 - <utils.node_utils.TBKNode.Subscriber object at 0x7fded47b2430> calc failed! Error: 'TBKManager' object has no attribute 'Subscriber', occurred on line 63 in file /home/mark/TnTeQAQ/workspace/dpg demo/TBK-Client/utils/node_utils/TBKNode.py
2024-12-20 14:51:28.155 | ERROR    | utils.ClientLogManager:log:49 - <utils.node_utils.TBKNode.Subscriber object at 0x7fded47b2430> calc failed! Error: 'TBKManager' object has no attribute 'Subscriber', occurred on line 63 in file /home/mark/TnTeQAQ/workspace/dpg demo/TBK-Client/utils/node_utils/TBKNode.py
2024-12-20 14:51:28.173 | ERROR    | utils.ClientLogManager:log:49 - <utils.node_utils.TBKNode.Subscriber object at 0x7fded47b2430> calc failed! Error: 'TBKManager' object has no attribute 'Subscriber', occurred on line 63 in file /home/mark/TnTeQAQ/workspace/dpg demo/TBK-Client/utils/node_utils/TBKNode.py
2024-12-20 14:51:28.226 | ERROR    | utils.ClientLogManager:log:49 - <utils.node_utils.TBKNode.Subscriber object at 0x7fded47b2430> calc failed! Error: 'TBKManager' object has no attribute 'Subscriber', occurred on line 63 in file /home/mark/TnTeQAQ/workspace/dpg demo/TBK-Client/utils/node_utils/TBKNode.py
2024-12-20 14:51:28.257 | ERROR    | utils.ClientLogManager:log:49 - <utils.node_utils.TBKNode.Subscriber object at 0x7fded47b2430> calc failed! Error: 'TBKManager' object has no attribute 'Subscriber', occurred on line 63 in file /home/mark/TnTeQAQ/workspace/dpg demo/TBK-Client/utils/node_utils/TBKNode.py
2024-12-20 14:51:28.272 | ERROR    | utils.ClientLogManager:log:49 - <utils.node_utils.TBKNode.Subscriber object at 0x7fded47b2430> calc failed! Error: 'TBKManager' object has no attribute 'Subscriber', occurred on line 63 in file /home/mark/TnTeQAQ/workspace/dpg demo/TBK-Client/utils/node_utils/TBKNode.py
2024-12-20 14:51:28.289 | ERROR    | utils.ClientLogManager:log:49 - <utils.node_utils.TBKNode.Subscriber object at 0x7fded47b2430> calc failed! Error: 'TBKManager' object has no attribute 'Subscriber', occurred on line 63 in file /home/mark/TnTeQAQ/workspace/dpg demo/TBK-Client/utils/node_utils/TBKNode.py
2024-12-20 14:51:28.305 | ERROR    | utils.ClientLogManager:log:49 - <utils.node_utils.TBKNode.Subscriber object at 0x7fded47b2430> calc failed! Error: 'TBKManager' object has no attribute 'Subscriber', occurred on line 63 in file /home/mark/TnTeQAQ/workspace/dpg demo/TBK-Client/utils/node_utils/TBKNode.py
2024-12-20 14:51:28.322 | ERROR    | utils.ClientLogManager:log:49 - <utils.node_utils.TBKNode.Subscriber object at 0x7fded47b2430> calc failed! Error: 'TBKManager' object has no attribute 'Subscriber', occurred on line 63 in file /home/mark/TnTeQAQ/workspace/dpg demo/TBK-Client/utils/node_utils/TBKNode.py
2024-12-20 14:51:28.339 | ERROR    | utils.ClientLogManager:log:49 - <utils.node_utils.TBKNode.Subscriber object at 0x7fded47b2430> calc failed! Error: 'TBKManager' object has no attribute 'Subscriber', occurred on line 63 in file /home/mark/TnTeQAQ/workspace/dpg demo/TBK-Client/utils/node_utils/TBKNode.py
2024-12-20 14:51:28.355 | ERROR    | utils.ClientLogManager:log:49 - <utils.node_utils.TBKNode.Subscriber object at 0x7fded47b2430> calc failed! Error: 'TBKManager' object has no attribute 'Subscriber', occurred on line 63 in file /home/mark/TnTeQAQ/workspace/dpg demo/TBK-Client/utils/node_utils/TBKNode.py
2024-12-20 14:51:28.372 | ERROR    | utils.ClientLogManager:log:49 - <utils.node_utils.TBKNode.Subscriber object at 0x7fded47b2430> calc failed! Error: 'TBKManager' object has no attribute 'Subscriber', occurred on line 63 in file /home/mark/TnTeQAQ/workspace/dpg demo/TBK-Client/utils/node_utils/TBKNode.py
2024-12-20 14:51:28.389 | ERROR    | utils.ClientLogManager:log:49 - <utils.node_utils.TBKNode.Subscriber object at 0x7fded47b2430> calc failed! Error: 'TBKManager' object has no attribute 'Subscriber', occurred on line 63 in file /home/mark/TnTeQAQ/workspace/dpg demo/TBK-Client/utils/node_utils/TBKNode.py
2024-12-20 14:51:28.435 | ERROR    | utils.ClientLogManager:log:49 - <utils.node_utils.TBKNode.Subscriber object at 0x7fded47b2430> calc failed! Error: 'TBKManager' object has no attribute 'Subscriber', occurred on line 63 in file /home/mark/TnTeQAQ/workspace/dpg demo/TBK-Client/utils/node_utils/TBKNode.py
2024-12-20 14:51:28.485 | ERROR    | utils.ClientLogManager:log:49 - <utils.node_utils.TBKNode.Subscriber object at 0x7fded47b2430> calc failed! Error: 'TBKManager' object has no attribute 'Subscriber', occurred on line 63 in file /home/mark/TnTeQAQ/workspace/dpg demo/TBK-Client/utils/node_utils/TBKNode.py
2024-12-20 14:51:28.489 | ERROR    | utils.ClientLogManager:log:49 - <utils.node_utils.TBKNode.Subscriber object at 0x7fded47b2430> calc failed! Error: 'TBKManager' object has no attribute 'Subscriber', occurred on line 63 in file /home/mark/TnTeQAQ/workspace/dpg demo/TBK-Client/utils/node_utils/TBKNode.py
2024-12-20 14:51:28.505 | ERROR    | utils.ClientLogManager:log:49 - <utils.node_utils.TBKNode.Subscriber object at 0x7fded47b2430> calc failed! Error: 'TBKManager' object has no attribute 'Subscriber', occurred on line 63 in file /home/mark/TnTeQAQ/workspace/dpg demo/TBK-Client/utils/node_utils/TBKNode.py
2024-12-20 14:51:28.522 | ERROR    | utils.ClientLogManager:log:49 - <utils.node_utils.TBKNode.Subscriber object at 0x7fded47b2430> calc failed! Error: 'TBKManager' object has no attribute 'Subscriber', occurred on line 63 in file /home/mark/TnTeQAQ/workspace/dpg demo/TBK-Client/utils/node_utils/TBKNode.py
2024-12-20 14:51:28.539 | ERROR    | utils.ClientLogManager:log:49 - <utils.node_utils.TBKNode.Subscriber object at 0x7fded47b2430> calc failed! Error: 'TBKManager' object has no attribute 'Subscriber', occurred on line 63 in file /home/mark/TnTeQAQ/workspace/dpg demo/TBK-Client/utils/node_utils/TBKNode.py
2024-12-20 14:51:28.555 | ERROR    | utils.ClientLogManager:log:49 - <utils.node_utils.TBKNode.Subscriber object at 0x7fded47b2430> calc failed! Error: 'TBKManager' object has no attribute 'Subscriber', occurred on line 63 in file /home/mark/TnTeQAQ/workspace/dpg demo/TBK-Client/utils/node_utils/TBKNode.py
2024-12-20 14:51:28.572 | ERROR    | utils.ClientLogManager:log:49 - <utils.node_utils.TBKNode.Subscriber object at 0x7fded47b2430> calc failed! Error: 'TBKManager' object has no attribute 'Subscriber', occurred on line 63 in file /home/mark/TnTeQAQ/workspace/dpg demo/TBK-Client/utils/node_utils/TBKNode.py
2024-12-20 14:51:28.589 | ERROR    | utils.ClientLogManager:log:49 - <utils.node_utils.TBKNode.Subscriber object at 0x7fded47b2430> calc failed! Error: 'TBKManager' object has no attribute 'Subscriber', occurred on line 63 in file /home/mark/TnTeQAQ/workspace/dpg demo/TBK-Client/utils/node_utils/TBKNode.py
2024-12-20 14:51:28.606 | ERROR    | utils.ClientLogManager:log:49 - <utils.node_utils.TBKNode.Subscriber object at 0x7fded47b2430> calc failed! Error: 'TBKManager' object has no attribute 'Subscriber', occurred on line 63 in file /home/mark/TnTeQAQ/workspace/dpg demo/TBK-Client/utils/node_utils/TBKNode.py
2024-12-20 14:51:28.655 | ERROR    | utils.ClientLogManager:log:49 - <utils.node_utils.TBKNode.Subscriber object at 0x7fded47b2430> calc failed! Error: 'TBKManager' object has no attribute 'Subscriber', occurred on line 63 in file /home/mark/TnTeQAQ/workspace/dpg demo/TBK-Client/utils/node_utils/TBKNode.py
2024-12-20 14:51:28.700 | ERROR    | utils.ClientLogManager:log:49 - <utils.node_utils.TBKNode.Subscriber object at 0x7fded47b2430> calc failed! Error: 'TBKManager' object has no attribute 'Subscriber', occurred on line 63 in file /home/mark/TnTeQAQ/workspace/dpg demo/TBK-Client/utils/node_utils/TBKNode.py
2024-12-20 14:51:28.706 | ERROR    | utils.ClientLogManager:log:49 - <utils.node_utils.TBKNode.Subscriber object at 0x7fded47b2430> calc failed! Error: 'TBKManager' object has no attribute 'Subscriber', occurred on line 63 in file /home/mark/TnTeQAQ/workspace/dpg demo/TBK-Client/utils/node_utils/TBKNode.py
2024-12-20 14:51:28.722 | ERROR    | utils.ClientLogManager:log:49 - <utils.node_utils.TBKNode.Subscriber object at 0x7fded47b2430> calc failed! Error: 'TBKManager' object has no attribute 'Subscriber', occurred on line 63 in file /home/mark/TnTeQAQ/workspace/dpg demo/TBK-Client/utils/node_utils/TBKNode.py
2024-12-20 14:51:28.739 | ERROR    | utils.ClientLogManager:log:49 - <utils.node_utils.TBKNode.Subscriber object at 0x7fded47b2430> calc failed! Error: 'TBKManager' object has no attribute 'Subscriber', occurred on line 63 in file /home/mark/TnTeQAQ/workspace/dpg demo/TBK-Client/utils/node_utils/TBKNode.py
2024-12-20 14:51:28.756 | ERROR    | utils.ClientLogManager:log:49 - <utils.node_utils.TBKNode.Subscriber object at 0x7fded47b2430> calc failed! Error: 'TBKManager' object has no attribute 'Subscriber', occurred on line 63 in file /home/mark/TnTeQAQ/workspace/dpg demo/TBK-Client/utils/node_utils/TBKNode.py
2024-12-20 14:51:28.772 | ERROR    | utils.ClientLogManager:log:49 - <utils.node_utils.TBKNode.Subscriber object at 0x7fded47b2430> calc failed! Error: 'TBKManager' object has no attribute 'Subscriber', occurred on line 63 in file /home/mark/TnTeQAQ/workspace/dpg demo/TBK-Client/utils/node_utils/TBKNode.py
2024-12-20 14:51:28.789 | ERROR    | utils.ClientLogManager:log:49 - <utils.node_utils.TBKNode.Subscriber object at 0x7fded47b2430> calc failed! Error: 'TBKManager' object has no attribute 'Subscriber', occurred on line 63 in file /home/mark/TnTeQAQ/workspace/dpg demo/TBK-Client/utils/node_utils/TBKNode.py
2024-12-20 14:51:28.806 | ERROR    | utils.ClientLogManager:log:49 - <utils.node_utils.TBKNode.Subscriber object at 0x7fded47b2430> calc failed! Error: 'TBKManager' object has no attribute 'Subscriber', occurred on line 63 in file /home/mark/TnTeQAQ/workspace/dpg demo/TBK-Client/utils/node_utils/TBKNode.py
2024-12-20 14:51:28.824 | ERROR    | utils.ClientLogManager:log:49 - <utils.node_utils.TBKNode.Subscriber object at 0x7fded47b2430> calc failed! Error: 'TBKManager' object has no attribute 'Subscriber', occurred on line 63 in file /home/mark/TnTeQAQ/workspace/dpg demo/TBK-Client/utils/node_utils/TBKNode.py
2024-12-20 14:51:28.866 | ERROR    | utils.ClientLogManager:log:49 - <utils.node_utils.TBKNode.Subscriber object at 0x7fded47b2430> calc failed! Error: 'TBKManager' object has no attribute 'Subscriber', occurred on line 63 in file /home/mark/TnTeQAQ/workspace/dpg demo/TBK-Client/utils/node_utils/TBKNode.py
2024-12-20 14:51:28.907 | ERROR    | utils.ClientLogManager:log:49 - <utils.node_utils.TBKNode.Subscriber object at 0x7fded47b2430> calc failed! Error: 'TBKManager' object has no attribute 'Subscriber', occurred on line 63 in file /home/mark/TnTeQAQ/workspace/dpg demo/TBK-Client/utils/node_utils/TBKNode.py
2024-12-20 14:51:28.922 | ERROR    | utils.ClientLogManager:log:49 - <utils.node_utils.TBKNode.Subscriber object at 0x7fded47b2430> calc failed! Error: 'TBKManager' object has no attribute 'Subscriber', occurred on line 63 in file /home/mark/TnTeQAQ/workspace/dpg demo/TBK-Client/utils/node_utils/TBKNode.py
2024-12-20 14:51:28.939 | ERROR    | utils.ClientLogManager:log:49 - <utils.node_utils.TBKNode.Subscriber object at 0x7fded47b2430> calc failed! Error: 'TBKManager' object has no attribute 'Subscriber', occurred on line 63 in file /home/mark/TnTeQAQ/workspace/dpg demo/TBK-Client/utils/node_utils/TBKNode.py
2024-12-20 14:51:28.956 | ERROR    | utils.ClientLogManager:log:49 - <utils.node_utils.TBKNode.Subscriber object at 0x7fded47b2430> calc failed! Error: 'TBKManager' object has no attribute 'Subscriber', occurred on line 63 in file /home/mark/TnTeQAQ/workspace/dpg demo/TBK-Client/utils/node_utils/TBKNode.py
2024-12-20 14:51:28.973 | ERROR    | utils.ClientLogManager:log:49 - <utils.node_utils.TBKNode.Subscriber object at 0x7fded47b2430> calc failed! Error: 'TBKManager' object has no attribute 'Subscriber', occurred on line 63 in file /home/mark/TnTeQAQ/workspace/dpg demo/TBK-Client/utils/node_utils/TBKNode.py
2024-12-20 14:51:28.989 | ERROR    | utils.ClientLogManager:log:49 - <utils.node_utils.TBKNode.Subscriber object at 0x7fded47b2430> calc failed! Error: 'TBKManager' object has no attribute 'Subscriber', occurred on line 63 in file /home/mark/TnTeQAQ/workspace/dpg demo/TBK-Client/utils/node_utils/TBKNode.py
2024-12-20 14:51:29.006 | ERROR    | utils.ClientLogManager:log:49 - <utils.node_utils.TBKNode.Subscriber object at 0x7fded47b2430> calc failed! Error: 'TBKManager' object has no attribute 'Subscriber', occurred on line 63 in file /home/mark/TnTeQAQ/workspace/dpg demo/TBK-Client/utils/node_utils/TBKNode.py
2024-12-20 14:51:29.024 | ERROR    | utils.ClientLogManager:log:49 - <utils.node_utils.TBKNode.Subscriber object at 0x7fded47b2430> calc failed! Error: 'TBKManager' object has no attribute 'Subscriber', occurred on line 63 in file /home/mark/TnTeQAQ/workspace/dpg demo/TBK-Client/utils/node_utils/TBKNode.py
2024-12-20 14:51:29.079 | ERROR    | utils.ClientLogManager:log:49 - <utils.node_utils.TBKNode.Subscriber object at 0x7fded47b2430> calc failed! Error: 'TBKManager' object has no attribute 'Subscriber', occurred on line 63 in file /home/mark/TnTeQAQ/workspace/dpg demo/TBK-Client/utils/node_utils/TBKNode.py
2024-12-20 14:51:29.116 | ERROR    | utils.ClientLogManager:log:49 - <utils.node_utils.TBKNode.Subscriber object at 0x7fded47b2430> calc failed! Error: 'TBKManager' object has no attribute 'Subscriber', occurred on line 63 in file /home/mark/TnTeQAQ/workspace/dpg demo/TBK-Client/utils/node_utils/TBKNode.py
2024-12-20 14:51:29.123 | ERROR    | utils.ClientLogManager:log:49 - <utils.node_utils.TBKNode.Subscriber object at 0x7fded47b2430> calc failed! Error: 'TBKManager' object has no attribute 'Subscriber', occurred on line 63 in file /home/mark/TnTeQAQ/workspace/dpg demo/TBK-Client/utils/node_utils/TBKNode.py
2024-12-20 14:51:29.139 | ERROR    | utils.ClientLogManager:log:49 - <utils.node_utils.TBKNode.Subscriber object at 0x7fded47b2430> calc failed! Error: 'TBKManager' object has no attribute 'Subscriber', occurred on line 63 in file /home/mark/TnTeQAQ/workspace/dpg demo/TBK-Client/utils/node_utils/TBKNode.py
2024-12-20 14:51:29.156 | ERROR    | utils.ClientLogManager:log:49 - <utils.node_utils.TBKNode.Subscriber object at 0x7fded47b2430> calc failed! Error: 'TBKManager' object has no attribute 'Subscriber', occurred on line 63 in file /home/mark/TnTeQAQ/workspace/dpg demo/TBK-Client/utils/node_utils/TBKNode.py
2024-12-20 14:51:29.173 | ERROR    | utils.ClientLogManager:log:49 - <utils.node_utils.TBKNode.Subscriber object at 0x7fded47b2430> calc failed! Error: 'TBKManager' object has no attribute 'Subscriber', occurred on line 63 in file /home/mark/TnTeQAQ/workspace/dpg demo/TBK-Client/utils/node_utils/TBKNode.py
2024-12-20 14:51:29.190 | ERROR    | utils.ClientLogManager:log:49 - <utils.node_utils.TBKNode.Subscriber object at 0x7fded47b2430> calc failed! Error: 'TBKManager' object has no attribute 'Subscriber', occurred on line 63 in file /home/mark/TnTeQAQ/workspace/dpg demo/TBK-Client/utils/node_utils/TBKNode.py
2024-12-20 14:51:29.206 | ERROR    | utils.ClientLogManager:log:49 - <utils.node_utils.TBKNode.Subscriber object at 0x7fded47b2430> calc failed! Error: 'TBKManager' object has no attribute 'Subscriber', occurred on line 63 in file /home/mark/TnTeQAQ/workspace/dpg demo/TBK-Client/utils/node_utils/TBKNode.py
2024-12-20 14:51:29.223 | ERROR    | utils.ClientLogManager:log:49 - <utils.node_utils.TBKNode.Subscriber object at 0x7fded47b2430> calc failed! Error: 'TBKManager' object has no attribute 'Subscriber', occurred on line 63 in file /home/mark/TnTeQAQ/workspace/dpg demo/TBK-Client/utils/node_utils/TBKNode.py
2024-12-20 14:51:29.240 | ERROR    | utils.ClientLogManager:log:49 - <utils.node_utils.TBKNode.Subscriber object at 0x7fded47b2430> calc failed! Error: 'TBKManager' object has no attribute 'Subscriber', occurred on line 63 in file /home/mark/TnTeQAQ/workspace/dpg demo/TBK-Client/utils/node_utils/TBKNode.py
2024-12-20 14:51:29.298 | ERROR    | utils.ClientLogManager:log:49 - <utils.node_utils.TBKNode.Subscriber object at 0x7fded47b2430> calc failed! Error: 'TBKManager' object has no attribute 'Subscriber', occurred on line 63 in file /home/mark/TnTeQAQ/workspace/dpg demo/TBK-Client/utils/node_utils/TBKNode.py
2024-12-20 14:51:29.338 | ERROR    | utils.ClientLogManager:log:49 - <utils.node_utils.TBKNode.Subscriber object at 0x7fded47b2430> calc failed! Error: 'TBKManager' object has no attribute 'Subscriber', occurred on line 63 in file /home/mark/TnTeQAQ/workspace/dpg demo/TBK-Client/utils/node_utils/TBKNode.py
2024-12-20 14:51:29.340 | ERROR    | utils.ClientLogManager:log:49 - <utils.node_utils.TBKNode.Subscriber object at 0x7fded47b2430> calc failed! Error: 'TBKManager' object has no attribute 'Subscriber', occurred on line 63 in file /home/mark/TnTeQAQ/workspace/dpg demo/TBK-Client/utils/node_utils/TBKNode.py
2024-12-20 14:51:29.356 | ERROR    | utils.ClientLogManager:log:49 - <utils.node_utils.TBKNode.Subscriber object at 0x7fded47b2430> calc failed! Error: 'TBKManager' object has no attribute 'Subscriber', occurred on line 63 in file /home/mark/TnTeQAQ/workspace/dpg demo/TBK-Client/utils/node_utils/TBKNode.py
2024-12-20 14:51:29.373 | ERROR    | utils.ClientLogManager:log:49 - <utils.node_utils.TBKNode.Subscriber object at 0x7fded47b2430> calc failed! Error: 'TBKManager' object has no attribute 'Subscriber', occurred on line 63 in file /home/mark/TnTeQAQ/workspace/dpg demo/TBK-Client/utils/node_utils/TBKNode.py
2024-12-20 14:51:29.390 | ERROR    | utils.ClientLogManager:log:49 - <utils.node_utils.TBKNode.Subscriber object at 0x7fded47b2430> calc failed! Error: 'TBKManager' object has no attribute 'Subscriber', occurred on line 63 in file /home/mark/TnTeQAQ/workspace/dpg demo/TBK-Client/utils/node_utils/TBKNode.py
2024-12-20 14:51:29.406 | ERROR    | utils.ClientLogManager:log:49 - <utils.node_utils.TBKNode.Subscriber object at 0x7fded47b2430> calc failed! Error: 'TBKManager' object has no attribute 'Subscriber', occurred on line 63 in file /home/mark/TnTeQAQ/workspace/dpg demo/TBK-Client/utils/node_utils/TBKNode.py
2024-12-20 14:51:29.423 | ERROR    | utils.ClientLogManager:log:49 - <utils.node_utils.TBKNode.Subscriber object at 0x7fded47b2430> calc failed! Error: 'TBKManager' object has no attribute 'Subscriber', occurred on line 63 in file /home/mark/TnTeQAQ/workspace/dpg demo/TBK-Client/utils/node_utils/TBKNode.py
2024-12-20 14:51:29.439 | ERROR    | utils.ClientLogManager:log:49 - <utils.node_utils.TBKNode.Subscriber object at 0x7fded47b2430> calc failed! Error: 'TBKManager' object has no attribute 'Subscriber', occurred on line 63 in file /home/mark/TnTeQAQ/workspace/dpg demo/TBK-Client/utils/node_utils/TBKNode.py
2024-12-20 14:51:29.457 | ERROR    | utils.ClientLogManager:log:49 - <utils.node_utils.TBKNode.Subscriber object at 0x7fded47b2430> calc failed! Error: 'TBKManager' object has no attribute 'Subscriber', occurred on line 63 in file /home/mark/TnTeQAQ/workspace/dpg demo/TBK-Client/utils/node_utils/TBKNode.py
2024-12-20 14:51:29.474 | ERROR    | utils.ClientLogManager:log:49 - <utils.node_utils.TBKNode.Subscriber object at 0x7fded47b2430> calc failed! Error: 'TBKManager' object has no attribute 'Subscriber', occurred on line 63 in file /home/mark/TnTeQAQ/workspace/dpg demo/TBK-Client/utils/node_utils/TBKNode.py
2024-12-20 14:51:29.529 | ERROR    | utils.ClientLogManager:log:49 - <utils.node_utils.TBKNode.Subscriber object at 0x7fded47b2430> calc failed! Error: 'TBKManager' object has no attribute 'Subscriber', occurred on line 63 in file /home/mark/TnTeQAQ/workspace/dpg demo/TBK-Client/utils/node_utils/TBKNode.py
2024-12-20 14:51:29.545 | ERROR    | utils.ClientLogManager:log:49 - <utils.node_utils.TBKNode.Subscriber object at 0x7fded47b2430> calc failed! Error: 'TBKManager' object has no attribute 'Subscriber', occurred on line 63 in file /home/mark/TnTeQAQ/workspace/dpg demo/TBK-Client/utils/node_utils/TBKNode.py
2024-12-20 14:51:29.557 | ERROR    | utils.ClientLogManager:log:49 - <utils.node_utils.TBKNode.Subscriber object at 0x7fded47b2430> calc failed! Error: 'TBKManager' object has no attribute 'Subscriber', occurred on line 63 in file /home/mark/TnTeQAQ/workspace/dpg demo/TBK-Client/utils/node_utils/TBKNode.py
2024-12-20 14:51:29.573 | ERROR    | utils.ClientLogManager:log:49 - <utils.node_utils.TBKNode.Subscriber object at 0x7fded47b2430> calc failed! Error: 'TBKManager' object has no attribute 'Subscriber', occurred on line 63 in file /home/mark/TnTeQAQ/workspace/dpg demo/TBK-Client/utils/node_utils/TBKNode.py
2024-12-20 14:51:29.590 | ERROR    | utils.ClientLogManager:log:49 - <utils.node_utils.TBKNode.Subscriber object at 0x7fded47b2430> calc failed! Error: 'TBKManager' object has no attribute 'Subscriber', occurred on line 63 in file /home/mark/TnTeQAQ/workspace/dpg demo/TBK-Client/utils/node_utils/TBKNode.py
2024-12-20 14:51:29.607 | ERROR    | utils.ClientLogManager:log:49 - <utils.node_utils.TBKNode.Subscriber object at 0x7fded47b2430> calc failed! Error: 'TBKManager' object has no attribute 'Subscriber', occurred on line 63 in file /home/mark/TnTeQAQ/workspace/dpg demo/TBK-Client/utils/node_utils/TBKNode.py
2024-12-20 14:51:29.623 | ERROR    | utils.ClientLogManager:log:49 - <utils.node_utils.TBKNode.Subscriber object at 0x7fded47b2430> calc failed! Error: 'TBKManager' object has no attribute 'Subscriber', occurred on line 63 in file /home/mark/TnTeQAQ/workspace/dpg demo/TBK-Client/utils/node_utils/TBKNode.py
2024-12-20 14:51:29.640 | ERROR    | utils.ClientLogManager:log:49 - <utils.node_utils.TBKNode.Subscriber object at 0x7fded47b2430> calc failed! Error: 'TBKManager' object has no attribute 'Subscriber', occurred on line 63 in file /home/mark/TnTeQAQ/workspace/dpg demo/TBK-Client/utils/node_utils/TBKNode.py
2024-12-20 14:51:29.657 | ERROR    | utils.ClientLogManager:log:49 - <utils.node_utils.TBKNode.Subscriber object at 0x7fded47b2430> calc failed! Error: 'TBKManager' object has no attribute 'Subscriber', occurred on line 63 in file /home/mark/TnTeQAQ/workspace/dpg demo/TBK-Client/utils/node_utils/TBKNode.py
2024-12-20 14:51:29.703 | ERROR    | utils.ClientLogManager:log:49 - <utils.node_utils.TBKNode.Subscriber object at 0x7fded47b2430> calc failed! Error: 'TBKManager' object has no attribute 'Subscriber', occurred on line 63 in file /home/mark/TnTeQAQ/workspace/dpg demo/TBK-Client/utils/node_utils/TBKNode.py
2024-12-20 14:51:29.708 | ERROR    | utils.ClientLogManager:log:49 - <utils.node_utils.TBKNode.Subscriber object at 0x7fded47b2430> calc failed! Error: 'TBKManager' object has no attribute 'Subscriber', occurred on line 63 in file /home/mark/TnTeQAQ/workspace/dpg demo/TBK-Client/utils/node_utils/TBKNode.py
2024-12-20 14:51:29.724 | ERROR    | utils.ClientLogManager:log:49 - <utils.node_utils.TBKNode.Subscriber object at 0x7fded47b2430> calc failed! Error: 'TBKManager' object has no attribute 'Subscriber', occurred on line 63 in file /home/mark/TnTeQAQ/workspace/dpg demo/TBK-Client/utils/node_utils/TBKNode.py
2024-12-20 14:51:29.740 | ERROR    | utils.ClientLogManager:log:49 - <utils.node_utils.TBKNode.Subscriber object at 0x7fded47b2430> calc failed! Error: 'TBKManager' object has no attribute 'Subscriber', occurred on line 63 in file /home/mark/TnTeQAQ/workspace/dpg demo/TBK-Client/utils/node_utils/TBKNode.py
2024-12-20 14:51:29.757 | ERROR    | utils.ClientLogManager:log:49 - <utils.node_utils.TBKNode.Subscriber object at 0x7fded47b2430> calc failed! Error: 'TBKManager' object has no attribute 'Subscriber', occurred on line 63 in file /home/mark/TnTeQAQ/workspace/dpg demo/TBK-Client/utils/node_utils/TBKNode.py
2024-12-20 14:51:29.773 | ERROR    | utils.ClientLogManager:log:49 - <utils.node_utils.TBKNode.Subscriber object at 0x7fded47b2430> calc failed! Error: 'TBKManager' object has no attribute 'Subscriber', occurred on line 63 in file /home/mark/TnTeQAQ/workspace/dpg demo/TBK-Client/utils/node_utils/TBKNode.py
2024-12-20 14:51:29.790 | ERROR    | utils.ClientLogManager:log:49 - <utils.node_utils.TBKNode.Subscriber object at 0x7fded47b2430> calc failed! Error: 'TBKManager' object has no attribute 'Subscriber', occurred on line 63 in file /home/mark/TnTeQAQ/workspace/dpg demo/TBK-Client/utils/node_utils/TBKNode.py
2024-12-20 14:51:29.807 | ERROR    | utils.ClientLogManager:log:49 - <utils.node_utils.TBKNode.Subscriber object at 0x7fded47b2430> calc failed! Error: 'TBKManager' object has no attribute 'Subscriber', occurred on line 63 in file /home/mark/TnTeQAQ/workspace/dpg demo/TBK-Client/utils/node_utils/TBKNode.py
2024-12-20 14:51:29.823 | ERROR    | utils.ClientLogManager:log:49 - <utils.node_utils.TBKNode.Subscriber object at 0x7fded47b2430> calc failed! Error: 'TBKManager' object has no attribute 'Subscriber', occurred on line 63 in file /home/mark/TnTeQAQ/workspace/dpg demo/TBK-Client/utils/node_utils/TBKNode.py
2024-12-20 14:51:29.840 | ERROR    | utils.ClientLogManager:log:49 - <utils.node_utils.TBKNode.Subscriber object at 0x7fded47b2430> calc failed! Error: 'TBKManager' object has no attribute 'Subscriber', occurred on line 63 in file /home/mark/TnTeQAQ/workspace/dpg demo/TBK-Client/utils/node_utils/TBKNode.py
2024-12-20 14:51:29.856 | ERROR    | utils.ClientLogManager:log:49 - <utils.node_utils.TBKNode.Subscriber object at 0x7fded47b2430> calc failed! Error: 'TBKManager' object has no attribute 'Subscriber', occurred on line 63 in file /home/mark/TnTeQAQ/workspace/dpg demo/TBK-Client/utils/node_utils/TBKNode.py
2024-12-20 14:51:29.874 | ERROR    | utils.ClientLogManager:log:49 - <utils.node_utils.TBKNode.Subscriber object at 0x7fded47b2430> calc failed! Error: 'TBKManager' object has no attribute 'Subscriber', occurred on line 63 in file /home/mark/TnTeQAQ/workspace/dpg demo/TBK-Client/utils/node_utils/TBKNode.py
2024-12-20 14:51:29.910 | ERROR    | utils.ClientLogManager:log:49 - <utils.node_utils.TBKNode.Subscriber object at 0x7fded47b2430> calc failed! Error: 'TBKManager' object has no attribute 'Subscriber', occurred on line 63 in file /home/mark/TnTeQAQ/workspace/dpg demo/TBK-Client/utils/node_utils/TBKNode.py
2024-12-20 14:51:29.970 | ERROR    | utils.ClientLogManager:log:49 - <utils.node_utils.TBKNode.Subscriber object at 0x7fded47b2430> calc failed! Error: 'TBKManager' object has no attribute 'Subscriber', occurred on line 63 in file /home/mark/TnTeQAQ/workspace/dpg demo/TBK-Client/utils/node_utils/TBKNode.py
2024-12-20 14:51:29.978 | ERROR    | utils.ClientLogManager:log:49 - <utils.node_utils.TBKNode.Subscriber object at 0x7fded47b2430> calc failed! Error: 'TBKManager' object has no attribute 'Subscriber', occurred on line 63 in file /home/mark/TnTeQAQ/workspace/dpg demo/TBK-Client/utils/node_utils/TBKNode.py
2024-12-20 14:51:29.990 | ERROR    | utils.ClientLogManager:log:49 - <utils.node_utils.TBKNode.Subscriber object at 0x7fded47b2430> calc failed! Error: 'TBKManager' object has no attribute 'Subscriber', occurred on line 63 in file /home/mark/TnTeQAQ/workspace/dpg demo/TBK-Client/utils/node_utils/TBKNode.py
2024-12-20 14:51:30.007 | ERROR    | utils.ClientLogManager:log:49 - <utils.node_utils.TBKNode.Subscriber object at 0x7fded47b2430> calc failed! Error: 'TBKManager' object has no attribute 'Subscriber', occurred on line 63 in file /home/mark/TnTeQAQ/workspace/dpg demo/TBK-Client/utils/node_utils/TBKNode.py
2024-12-20 14:51:30.023 | ERROR    | utils.ClientLogManager:log:49 - <utils.node_utils.TBKNode.Subscriber object at 0x7fded47b2430> calc failed! Error: 'TBKManager' object has no attribute 'Subscriber', occurred on line 63 in file /home/mark/TnTeQAQ/workspace/dpg demo/TBK-Client/utils/node_utils/TBKNode.py
2024-12-20 14:51:30.040 | ERROR    | utils.ClientLogManager:log:49 - <utils.node_utils.TBKNode.Subscriber object at 0x7fded47b2430> calc failed! Error: 'TBKManager' object has no attribute 'Subscriber', occurred on line 63 in file /home/mark/TnTeQAQ/workspace/dpg demo/TBK-Client/utils/node_utils/TBKNode.py
2024-12-20 14:51:30.057 | ERROR    | utils.ClientLogManager:log:49 - <utils.node_utils.TBKNode.Subscriber object at 0x7fded47b2430> calc failed! Error: 'TBKManager' object has no attribute 'Subscriber', occurred on line 63 in file /home/mark/TnTeQAQ/workspace/dpg demo/TBK-Client/utils/node_utils/TBKNode.py
2024-12-20 14:51:30.074 | ERROR    | utils.ClientLogManager:log:49 - <utils.node_utils.TBKNode.Subscriber object at 0x7fded47b2430> calc failed! Error: 'TBKManager' object has no attribute 'Subscriber', occurred on line 63 in file /home/mark/TnTeQAQ/workspace/dpg demo/TBK-Client/utils/node_utils/TBKNode.py
2024-12-20 14:51:30.119 | ERROR    | utils.ClientLogManager:log:49 - <utils.node_utils.TBKNode.Subscriber object at 0x7fded47b2430> calc failed! Error: 'TBKManager' object has no attribute 'Subscriber', occurred on line 63 in file /home/mark/TnTeQAQ/workspace/dpg demo/TBK-Client/utils/node_utils/TBKNode.py
2024-12-20 14:51:30.164 | ERROR    | utils.ClientLogManager:log:49 - <utils.node_utils.TBKNode.Subscriber object at 0x7fded47b2430> calc failed! Error: 'TBKManager' object has no attribute 'Subscriber', occurred on line 63 in file /home/mark/TnTeQAQ/workspace/dpg demo/TBK-Client/utils/node_utils/TBKNode.py
2024-12-20 14:51:30.173 | ERROR    | utils.ClientLogManager:log:49 - <utils.node_utils.TBKNode.Subscriber object at 0x7fded47b2430> calc failed! Error: 'TBKManager' object has no attribute 'Subscriber', occurred on line 63 in file /home/mark/TnTeQAQ/workspace/dpg demo/TBK-Client/utils/node_utils/TBKNode.py
2024-12-20 14:51:30.190 | ERROR    | utils.ClientLogManager:log:49 - <utils.node_utils.TBKNode.Subscriber object at 0x7fded47b2430> calc failed! Error: 'TBKManager' object has no attribute 'Subscriber', occurred on line 63 in file /home/mark/TnTeQAQ/workspace/dpg demo/TBK-Client/utils/node_utils/TBKNode.py
2024-12-20 14:51:30.207 | ERROR    | utils.ClientLogManager:log:49 - <utils.node_utils.TBKNode.Subscriber object at 0x7fded47b2430> calc failed! Error: 'TBKManager' object has no attribute 'Subscriber', occurred on line 63 in file /home/mark/TnTeQAQ/workspace/dpg demo/TBK-Client/utils/node_utils/TBKNode.py
2024-12-20 14:51:30.223 | ERROR    | utils.ClientLogManager:log:49 - <utils.node_utils.TBKNode.Subscriber object at 0x7fded47b2430> calc failed! Error: 'TBKManager' object has no attribute 'Subscriber', occurred on line 63 in file /home/mark/TnTeQAQ/workspace/dpg demo/TBK-Client/utils/node_utils/TBKNode.py
2024-12-20 14:51:30.240 | ERROR    | utils.ClientLogManager:log:49 - <utils.node_utils.TBKNode.Subscriber object at 0x7fded47b2430> calc failed! Error: 'TBKManager' object has no attribute 'Subscriber', occurred on line 63 in file /home/mark/TnTeQAQ/workspace/dpg demo/TBK-Client/utils/node_utils/TBKNode.py
2024-12-20 14:51:30.257 | ERROR    | utils.ClientLogManager:log:49 - <utils.node_utils.TBKNode.Subscriber object at 0x7fded47b2430> calc failed! Error: 'TBKManager' object has no attribute 'Subscriber', occurred on line 63 in file /home/mark/TnTeQAQ/workspace/dpg demo/TBK-Client/utils/node_utils/TBKNode.py
2024-12-20 14:51:30.274 | ERROR    | utils.ClientLogManager:log:49 - <utils.node_utils.TBKNode.Subscriber object at 0x7fded47b2430> calc failed! Error: 'TBKManager' object has no attribute 'Subscriber', occurred on line 63 in file /home/mark/TnTeQAQ/workspace/dpg demo/TBK-Client/utils/node_utils/TBKNode.py
2024-12-20 14:51:30.291 | ERROR    | utils.ClientLogManager:log:49 - <utils.node_utils.TBKNode.Subscriber object at 0x7fded47b2430> calc failed! Error: 'TBKManager' object has no attribute 'Subscriber', occurred on line 63 in file /home/mark/TnTeQAQ/workspace/dpg demo/TBK-Client/utils/node_utils/TBKNode.py
2024-12-20 14:51:30.340 | ERROR    | utils.ClientLogManager:log:49 - <utils.node_utils.TBKNode.Subscriber object at 0x7fded47b2430> calc failed! Error: 'TBKManager' object has no attribute 'Subscriber', occurred on line 63 in file /home/mark/TnTeQAQ/workspace/dpg demo/TBK-Client/utils/node_utils/TBKNode.py
2024-12-20 14:51:30.385 | ERROR    | utils.ClientLogManager:log:49 - <utils.node_utils.TBKNode.Subscriber object at 0x7fded47b2430> calc failed! Error: 'TBKManager' object has no attribute 'Subscriber', occurred on line 63 in file /home/mark/TnTeQAQ/workspace/dpg demo/TBK-Client/utils/node_utils/TBKNode.py
2024-12-20 14:51:30.390 | ERROR    | utils.ClientLogManager:log:49 - <utils.node_utils.TBKNode.Subscriber object at 0x7fded47b2430> calc failed! Error: 'TBKManager' object has no attribute 'Subscriber', occurred on line 63 in file /home/mark/TnTeQAQ/workspace/dpg demo/TBK-Client/utils/node_utils/TBKNode.py
2024-12-20 14:51:30.407 | ERROR    | utils.ClientLogManager:log:49 - <utils.node_utils.TBKNode.Subscriber object at 0x7fded47b2430> calc failed! Error: 'TBKManager' object has no attribute 'Subscriber', occurred on line 63 in file /home/mark/TnTeQAQ/workspace/dpg demo/TBK-Client/utils/node_utils/TBKNode.py
2024-12-20 14:51:30.424 | ERROR    | utils.ClientLogManager:log:49 - <utils.node_utils.TBKNode.Subscriber object at 0x7fded47b2430> calc failed! Error: 'TBKManager' object has no attribute 'Subscriber', occurred on line 63 in file /home/mark/TnTeQAQ/workspace/dpg demo/TBK-Client/utils/node_utils/TBKNode.py
2024-12-20 14:51:30.440 | ERROR    | utils.ClientLogManager:log:49 - <utils.node_utils.TBKNode.Subscriber object at 0x7fded47b2430> calc failed! Error: 'TBKManager' object has no attribute 'Subscriber', occurred on line 63 in file /home/mark/TnTeQAQ/workspace/dpg demo/TBK-Client/utils/node_utils/TBKNode.py
2024-12-20 14:51:30.457 | ERROR    | utils.ClientLogManager:log:49 - <utils.node_utils.TBKNode.Subscriber object at 0x7fded47b2430> calc failed! Error: 'TBKManager' object has no attribute 'Subscriber', occurred on line 63 in file /home/mark/TnTeQAQ/workspace/dpg demo/TBK-Client/utils/node_utils/TBKNode.py
2024-12-20 14:51:30.474 | ERROR    | utils.ClientLogManager:log:49 - <utils.node_utils.TBKNode.Subscriber object at 0x7fded47b2430> calc failed! Error: 'TBKManager' object has no attribute 'Subscriber', occurred on line 63 in file /home/mark/TnTeQAQ/workspace/dpg demo/TBK-Client/utils/node_utils/TBKNode.py
2024-12-20 14:51:30.490 | ERROR    | utils.ClientLogManager:log:49 - <utils.node_utils.TBKNode.Subscriber object at 0x7fded47b2430> calc failed! Error: 'TBKManager' object has no attribute 'Subscriber', occurred on line 63 in file /home/mark/TnTeQAQ/workspace/dpg demo/TBK-Client/utils/node_utils/TBKNode.py
2024-12-20 14:51:30.508 | ERROR    | utils.ClientLogManager:log:49 - <utils.node_utils.TBKNode.Subscriber object at 0x7fded47b2430> calc failed! Error: 'TBKManager' object has no attribute 'Subscriber', occurred on line 63 in file /home/mark/TnTeQAQ/workspace/dpg demo/TBK-Client/utils/node_utils/TBKNode.py
2024-12-20 14:51:30.563 | ERROR    | utils.ClientLogManager:log:49 - <utils.node_utils.TBKNode.Subscriber object at 0x7fded47b2430> calc failed! Error: 'TBKManager' object has no attribute 'Subscriber', occurred on line 63 in file /home/mark/TnTeQAQ/workspace/dpg demo/TBK-Client/utils/node_utils/TBKNode.py
2024-12-20 14:51:30.605 | ERROR    | utils.ClientLogManager:log:49 - <utils.node_utils.TBKNode.Subscriber object at 0x7fded47b2430> calc failed! Error: 'TBKManager' object has no attribute 'Subscriber', occurred on line 63 in file /home/mark/TnTeQAQ/workspace/dpg demo/TBK-Client/utils/node_utils/TBKNode.py
2024-12-20 14:51:30.607 | ERROR    | utils.ClientLogManager:log:49 - <utils.node_utils.TBKNode.Subscriber object at 0x7fded47b2430> calc failed! Error: 'TBKManager' object has no attribute 'Subscriber', occurred on line 63 in file /home/mark/TnTeQAQ/workspace/dpg demo/TBK-Client/utils/node_utils/TBKNode.py
2024-12-20 14:51:30.624 | ERROR    | utils.ClientLogManager:log:49 - <utils.node_utils.TBKNode.Subscriber object at 0x7fded47b2430> calc failed! Error: 'TBKManager' object has no attribute 'Subscriber', occurred on line 63 in file /home/mark/TnTeQAQ/workspace/dpg demo/TBK-Client/utils/node_utils/TBKNode.py
2024-12-20 14:51:30.641 | ERROR    | utils.ClientLogManager:log:49 - <utils.node_utils.TBKNode.Subscriber object at 0x7fded47b2430> calc failed! Error: 'TBKManager' object has no attribute 'Subscriber', occurred on line 63 in file /home/mark/TnTeQAQ/workspace/dpg demo/TBK-Client/utils/node_utils/TBKNode.py
2024-12-20 14:51:30.657 | ERROR    | utils.ClientLogManager:log:49 - <utils.node_utils.TBKNode.Subscriber object at 0x7fded47b2430> calc failed! Error: 'TBKManager' object has no attribute 'Subscriber', occurred on line 63 in file /home/mark/TnTeQAQ/workspace/dpg demo/TBK-Client/utils/node_utils/TBKNode.py
2024-12-20 14:51:30.674 | ERROR    | utils.ClientLogManager:log:49 - <utils.node_utils.TBKNode.Subscriber object at 0x7fded47b2430> calc failed! Error: 'TBKManager' object has no attribute 'Subscriber', occurred on line 63 in file /home/mark/TnTeQAQ/workspace/dpg demo/TBK-Client/utils/node_utils/TBKNode.py
2024-12-20 14:51:30.691 | ERROR    | utils.ClientLogManager:log:49 - <utils.node_utils.TBKNode.Subscriber object at 0x7fded47b2430> calc failed! Error: 'TBKManager' object has no attribute 'Subscriber', occurred on line 63 in file /home/mark/TnTeQAQ/workspace/dpg demo/TBK-Client/utils/node_utils/TBKNode.py
2024-12-20 14:51:30.707 | ERROR    | utils.ClientLogManager:log:49 - <utils.node_utils.TBKNode.Subscriber object at 0x7fded47b2430> calc failed! Error: 'TBKManager' object has no attribute 'Subscriber', occurred on line 63 in file /home/mark/TnTeQAQ/workspace/dpg demo/TBK-Client/utils/node_utils/TBKNode.py
2024-12-20 14:51:30.725 | ERROR    | utils.ClientLogManager:log:49 - <utils.node_utils.TBKNode.Subscriber object at 0x7fded47b2430> calc failed! Error: 'TBKManager' object has no attribute 'Subscriber', occurred on line 63 in file /home/mark/TnTeQAQ/workspace/dpg demo/TBK-Client/utils/node_utils/TBKNode.py
2024-12-20 14:51:30.742 | ERROR    | utils.ClientLogManager:log:49 - <utils.node_utils.TBKNode.Subscriber object at 0x7fded47b2430> calc failed! Error: 'TBKManager' object has no attribute 'Subscriber', occurred on line 63 in file /home/mark/TnTeQAQ/workspace/dpg demo/TBK-Client/utils/node_utils/TBKNode.py
2024-12-20 14:51:30.800 | ERROR    | utils.ClientLogManager:log:49 - <utils.node_utils.TBKNode.Subscriber object at 0x7fded47b2430> calc failed! Error: 'TBKManager' object has no attribute 'Subscriber', occurred on line 63 in file /home/mark/TnTeQAQ/workspace/dpg demo/TBK-Client/utils/node_utils/TBKNode.py
2024-12-20 14:51:30.822 | ERROR    | utils.ClientLogManager:log:49 - <utils.node_utils.TBKNode.Subscriber object at 0x7fded47b2430> calc failed! Error: 'TBKManager' object has no attribute 'Subscriber', occurred on line 63 in file /home/mark/TnTeQAQ/workspace/dpg demo/TBK-Client/utils/node_utils/TBKNode.py
2024-12-20 14:51:30.824 | ERROR    | utils.ClientLogManager:log:49 - <utils.node_utils.TBKNode.Subscriber object at 0x7fded47b2430> calc failed! Error: 'TBKManager' object has no attribute 'Subscriber', occurred on line 63 in file /home/mark/TnTeQAQ/workspace/dpg demo/TBK-Client/utils/node_utils/TBKNode.py
2024-12-20 14:51:30.841 | ERROR    | utils.ClientLogManager:log:49 - <utils.node_utils.TBKNode.Subscriber object at 0x7fded47b2430> calc failed! Error: 'TBKManager' object has no attribute 'Subscriber', occurred on line 63 in file /home/mark/TnTeQAQ/workspace/dpg demo/TBK-Client/utils/node_utils/TBKNode.py
2024-12-20 14:51:30.857 | ERROR    | utils.ClientLogManager:log:49 - <utils.node_utils.TBKNode.Subscriber object at 0x7fded47b2430> calc failed! Error: 'TBKManager' object has no attribute 'Subscriber', occurred on line 63 in file /home/mark/TnTeQAQ/workspace/dpg demo/TBK-Client/utils/node_utils/TBKNode.py
2024-12-20 14:51:30.874 | ERROR    | utils.ClientLogManager:log:49 - <utils.node_utils.TBKNode.Subscriber object at 0x7fded47b2430> calc failed! Error: 'TBKManager' object has no attribute 'Subscriber', occurred on line 63 in file /home/mark/TnTeQAQ/workspace/dpg demo/TBK-Client/utils/node_utils/TBKNode.py
2024-12-20 14:51:30.891 | ERROR    | utils.ClientLogManager:log:49 - <utils.node_utils.TBKNode.Subscriber object at 0x7fded47b2430> calc failed! Error: 'TBKManager' object has no attribute 'Subscriber', occurred on line 63 in file /home/mark/TnTeQAQ/workspace/dpg demo/TBK-Client/utils/node_utils/TBKNode.py
2024-12-20 14:51:30.907 | ERROR    | utils.ClientLogManager:log:49 - <utils.node_utils.TBKNode.Subscriber object at 0x7fded47b2430> calc failed! Error: 'TBKManager' object has no attribute 'Subscriber', occurred on line 63 in file /home/mark/TnTeQAQ/workspace/dpg demo/TBK-Client/utils/node_utils/TBKNode.py
2024-12-20 14:51:30.924 | ERROR    | utils.ClientLogManager:log:49 - <utils.node_utils.TBKNode.Subscriber object at 0x7fded47b2430> calc failed! Error: 'TBKManager' object has no attribute 'Subscriber', occurred on line 63 in file /home/mark/TnTeQAQ/workspace/dpg demo/TBK-Client/utils/node_utils/TBKNode.py
2024-12-20 14:51:30.942 | ERROR    | utils.ClientLogManager:log:49 - <utils.node_utils.TBKNode.Subscriber object at 0x7fded47b2430> calc failed! Error: 'TBKManager' object has no attribute 'Subscriber', occurred on line 63 in file /home/mark/TnTeQAQ/workspace/dpg demo/TBK-Client/utils/node_utils/TBKNode.py
2024-12-20 14:51:31.001 | ERROR    | utils.ClientLogManager:log:49 - <utils.node_utils.TBKNode.Subscriber object at 0x7fded47b2430> calc failed! Error: 'TBKManager' object has no attribute 'Subscriber', occurred on line 63 in file /home/mark/TnTeQAQ/workspace/dpg demo/TBK-Client/utils/node_utils/TBKNode.py
2024-12-20 14:51:31.033 | ERROR    | utils.ClientLogManager:log:49 - <utils.node_utils.TBKNode.Subscriber object at 0x7fded47b2430> calc failed! Error: 'TBKManager' object has no attribute 'Subscriber', occurred on line 63 in file /home/mark/TnTeQAQ/workspace/dpg demo/TBK-Client/utils/node_utils/TBKNode.py
2024-12-20 14:51:31.041 | ERROR    | utils.ClientLogManager:log:49 - <utils.node_utils.TBKNode.Subscriber object at 0x7fded47b2430> calc failed! Error: 'TBKManager' object has no attribute 'Subscriber', occurred on line 63 in file /home/mark/TnTeQAQ/workspace/dpg demo/TBK-Client/utils/node_utils/TBKNode.py
2024-12-20 14:51:31.058 | ERROR    | utils.ClientLogManager:log:49 - <utils.node_utils.TBKNode.Subscriber object at 0x7fded47b2430> calc failed! Error: 'TBKManager' object has no attribute 'Subscriber', occurred on line 63 in file /home/mark/TnTeQAQ/workspace/dpg demo/TBK-Client/utils/node_utils/TBKNode.py
2024-12-20 14:51:31.074 | ERROR    | utils.ClientLogManager:log:49 - <utils.node_utils.TBKNode.Subscriber object at 0x7fded47b2430> calc failed! Error: 'TBKManager' object has no attribute 'Subscriber', occurred on line 63 in file /home/mark/TnTeQAQ/workspace/dpg demo/TBK-Client/utils/node_utils/TBKNode.py
2024-12-20 14:51:31.091 | ERROR    | utils.ClientLogManager:log:49 - <utils.node_utils.TBKNode.Subscriber object at 0x7fded47b2430> calc failed! Error: 'TBKManager' object has no attribute 'Subscriber', occurred on line 63 in file /home/mark/TnTeQAQ/workspace/dpg demo/TBK-Client/utils/node_utils/TBKNode.py
2024-12-20 14:51:31.107 | ERROR    | utils.ClientLogManager:log:49 - <utils.node_utils.TBKNode.Subscriber object at 0x7fded47b2430> calc failed! Error: 'TBKManager' object has no attribute 'Subscriber', occurred on line 63 in file /home/mark/TnTeQAQ/workspace/dpg demo/TBK-Client/utils/node_utils/TBKNode.py
2024-12-20 14:51:31.124 | ERROR    | utils.ClientLogManager:log:49 - <utils.node_utils.TBKNode.Subscriber object at 0x7fded47b2430> calc failed! Error: 'TBKManager' object has no attribute 'Subscriber', occurred on line 63 in file /home/mark/TnTeQAQ/workspace/dpg demo/TBK-Client/utils/node_utils/TBKNode.py
2024-12-20 14:51:31.141 | ERROR    | utils.ClientLogManager:log:49 - <utils.node_utils.TBKNode.Subscriber object at 0x7fded47b2430> calc failed! Error: 'TBKManager' object has no attribute 'Subscriber', occurred on line 63 in file /home/mark/TnTeQAQ/workspace/dpg demo/TBK-Client/utils/node_utils/TBKNode.py
2024-12-20 14:51:31.158 | ERROR    | utils.ClientLogManager:log:49 - <utils.node_utils.TBKNode.Subscriber object at 0x7fded47b2430> calc failed! Error: 'TBKManager' object has no attribute 'Subscriber', occurred on line 63 in file /home/mark/TnTeQAQ/workspace/dpg demo/TBK-Client/utils/node_utils/TBKNode.py
2024-12-20 14:51:31.195 | ERROR    | utils.ClientLogManager:log:49 - <utils.node_utils.TBKNode.Subscriber object at 0x7fded47b2430> calc failed! Error: 'TBKManager' object has no attribute 'Subscriber', occurred on line 63 in file /home/mark/TnTeQAQ/workspace/dpg demo/TBK-Client/utils/node_utils/TBKNode.py
2024-12-20 14:51:31.250 | ERROR    | utils.ClientLogManager:log:49 - <utils.node_utils.TBKNode.Subscriber object at 0x7fded47b2430> calc failed! Error: 'TBKManager' object has no attribute 'Subscriber', occurred on line 63 in file /home/mark/TnTeQAQ/workspace/dpg demo/TBK-Client/utils/node_utils/TBKNode.py
2024-12-20 14:51:31.258 | ERROR    | utils.ClientLogManager:log:49 - <utils.node_utils.TBKNode.Subscriber object at 0x7fded47b2430> calc failed! Error: 'TBKManager' object has no attribute 'Subscriber', occurred on line 63 in file /home/mark/TnTeQAQ/workspace/dpg demo/TBK-Client/utils/node_utils/TBKNode.py
2024-12-20 14:51:31.274 | ERROR    | utils.ClientLogManager:log:49 - <utils.node_utils.TBKNode.Subscriber object at 0x7fded47b2430> calc failed! Error: 'TBKManager' object has no attribute 'Subscriber', occurred on line 63 in file /home/mark/TnTeQAQ/workspace/dpg demo/TBK-Client/utils/node_utils/TBKNode.py
2024-12-20 14:51:31.291 | ERROR    | utils.ClientLogManager:log:49 - <utils.node_utils.TBKNode.Subscriber object at 0x7fded47b2430> calc failed! Error: 'TBKManager' object has no attribute 'Subscriber', occurred on line 63 in file /home/mark/TnTeQAQ/workspace/dpg demo/TBK-Client/utils/node_utils/TBKNode.py
2024-12-20 14:51:31.308 | ERROR    | utils.ClientLogManager:log:49 - <utils.node_utils.TBKNode.Subscriber object at 0x7fded47b2430> calc failed! Error: 'TBKManager' object has no attribute 'Subscriber', occurred on line 63 in file /home/mark/TnTeQAQ/workspace/dpg demo/TBK-Client/utils/node_utils/TBKNode.py
2024-12-20 14:51:31.324 | ERROR    | utils.ClientLogManager:log:49 - <utils.node_utils.TBKNode.Subscriber object at 0x7fded47b2430> calc failed! Error: 'TBKManager' object has no attribute 'Subscriber', occurred on line 63 in file /home/mark/TnTeQAQ/workspace/dpg demo/TBK-Client/utils/node_utils/TBKNode.py
2024-12-20 14:51:31.341 | ERROR    | utils.ClientLogManager:log:49 - <utils.node_utils.TBKNode.Subscriber object at 0x7fded47b2430> calc failed! Error: 'TBKManager' object has no attribute 'Subscriber', occurred on line 63 in file /home/mark/TnTeQAQ/workspace/dpg demo/TBK-Client/utils/node_utils/TBKNode.py
2024-12-20 15:50:33.418 | ERROR    | utils.ClientLogManager:log:49 - Unexpected error while importing LiveBox from ui.boxes.LiveBox Error: name 'UiData' is not defined, occurred on line 132 in file /home/mark/TnTeQAQ/workspace/dpg demo/TBK-Client/ui/boxes/LiveBox.py
2024-12-20 15:50:59.731 | ERROR    | utils.ClientLogManager:log:49 - Unexpected error while importing LiveBox from ui.boxes.LiveBox Error: name 'UiData' is not defined, occurred on line 132 in file /home/mark/TnTeQAQ/workspace/dpg demo/TBK-Client/ui/boxes/LiveBox.py
2024-12-20 15:53:04.902 | ERROR    | utils.ClientLogManager:log:49 - Failed to import LiveBox2 from ui.boxes.LiveBox1 Error: No module named 'ui.boxes.LiveBox1', occurred on line 7 in file /home/mark/TnTeQAQ/workspace/dpg demo/TBK-Client/ui/boxes/__init__.py
2024-12-20 16:53:52.689 | ERROR    | utils.ClientLogManager:log:49 - Failed to import IMUBox from ui.boxes.IMUBox Error: cannot import name 'ui_data' from 'utils.DataProcessor' (/home/mark/TnTeQAQ/workspace/dpg demo/TBK-Client/utils/DataProcessor.py), occurred on line 3 in file /home/mark/TnTeQAQ/workspace/dpg demo/TBK-Client/ui/components/Canvas2D.py
2024-12-20 16:53:52.690 | ERROR    | utils.ClientLogManager:log:49 - Failed to import PointsCouldBox from ui.boxes.PointsCouldBox Error: cannot import name 'ui_data' from 'utils.DataProcessor' (/home/mark/TnTeQAQ/workspace/dpg demo/TBK-Client/utils/DataProcessor.py), occurred on line 3 in file /home/mark/TnTeQAQ/workspace/dpg demo/TBK-Client/ui/components/Canvas2D.py
2024-12-20 16:53:52.690 | ERROR    | utils.ClientLogManager:log:49 - Failed to import AGVControlBox from ui.boxes.AGVControlBox Error: cannot import name 'ui_data' from 'utils.DataProcessor' (/home/mark/TnTeQAQ/workspace/dpg demo/TBK-Client/utils/DataProcessor.py), occurred on line 3 in file /home/mark/TnTeQAQ/workspace/dpg demo/TBK-Client/ui/components/Canvas2D.py
2024-12-20 16:53:52.691 | ERROR    | utils.ClientLogManager:log:49 - Failed to import RRTBox from ui.boxes.RRTBox Error: cannot import name 'ui_data' from 'utils.DataProcessor' (/home/mark/TnTeQAQ/workspace/dpg demo/TBK-Client/utils/DataProcessor.py), occurred on line 3 in file /home/mark/TnTeQAQ/workspace/dpg demo/TBK-Client/ui/components/Canvas2D.py
2024-12-20 16:53:52.691 | ERROR    | utils.ClientLogManager:log:49 - Failed to import FastLioMappingBox from ui.boxes.FastLioMappingBox Error: cannot import name 'ui_data' from 'utils.DataProcessor' (/home/mark/TnTeQAQ/workspace/dpg demo/TBK-Client/utils/DataProcessor.py), occurred on line 3 in file /home/mark/TnTeQAQ/workspace/dpg demo/TBK-Client/ui/components/Canvas2D.py
2024-12-20 16:53:52.692 | ERROR    | utils.ClientLogManager:log:49 - Failed to import PointsFaceBox from ui.boxes.PointsFaceBox Error: cannot import name 'ui_data' from 'utils.DataProcessor' (/home/mark/TnTeQAQ/workspace/dpg demo/TBK-Client/utils/DataProcessor.py), occurred on line 3 in file /home/mark/TnTeQAQ/workspace/dpg demo/TBK-Client/ui/components/Canvas2D.py
2024-12-20 16:54:16.449 | ERROR    | utils.ClientLogManager:log:49 - Failed to import IMUBox from ui.boxes.IMUBox Error: cannot import name 'ui_data' from 'utils.DataProcessor' (/home/mark/TnTeQAQ/workspace/dpg demo/TBK-Client/utils/DataProcessor.py), occurred on line 3 in file /home/mark/TnTeQAQ/workspace/dpg demo/TBK-Client/ui/components/Canvas2D.py
2024-12-20 16:54:16.450 | ERROR    | utils.ClientLogManager:log:49 - Failed to import PointsCouldBox from ui.boxes.PointsCouldBox Error: cannot import name 'ui_data' from 'utils.DataProcessor' (/home/mark/TnTeQAQ/workspace/dpg demo/TBK-Client/utils/DataProcessor.py), occurred on line 3 in file /home/mark/TnTeQAQ/workspace/dpg demo/TBK-Client/ui/components/Canvas2D.py
2024-12-20 16:54:16.450 | ERROR    | utils.ClientLogManager:log:49 - Failed to import AGVControlBox from ui.boxes.AGVControlBox Error: cannot import name 'ui_data' from 'utils.DataProcessor' (/home/mark/TnTeQAQ/workspace/dpg demo/TBK-Client/utils/DataProcessor.py), occurred on line 3 in file /home/mark/TnTeQAQ/workspace/dpg demo/TBK-Client/ui/components/Canvas2D.py
2024-12-20 16:54:16.451 | ERROR    | utils.ClientLogManager:log:49 - Failed to import RRTBox from ui.boxes.RRTBox Error: cannot import name 'ui_data' from 'utils.DataProcessor' (/home/mark/TnTeQAQ/workspace/dpg demo/TBK-Client/utils/DataProcessor.py), occurred on line 3 in file /home/mark/TnTeQAQ/workspace/dpg demo/TBK-Client/ui/components/Canvas2D.py
2024-12-20 16:54:16.451 | ERROR    | utils.ClientLogManager:log:49 - Failed to import FastLioMappingBox from ui.boxes.FastLioMappingBox Error: cannot import name 'ui_data' from 'utils.DataProcessor' (/home/mark/TnTeQAQ/workspace/dpg demo/TBK-Client/utils/DataProcessor.py), occurred on line 3 in file /home/mark/TnTeQAQ/workspace/dpg demo/TBK-Client/ui/components/Canvas2D.py
2024-12-20 16:54:16.452 | ERROR    | utils.ClientLogManager:log:49 - Failed to import PointsFaceBox from ui.boxes.PointsFaceBox Error: cannot import name 'ui_data' from 'utils.DataProcessor' (/home/mark/TnTeQAQ/workspace/dpg demo/TBK-Client/utils/DataProcessor.py), occurred on line 3 in file /home/mark/TnTeQAQ/workspace/dpg demo/TBK-Client/ui/components/Canvas2D.py
2024-12-20 16:55:52.574 | ERROR    | utils.ClientLogManager:log:49 - Failed to import IMUBox from ui.boxes.IMUBox Error: cannot import name 'ui_data' from 'utils.DataProcessor' (/home/mark/TnTeQAQ/workspace/dpg demo/TBK-Client/utils/DataProcessor.py), occurred on line 3 in file /home/mark/TnTeQAQ/workspace/dpg demo/TBK-Client/ui/components/Canvas2D.py
2024-12-20 16:55:52.574 | ERROR    | utils.ClientLogManager:log:49 - Failed to import PointsCouldBox from ui.boxes.PointsCouldBox Error: cannot import name 'ui_data' from 'utils.DataProcessor' (/home/mark/TnTeQAQ/workspace/dpg demo/TBK-Client/utils/DataProcessor.py), occurred on line 3 in file /home/mark/TnTeQAQ/workspace/dpg demo/TBK-Client/ui/components/Canvas2D.py
2024-12-20 16:55:52.575 | ERROR    | utils.ClientLogManager:log:49 - Failed to import AGVControlBox from ui.boxes.AGVControlBox Error: cannot import name 'ui_data' from 'utils.DataProcessor' (/home/mark/TnTeQAQ/workspace/dpg demo/TBK-Client/utils/DataProcessor.py), occurred on line 3 in file /home/mark/TnTeQAQ/workspace/dpg demo/TBK-Client/ui/components/Canvas2D.py
2024-12-20 16:55:52.575 | ERROR    | utils.ClientLogManager:log:49 - Failed to import RRTBox from ui.boxes.RRTBox Error: cannot import name 'ui_data' from 'utils.DataProcessor' (/home/mark/TnTeQAQ/workspace/dpg demo/TBK-Client/utils/DataProcessor.py), occurred on line 3 in file /home/mark/TnTeQAQ/workspace/dpg demo/TBK-Client/ui/components/Canvas2D.py
2024-12-20 16:55:52.576 | ERROR    | utils.ClientLogManager:log:49 - Failed to import FastLioMappingBox from ui.boxes.FastLioMappingBox Error: cannot import name 'ui_data' from 'utils.DataProcessor' (/home/mark/TnTeQAQ/workspace/dpg demo/TBK-Client/utils/DataProcessor.py), occurred on line 3 in file /home/mark/TnTeQAQ/workspace/dpg demo/TBK-Client/ui/components/Canvas2D.py
2024-12-20 16:55:52.576 | ERROR    | utils.ClientLogManager:log:49 - Failed to import PointsFaceBox from ui.boxes.PointsFaceBox Error: cannot import name 'ui_data' from 'utils.DataProcessor' (/home/mark/TnTeQAQ/workspace/dpg demo/TBK-Client/utils/DataProcessor.py), occurred on line 3 in file /home/mark/TnTeQAQ/workspace/dpg demo/TBK-Client/ui/components/Canvas2D.py
2024-12-20 17:11:06.875 | ERROR    | utils.ClientLogManager:log:49 - Loop Failed??? 'UiData' object has no attribute 'draw_mouse_pos'
2024-12-20 17:14:37.306 | ERROR    | utils.ClientLogManager:log:49 - Failed to import IMUBox from ui.boxes.IMUBox Error: cannot import name 'ui_data' from 'utils.DataProcessor' (/home/mark/TnTeQAQ/workspace/dpg demo/TBK-Client/utils/DataProcessor.py), occurred on line 3 in file /home/mark/TnTeQAQ/workspace/dpg demo/TBK-Client/ui/components/Canvas2D.py
2024-12-20 17:14:37.306 | ERROR    | utils.ClientLogManager:log:49 - Failed to import PointsCouldBox from ui.boxes.PointsCouldBox Error: cannot import name 'ui_data' from 'utils.DataProcessor' (/home/mark/TnTeQAQ/workspace/dpg demo/TBK-Client/utils/DataProcessor.py), occurred on line 3 in file /home/mark/TnTeQAQ/workspace/dpg demo/TBK-Client/ui/components/Canvas2D.py
2024-12-20 17:14:37.307 | ERROR    | utils.ClientLogManager:log:49 - Failed to import AGVControlBox from ui.boxes.AGVControlBox Error: cannot import name 'ui_data' from 'utils.DataProcessor' (/home/mark/TnTeQAQ/workspace/dpg demo/TBK-Client/utils/DataProcessor.py), occurred on line 3 in file /home/mark/TnTeQAQ/workspace/dpg demo/TBK-Client/ui/components/Canvas2D.py
2024-12-20 17:14:37.307 | ERROR    | utils.ClientLogManager:log:49 - Failed to import RRTBox from ui.boxes.RRTBox Error: cannot import name 'ui_data' from 'utils.DataProcessor' (/home/mark/TnTeQAQ/workspace/dpg demo/TBK-Client/utils/DataProcessor.py), occurred on line 3 in file /home/mark/TnTeQAQ/workspace/dpg demo/TBK-Client/ui/components/Canvas2D.py
2024-12-20 17:14:37.308 | ERROR    | utils.ClientLogManager:log:49 - Failed to import FastLioMappingBox from ui.boxes.FastLioMappingBox Error: cannot import name 'ui_data' from 'utils.DataProcessor' (/home/mark/TnTeQAQ/workspace/dpg demo/TBK-Client/utils/DataProcessor.py), occurred on line 3 in file /home/mark/TnTeQAQ/workspace/dpg demo/TBK-Client/ui/components/Canvas2D.py
2024-12-20 17:14:37.308 | ERROR    | utils.ClientLogManager:log:49 - Failed to import PointsFaceBox from ui.boxes.PointsFaceBox Error: cannot import name 'ui_data' from 'utils.DataProcessor' (/home/mark/TnTeQAQ/workspace/dpg demo/TBK-Client/utils/DataProcessor.py), occurred on line 3 in file /home/mark/TnTeQAQ/workspace/dpg demo/TBK-Client/ui/components/Canvas2D.py
2024-12-20 20:11:21.179 | ERROR    | utils.ClientLogManager:log:49 - Failed to import LiveBox from ui.boxes.LiveBox Error: No module named 'asdasidhu', occurred on line 3 in file /home/mark/TnTeQAQ/workspace/dpg demo/TBK-Client/ui/boxes/LiveBox.py
